Workbook

Sheet 年計
D1: 1年生 | J1: 2年生 | P1: ３年生
A2: 月 | B2: 日 | D2: 1 | E2: 2 | F2: 3 | G2: 4 | H2: 5 | I2: 6 | J2: 1 | K2: 2 | L2: 3 | M2: 4 | N2: 5 | O2: 6 | P2: 1 | Q2: 2 | R2: 3 | S2: 4 | T2: 5 | U2: 6 | W2: 橙＝時間割変更したコマ 水色＝2年の総合を道徳・学活に替えるコマ 「学活」＝授業開始(4/14)前の学級の時間
A3: 46478 | B3: 木 | C3: 月６
A4: 46479 | B4: 金 | C4: 火６
A5: 46480 | B5: 土 | C5: 水６
A6: 46481 | B6: 日 | C6: 金６
A7: 46482 | B7: 月 | W7: 入学式
A8: 46483 | B8: 火 | C8: 着任式 始業式 | K8: 学活 | Q8: 学活
A9: 46484 | B9: 水 | C9: 入学式 | F9: 学活 | J9: 学活 | K9: 学活 | L9: 学活 | M9: 学活 | P9: 学活 | Q9: 学活 | R9: 学活 | S9: 学活 | X9: 月１ | Y9: 月２ | Z9: 月３ | AA9: 月４ | AB9: 月５ | AC9: 月６ | AD9: 月１ | AE9: 月２ | AF9: 月３ | AG9: 月４ | AH9: 月５ | AI9: 月６ | AJ9: 月１ | AK9: 月２ | AL9: 月３ | AM9: 月４ | AN9: 月５ | AO9: 月６
A10: 46485 | B10: 木 | C10: 生徒会オリエンテーション・対面式 身体測定(3年) | F10: 学活 | G10: 学活 | K10: 学活 | M10: 学活 | Q10: 学活 | X10: 火１ | Y10: 火２ | Z10: 火３ | AA10: 火４ | AB10: 火５ | AC10: 火６ | AD10: 火１ | AE10: 火２ | AF10: 火３ | AG10: 火４ | AH10: 火５ | AI10: 火６ | AJ10: 火１ | AK10: 火２ | AL10: 火３ | AM10: 火４ | AN10: 火５ | AO10: 火６
A11: 46486 | B11: 金 | C11: 身体測定(1年･IJ)・（ランチ４月スタート分〆切） | D11: 学活 | L11: 学活 | M11: 学活 | Q11: 学活 | S11: 学活 | X11: 水１ | Y11: 水２ | Z11: 水３ | AA11: 水４ | AB11: 水５ | AC11: 水６ | AD11: 水１ | AE11: 水２ | AF11: 水３ | AG11: 水４ | AH11: 水５ | AI11: 水６ | AJ11: 水１ | AK11: 水２ | AL11: 水３ | AM11: 水４ | AN11: 水５ | AO11: 水６
A12: 46487 | B12: 土 | X12: 木１ | Y12: 木２ | Z12: 木３ | AA12: 木４ | AB12: 木５ | AD12: 木１ | AE12: 木２ | AF12: 木３ | AG12: 木４ | AH12: 木５ | AJ12: 木１ | AK12: 木２ | AL12: 木３ | AM12: 木４ | AN12: 木５
A13: 46488 | B13: 日 | X13: 金１ | Y13: 金２ | Z13: 金３ | AA13: 金４ | AB13: 金５ | AC13: 金６ | AD13: 金１ | AE13: 金２ | AF13: 金３ | AG13: 金４ | AH13: 金５ | AI13: 金６ | AJ13: 金１ | AK13: 金２ | AL13: 金３ | AM13: 金４ | AN13: 金５ | AO13: 金６
A14: 46489 | B14: 月 | C14: 身体測定(2年) | D14: 学活 | G14: 学活 | J14: 学活 | R14: 学活 | S14: 学活
A15: 46490 | B15: 火 | C15: 学級写真撮影・部活紹介 | D15: 学活 | E15: 学活 | F15: 学活 | G15: 学活 | H15: 学活 | I15: 学活 | J15: 学活 | K15: 学活 | L15: 学活 | M15: 学活 | N15: 学活 | O15: 学活 | P15: 学活 | Q15: 学活 | R15: 学活 | S15: 学活 | T15: 学活 | U15: 学活
A16: 46491 | B16: 水 | C16: 身体測定(欠席者)・仮時間割 ランチ開始 | D16: 水１ | E16: 水２ | F16: 月６ | G16: 水４ | H16: 水５ | I16: 水６ | J16: 水１ | K16: 水２ | L16: 月６ | M16: 水４ | N16: 水５ | O16: 水６ | P16: 水１ | Q16: 水２ | R16: 月６ | S16: 水４ | T16: 水５ | U16: 水６
A17: 46492 | B17: 木 | C17: 全国学調(国･数･質)※4/13〜16で調整 | D17: 木１ | E17: 木２ | F17: 木３ | G17: 木４ | H17: 木５ | J17: 木１ | K17: 木２ | L17: 木３ | M17: 木４ | N17: 木５ | S17: 木４ | T17: 木５
A18: 46493 | B18: 金 | C18: 避難訓練 | D18: 金１ | E18: 金２ | F18: 金３ | G18: 金４ | H18: 金５ | J18: 金１ | K18: 金２ | L18: 金３ | M18: 金４ | N18: 金５ | P18: 金１ | Q18: 金２ | R18: 金３ | S18: 金４ | T18: 金５
A19: 46494 | B19: 土
A20: 46495 | B20: 日
A21: 46496 | B21: 月 | C21: 認証式 | D21: 月１ | E21: 月２ | F21: 月３ | G21: 月４ | H21: 月５ | I21: 月６ | J21: 月１ | K21: 月２ | L21: 月３ | M21: 月４ | N21: 月５ | O21: 月６ | P21: 月１ | Q21: 月２ | R21: 月３ | S21: 月４ | T21: 月５ | U21: 月６
A22: 46497 | B22: 火 | C22: 眼科検診(2･3年午後) | D22: 火１ | E22: 火２ | F22: 火３ | G22: 火４ | H22: 火５ | I22: 火６ | J22: 火１ | K22: 火２ | L22: 火３ | M22: 火４ | N22: 火５ | O22: 火６ | P22: 火１ | Q22: 火２ | R22: 火３ | S22: 火４ | T22: 火５ | U22: 火６
A23: 46498 | B23: 水 | D23: 水１ | E23: 水２ | F23: 水３ | G23: 水４ | H23: 水５ | I23: 水６ | J23: 水１ | K23: 水２ | L23: 水３ | M23: 水４ | N23: 水５ | O23: 水６ | P23: 水１ | Q23: 水２ | R23: 水３ | S23: 水４ | T23: 水５ | U23: 水６
A24: 46499 | B24: 木 | D24: 木１ | E24: 木２ | F24: 木３ | G24: 木４ | H24: 木５ | J24: 木１ | K24: 木２ | L24: 木３ | M24: 木４ | N24: 木５ | P24: 木１ | Q24: 木２ | R24: 木３ | S24: 木４ | T24: 木５
A25: 46500 | B25: 金 | C25: 眼科検診(IJ･1年･色覚午後)・部活動集会 | D25: 金１ | E25: 金２ | F25: 金３ | G25: 金４ | H25: 金５ | I25: 金６ | J25: 金１ | K25: 金２ | L25: 金３ | M25: 金４ | N25: 金５ | O25: 金６ | P25: 金１ | Q25: 金２ | R25: 金３ | S25: 金４ | T25: 金５ | U25: 金６
A26: 46501 | B26: 土
A27: 46502 | B27: 日
A28: 46503 | B28: 月 | C28: 授業参観(午前)・Ｐ総会・学級懇(午後) | D28: 月１ | E28: 月２ | F28: 月３ | G28: 月４ | J28: 月１ | K28: 月２ | L28: 月３ | M28: 月４ | P28: 月１ | Q28: 月２ | R28: 月３ | S28: 月４
A29: 46504 | B29: 火 | C29: 内科検診(3年午後) | D29: 火１ | E29: 火２ | F29: 火３ | G29: 火４ | H29: 火５ | I29: 火６ | J29: 火１ | K29: 火２ | L29: 火３ | M29: 火４ | N29: 火５ | O29: 火６ | P29: 火１ | Q29: 火２ | R29: 火３ | S29: 火４ | T29: 火５ | U29: 火６
A30: 46505 | B30: 水 | D30: 水１ | E30: 月６ | F30: 水３ | G30: 水４ | H30: 月５ | I30: 水６ | J30: 水１ | K30: 月６ | L30: 水３ | M30: 水４ | N30: 月５ | O30: 水６ | P30: 水１ | Q30: 月６ | R30: 水３ | S30: 水４ | T30: 月５ | U30: 水６
A31: 46506 | B31: 木 | C31: 昭和の日
A32: 46507 | B32: 金 | C32: ⑤⑥進路説明会(3年)・部活保護者会 | D32: 木１ | E32: 木２ | F32: 木３ | G32: 金４ | H32: 金５ | I32: 金６ | J32: 木１ | K32: 木２ | L32: 木３ | M32: 金４ | N32: 金５ | O32: 金６ | P32: 木１ | Q32: 木２ | R32: 木３ | S32: 金４ | T32: 金５ | U32: 金６
A33: 46508 | B33: 土
A34: 46509 | B34: 日
A35: 46510 | B35: 月 | C35: 憲法記念日
A36: 46511 | B36: 火 | C36: みどりの日
A37: 46512 | B37: 水 | C37: こどもの日
A38: 46513 | B38: 木 | C38: 本時間割 | D38: 月１ | E38: 月２ | F38: 月３ | G38: 木４ | H38: 木５ | J38: 月１ | K38: 月２ | L38: 月３ | M38: 木４ | N38: 木５ | P38: 月１ | Q38: 月２ | R38: 月３ | S38: 木４ | T38: 木５
A39: 46514 | B39: 金 | C39: 新体力テスト準備・⑤⑥修学旅行説明会(3年) | D39: 金１ | E39: 金２ | F39: 金３ | G39: 月４ | H39: 月５ | I39: 金６ | J39: 金１ | K39: 金２ | L39: 金３ | M39: 月４ | N39: 月５ | O39: 金６ | P39: 金１ | Q39: 金２ | R39: 金３ | S39: 月４
A40: 46515 | B40: 土
...

Sheet 合計
A2: 教育カレンダー 時間数
B3: １年 | G3: ２年 | L3: ３年
A4: ＜確認テストまで（授業開始4/14）＞ | T4: 月６ | U4: 道徳
B5: 月 | C5: 火 | D5: 水 | E5: 木 | F5: 金 | G5: 月 | H5: 火 | I5: 水 | J5: 木 | K5: 金 | L5: 月 | M5: 火 | N5: 水 | O5: 木 | P5: 金 | T5: 火６ | U5: 総合２３ | AI5: 入学式 | AJ5: =IFERROR(MATCH(AI5,年計!$C$2:$C$368,0),"") | AM5: 月１ | AN5: 火１ | AO5: 水１ | AP5: 木１ | AQ5: 金１ | AR5: 月１ | AS5: 火１ | AT5: 水１ | AU5: 木１ | AV5: 金１ | AW5: 月１ | AX5: 火１ | AY5: 水１ | AZ5: 木１ | BA5: 金１
A6: 1 | B6: =COUNTIF(年計!$D$3:$I$48,AM5) -> 3 | C6: =COUNTIF(年計!$D$3:$I$48,AN5) -> 3 | D6: =COUNTIF(年計!$D$3:$I$48,AO5) -> 4 | E6: =COUNTIF(年計!$D$3:$I$48,AP5) -> 4 | F6: =COUNTIF(年計!$D$3:$I$48,AQ5) -> 4 | G6: =COUNTIF(年計!$J$3:$O$48,AR5) -> 3 | H6: =COUNTIF(年計!$J$3:$O$48,AS5) -> 3 | I6: =COUNTIF(年計!$J$3:$O$48,AT5) -> 4 | J6: =COUNTIF(年計!$J$3:$O$48,AU5) -> 4 | K6: =COUNTIF(年計!$J$3:$O$48,AV5) -> 4 | L6: =COUNTIF(年計!$P$3:$U$48,AW5) -> 3 | M6: =COUNTIF(年計!$P$3:$U$48,AX5) -> 3 | N6: =COUNTIF(年計!$P$3:$U$48,AY5) -> 4 | O6: =COUNTIF(年計!$P$3:$U$48,AZ5) -> 3 | P6: =COUNTIF(年計!$P$3:$U$48,BA5) -> 4 | T6: 水６ | U6: 学活 | AI6: 定期テスト① | AJ6: =IFERROR(MATCH(AI6,年計!$C$2:$C$368,0),"") | AM6: 月２ | AN6: 火２ | AO6: 水２ | AP6: 木２ | AQ6: 金２ | AR6: 月２ | AS6: 火２ | AT6: 水２ | AU6: 木２ | AV6: 金２ | AW6: 月２ | AX6: 火２ | AY6: 水２ | AZ6: 木２ | BA6: 金２
A7: 2 | B7: =COUNTIF(年計!$D$3:$I$48,AM6) -> 3 | C7: =COUNTIF(年計!$D$3:$I$48,AN6) -> 3 | D7: =COUNTIF(年計!$D$3:$I$48,AO6) -> 3 | E7: =COUNTIF(年計!$D$3:$I$48,AP6) -> 4 | F7: =COUNTIF(年計!$D$3:$I$48,AQ6) -> 4 | G7: =COUNTIF(年計!$J$3:$O$48,AR6) -> 3 | H7: =COUNTIF(年計!$J$3:$O$48,AS6) -> 3 | I7: =COUNTIF(年計!$J$3:$O$48,AT6) -> 3 | J7: =COUNTIF(年計!$J$3:$O$48,AU6) -> 4 | K7: =COUNTIF(年計!$J$3:$O$48,AV6) -> 4 | L7: =COUNTIF(年計!$P$3:$U$48,AW6) -> 3 | M7: =COUNTIF(年計!$P$3:$U$48,AX6) -> 3 | N7: =COUNTIF(年計!$P$3:$U$48,AY6) -> 3 | O7: =COUNTIF(年計!$P$3:$U$48,AZ6) -> 3 | P7: =COUNTIF(年計!$P$3:$U$48,BA6) -> 4 | T7: 金６ | U7: 総合 | AM7: 月３ | AN7: 火３ | AO7: 水３ | AP7: 木３ | AQ7: 金３ | AR7: 月３ | AS7: 火３ | AT7: 水３ | AU7: 木３ | AV7: 金３ | AW7: 月３ | AX7: 火３ | AY7: 水３ | AZ7: 木３ | BA7: 金３
A8: 3 | B8: =COUNTIF(年計!$D$3:$I$48,AM7) -> 3 | C8: =COUNTIF(年計!$D$3:$I$48,AN7) -> 3 | D8: =COUNTIF(年計!$D$3:$I$48,AO7) -> 3 | E8: =COUNTIF(年計!$D$3:$I$48,AP7) -> 4 | F8: =COUNTIF(年計!$D$3:$I$48,AQ7) -> 4 | G8: =COUNTIF(年計!$J$3:$O$48,AR7) -> 3 | H8: =COUNTIF(年計!$J$3:$O$48,AS7) -> 3 | I8: =COUNTIF(年計!$J$3:$O$48,AT7) -> 3 | J8: =COUNTIF(年計!$J$3:$O$48,AU7) -> 4 | K8: =COUNTIF(年計!$J$3:$O$48,AV7) -> 4 | L8: =COUNTIF(年計!$P$3:$U$48,AW7) -> 3 | M8: =COUNTIF(年計!$P$3:$U$48,AX7) -> 3 | N8: =COUNTIF(年計!$P$3:$U$48,AY7) -> 3 | O8: =COUNTIF(年計!$P$3:$U$48,AZ7) -> 3 | P8: =COUNTIF(年計!$P$3:$U$48,BA7) -> 4 | AM8: 月４ | AN8: 火４ | AO8: 水４ | AP8: 木４ | AQ8: 金４ | AR8: 月４ | AS8: 火４ | AT8: 水４ | AU8: 木４ | AV8: 金４ | AW8: 月４ | AX8: 火４ | AY8: 水４ | AZ8: 木４ | BA8: 金４
A9: 4 | B9: =COUNTIF(年計!$D$3:$I$48,AM8) -> 3 | C9: =COUNTIF(年計!$D$3:$I$48,AN8) -> 3 | D9: =COUNTIF(年計!$D$3:$I$48,AO8) -> 3 | E9: =COUNTIF(年計!$D$3:$I$48,AP8) -> 4 | F9: =COUNTIF(年計!$D$3:$I$48,AQ8) -> 4 | G9: =COUNTIF(年計!$J$3:$O$48,AR8) -> 3 | H9: =COUNTIF(年計!$J$3:$O$48,AS8) -> 3 | I9: =COUNTIF(年計!$J$3:$O$48,AT8) -> 3 | J9: =COUNTIF(年計!$J$3:$O$48,AU8) -> 4 | K9: =COUNTIF(年計!$J$3:$O$48,AV8) -> 4 | L9: =COUNTIF(年計!$P$3:$U$48,AW8) -> 3 | M9: =COUNTIF(年計!$P$3:$U$48,AX8) -> 3 | N9: =COUNTIF(年計!$P$3:$U$48,AY8) -> 3 | O9: =COUNTIF(年計!$P$3:$U$48,AZ8) -> 4 | P9: =COUNTIF(年計!$P$3:$U$48,BA8) -> 4 | AM9: 月５ | AN9: 火５ | AO9: 水５ | AP9: 木５ | AQ9: 金５ | AR9: 月５ | AS9: 火５ | AT9: 水５ | AU9: 木５ | AV9: 金５ | AW9: 月５ | AX9: 火５ | AY9: 水５ | AZ9: 木５ | BA9: 金５
A10: 5 | B10: =COUNTIF(年計!$D$3:$I$48,AM9) -> 4 | C10: =COUNTIF(年計!$D$3:$I$48,AN9) -> 3 | D10: =COUNTIF(年計!$D$3:$I$48,AO9) -> 3 | E10: =COUNTIF(年計!$D$3:$I$48,AP9) -> 3 | F10: =COUNTIF(年計!$D$3:$I$48,AQ9) -> 4 | G10: =COUNTIF(年計!$J$3:$O$48,AR9) -> 4 | H10: =COUNTIF(年計!$J$3:$O$48,AS9) -> 3 | I10: =COUNTIF(年計!$J$3:$O$48,AT9) -> 3 | J10: =COUNTIF(年計!$J$3:$O$48,AU9) -> 3 | K10: =COUNTIF(年計!$J$3:$O$48,AV9) -> 4 | L10: =COUNTIF(年計!$P$3:$U$48,AW9) -> 3 | M10: =COUNTIF(年計!$P$3:$U$48,AX9) -> 3 | N10: =COUNTIF(年計!$P$3:$U$48,AY9) -> 3 | O10: =COUNTIF(年計!$P$3:$U$48,AZ9) -> 3 | P10: =COUNTIF(年計!$P$3:$U$48,BA9) -> 4 | AM10: 月６ | AN10: 火６ | AO10: 水６ | AP10: 木６ | AQ10: 金６ | AR10: 月６ | AS10: 火６ | AT10: 水６ | AU10: 木６ | AV10: 金６ | AW10: 月６ | AX10: 火６ | AY10: 水６ | AZ10: 木６ | BA10: 金６
A11: 6 | B11: =COUNTIF(年計!$D$3:$I$48,AM10) -> 4 | C11: =COUNTIF(年計!$D$3:$I$48,AN10) -> 3 | D11: =COUNTIF(年計!$D$3:$I$48,AO10) -> 4 | F11: =COUNTIF(年計!$D$3:$I$48,AQ10) -> 4 | G11: =COUNTIF(年計!$J$3:$O$48,AR10) -> 4 | H11: =COUNTIF(年計!$J$3:$O$48,AS10) -> 3 | I11: =COUNTIF(年計!$J$3:$O$48,AT10) -> 4 | J11: =COUNTIF(年計!$J$3:$O$48,AU10) -> 0 | K11: =COUNTIF(年計!$J$3:$O$48,AV10) -> 4 | L11: =COUNTIF(年計!$P$3:$U$48,AW10) -> 4 | M11: =COUNTIF(年計!$P$3:$U$48,AX10) -> 3 | N11: =COUNTIF(年計!$P$3:$U$48,AY10) -> 4 | O11: =COUNTIF(年計!$P$3:$U$48,AZ10) -> 0 | P11: =COUNTIF(年計!$P$3:$U$48,BA10) -> 3 | S11: １年 | X11: ２年 | AC11: ３年
A12: ＜確テ～１期末テ＞ | S12: ＜１期末テまで 累計＞
B13: 月 | C13: 火 | D13: 水 | E13: 木 | F13: 金 | G13: 月 | H13: 火 | I13: 水 | J13: 木 | K13: 金 | L13: 月 | M13: 火 | N13: 水 | O13: 木 | P13: 金 | T13: 月 | U13: 火 | V13: 水 | W13: 木 | X13: 金 | Y13: 月 | Z13: 火 | AA13: 水 | AB13: 木 | AC13: 金 | AD13: 月 | AE13: 火 | AF13: 水 | AG13: 木 | AH13: 金 | AM13: 月１ | AN13: 火１ | AO13: 水１ | AP13: 木１ | AQ13: 金１ | AR13: 月１ | AS13: 火１ | AT13: 水１ | AU13: 木１ | AV13: 金１ | AW13: 月１ | AX13: 火１ | AY13: 水１ | AZ13: 木１ | BA13: 金１ | BB13: 月１ | BC13: 火１ | BD13: 水１ | BE13: 木１ | BF13: 金１ | BG13: 月１ | BH13: 火１ | BI13: 水１ | BJ13: 木１ | BK13: 金１ | BL13: 月１ | BM13: 火１ | BN13: 水１ | BO13: 木１ | BP13: 金１
A14: 1 | B14: =COUNTIF(年計!$D$49:$I$86,AM13) -> 5 | C14: =COUNTIF(年計!$D$49:$I$86,AN13) -> 5 | D14: =COUNTIF(年計!$D$49:$I$86,AO13) -> 4 | E14: =COUNTIF(年計!$D$49:$I$86,AP13) -> 5 | F14: =COUNTIF(年計!$D$49:$I$86,AQ13) -> 4 | G14: =COUNTIF(年計!$J$49:$O$86,AR13) -> 5 | H14: =COUNTIF(年計!$J$49:$O$86,AS13) -> 5 | I14: =COUNTIF(年計!$J$49:$O$86,AT13) -> 4 | J14: =COUNTIF(年計!$J$49:$O$86,AU13) -> 5 | K14: =COUNTIF(年計!$J$49:$O$86,AV13) -> 4 | L14: =COUNTIF(年計!$P$49:$U$86,AW13) -> 4 | M14: =COUNTIF(年計!$P$49:$U$86,AX13) -> 3 | N14: =COUNTIF(年計!$P$49:$U$86,AY13) -> 4 | O14: =COUNTIF(年計!$P$49:$U$86,AZ13) -> 3 | P14: =COUNTIF(年計!$P$49:$U$86,BA13) -> 4 | S14: 1 | T14: =COUNTIF(年計!$D$3:$I$86,BB13) -> 8 | U14: =COUNTIF(年計!$D$3:$I$86,BC13) -> 8 | V14: =COUNTIF(年計!$D$3:$I$86,BD13) -> 8 | W14: =COUNTIF(年計!$D$3:$I$86,BE13) -> 9 | X14: =COUNTIF(年計!$D$3:$I$86,BF13) -> 8 | Y14: =COUNTIF(年計!$J$3:$O$86,BG13) -> 8 | Z14: =COUNTIF(年計!$J$3:$O$86,BH13) -> 8 | AA14: =COUNTIF(年計!$J$3:$O$86,BI13) -> 8 | AB14: =COUNTIF(年計!$J$3:$O$86,BJ13) -> 9 | AC14: =COUNTIF(年計!$J$3:$O$86,BK13) -> 8 | AD14: =COUNTIF(年計!$P$3:$U$86,BL13) -> 7 | AE14: =COUNTIF(年計!$P$3:$U$86,BM13) -> 6 | AF14: =COUNTIF(年計!$P$3:$U$86,BN13) -> 8 | AG14: =COUNTIF(年計!$P$3:$U$86,BO13) -> 6 | AH14: =COUNTIF(年計!$P$3:$U$86,BP13) -> 8 | AI14: 定期テスト② | AJ14: =IFERROR(MATCH(AI14,年計!$C$2:$C$368,0),"") | AM14: 月２ | AN14: 火２ | AO14: 水２ | AP14: 木２ | AQ14: 金２ | AR14: 月２ | AS14: 火２ | AT14: 水２ | AU14: 木２ | AV14: 金２ | AW14: 月２ | AX14: 火２ | AY14: 水２ | AZ14: 木２ | BA14: 金２ | BB14: 月２ | BC14: 火２ | BD14: 水２ | BE14: 木２ | BF14: 金２ | BG14: 月２ | BH14: 火２ | BI14: 水２ | BJ14: 木２ | BK14: 金２ | BL14: 月２ | BM14: 火２ | BN14: 水２ | BO14: 木２ | BP14: 金２
A15: 2 | B15: =COUNTIF(年計!$D$49:$I$86,AM14) -> 6 | C15: =COUNTIF(年計!$D$49:$I$86,AN14) -> 6 | D15: =COUNTIF(年計!$D$49:$I$86,AO14) -> 5 | E15: =COUNTIF(年計!$D$49:$I$86,AP14) -> 5 | F15: =COUNTIF(年計!$D$49:$I$86,AQ14) -> 5 | G15: =COUNTIF(年計!$J$49:$O$86,AR14) -> 6 | H15: =COUNTIF(年計!$J$49:$O$86,AS14) -> 6 | I15: =COUNTIF(年計!$J$49:$O$86,AT14) -> 5 | J15: =COUNTIF(年計!$J$49:$O$86,AU14) -> 5 | K15: =COUNTIF(年計!$J$49:$O$86,AV14) -> 5 | L15: =COUNTIF(年計!$P$49:$U$86,AW14) -> 5 | M15: =COUNTIF(年計!$P$49:$U$86,AX14) -> 5 | N15: =COUNTIF(年計!$P$49:$U$86,AY14) -> 4 | O15: =COUNTIF(年計!$P$49:$U$86,AZ14) -> 3 | P15: =COUNTIF(年計!$P$49:$U$86,BA14) -> 4 | S15: 2 | T15: =COUNTIF(年計!$D$3:$I$86,BB14) -> 9 | U15: =COUNTIF(年計!$D$3:$I$86,BC14) -> 9 | V15: =COUNTIF(年計!$D$3:$I$86,BD14) -> 8 | W15: =COUNTIF(年計!$D$3:$I$86,BE14) -> 9 | X15: =COUNTIF(年計!$D$3:$I$86,BF14) -> 9 | Y15: =COUNTIF(年計!$J$3:$O$86,BG14) -> 9 | Z15: =COUNTIF(年計!$J$3:$O$86,BH14) -> 9 | AA15: =COUNTIF(年計!$J$3:$O$86,BI14) -> 8 | AB15: =COUNTIF(年計!$J$3:$O$86,BJ14) -> 9 | AC15: =COUNTIF(年計!$J$3:$O$86,BK14) -> 9 | AD15: =COUNTIF(年計!$P$3:$U$86,BL14) -> 8 | AE15: =COUNTIF(年計!$P$3:$U$86,BM14) -> 8 | AF15: =COUNTIF(年計!$P$3:$U$86,BN14) -> 7 | AG15: =COUNTIF(年計!$P$3:$U$86,BO14) -> 6 | AH15: =COUNTIF(年計!$P$3:$U$86,BP14) -> 8 | AM15: 月３ | AN15: 火３ | AO15: 水３ | AP15: 木３ | AQ15: 金３ | AR15: 月３ | AS15: 火３ | AT15: 水３ | AU15: 木３ | AV15: 金３ | AW15: 月３ | AX15: 火３ | AY15: 水３ | AZ15: 木３ | BA15: 金３ | BB15: 月３ | BC15: 火３ | BD15: 水３ | BE15: 木３ | BF15: 金３ | BG15: 月３ | BH15: 火３ | BI15: 水３ | BJ15: 木３ | BK15: 金３ | BL15: 月３ | BM15: 火３ | BN15: 水３ | BO15: 木３ | BP15: 金３
A16: 3 | B16: =COUNTIF(年計!$D$49:$I$86,AM15) -> 6 | C16: =COUNTIF(年計!$D$49:$I$86,AN15) -> 6 | D16: =COUNTIF(年計!$D$49:$I$86,AO15) -> 5 | E16: =COUNTIF(年計!$D$49:$I$86,AP15) -> 5 | F16: =COUNTIF(年計!$D$49:$I$86,AQ15) -> 5 | G16: =COUNTIF(年計!$J$49:$O$86,AR15) -> 6 | H16: =COUNTIF(年計!$J$49:$O$86,AS15) -> 6 | I16: =COUNTIF(年計!$J$49:$O$86,AT15) -> 5 | J16: =COUNTIF(年計!$J$49:$O$86,AU15) -> 5 | K16: =COUNTIF(年計!$J$49:$O$86,AV15) -> 5 | L16: =COUNTIF(年計!$P$49:$U$86,AW15) -> 5 | M16: =COUNTIF(年計!$P$49:$U$86,AX15) -> 5 | N16: =COUNTIF(年計!$P$49:$U$86,AY15) -> 4 | O16: =COUNTIF(年計!$P$49:$U$86,AZ15) -> 3 | P16: =COUNTIF(年計!$P$49:$U$86,BA15) -> 4 | S16: 3 | T16: =COUNTIF(年計!$D$3:$I$86,BB15) -> 9 | U16: =COUNTIF(年計!$D$3:$I$86,BC15) -> 9 | V16: =COUNTIF(年計!$D$3:$I$86,BD15) -> 8 | W16: =COUNTIF(年計!$D$3:$I$86,BE15) -> 9 | X16: =COUNTIF(年計!$D$3:$I$86,BF15) -> 9 | Y16: =COUNTIF(年計!$J$3:$O$86,BG15) -> 9 | Z16: =COUNTIF(年計!$J$3:$O$86,BH15) -> 9 | AA16: =COUNTIF(年計!$J$3:$O$86,BI15) -> 8 | AB16: =COUNTIF(年計!$J$3:$O$86,BJ15) -> 9 | AC16: =COUNTIF(年計!$J$3:$O$86,BK15) -> 9 | AD16: =COUNTIF(年計!$P$3:$U$86,BL15) -> 8 | AE16: =COUNTIF(年計!$P$3:$U$86,BM15) -> 8 | AF16: =COUNTIF(年計!$P$3:$U$86,BN15) -> 7 | AG16: =COUNTIF(年計!$P$3:$U$86,BO15) -> 6 | AH16: =COUNTIF(年計!$P$3:$U$86,BP15) -> 8 | AM16: 月４ | AN16: 火４ | AO16: 水４ | AP16: 木４ | AQ16: 金４ | AR16: 月４ | AS16: 火４ | AT16: 水４ | AU16: 木４ | AV16: 金４ | AW16: 月４ | AX16: 火４ | AY16: 水４ | AZ16: 木４ | BA16: 金４ | BB16: 月４ | BC16: 火４ | BD16: 水４ | BE16: 木４ | BF16: 金４ | BG16: 月４ | BH16: 火４ | BI16: 水４ | BJ16: 木４ | BK16: 金４ | BL16: 月４ | BM16: 火４ | BN16: 水４ | BO16: 木４ | BP16: 金４
A17: 4 | B17: =COUNTIF(年計!$D$49:$I$86,AM16) -> 6 | C17: =COUNTIF(年計!$D$49:$I$86,AN16) -> 5 | D17: =COUNTIF(年計!$D$49:$I$86,AO16) -> 6 | E17: =COUNTIF(年計!$D$49:$I$86,AP16) -> 5 | F17: =COUNTIF(年計!$D$49:$I$86,AQ16) -> 5 | G17: =COUNTIF(年計!$J$49:$O$86,AR16) -> 6 | H17: =COUNTIF(年計!$J$49:$O$86,AS16) -> 5 | I17: =COUNTIF(年計!$J$49:$O$86,AT16) -> 6 | J17: =COUNTIF(年計!$J$49:$O$86,AU16) -> 5 | K17: =COUNTIF(年計!$J$49:$O$86,AV16) -> 5 | L17: =COUNTIF(年計!$P$49:$U$86,AW16) -> 5 | M17: =COUNTIF(年計!$P$49:$U$86,AX16) -> 4 | N17: =COUNTIF(年計!$P$49:$U$86,AY16) -> 5 | O17: =COUNTIF(年計!$P$49:$U$86,AZ16) -> 3 | P17: =COUNTIF(年計!$P$49:$U$86,BA16) -> 4 | S17: 4 | T17: =COUNTIF(年計!$D$3:$I$86,BB16) -> 9 | U17: =COUNTIF(年計!$D$3:$I$86,BC16) -> 8 | V17: =COUNTIF(年計!$D$3:$I$86,BD16) -> 9 | W17: =COUNTIF(年計!$D$3:$I$86,BE16) -> 9 | X17: =COUNTIF(年計!$D$3:$I$86,BF16) -> 9 | Y17: =COUNTIF(年計!$J$3:$O$86,BG16) -> 9 | Z17: =COUNTIF(年計!$J$3:$O$86,BH16) -> 8 | AA17: =COUNTIF(年計!$J$3:$O$86,BI16) -> 9 | AB17: =COUNTIF(年計!$J$3:$O$86,BJ16) -> 9 | AC17: =COUNTIF(年計!$J$3:$O$86,BK16) -> 9 | AD17: =COUNTIF(年計!$P$3:$U$86,BL16) -> 8 | AE17: =COUNTIF(年計!$P$3:$U$86,BM16) -> 7 | AF17: =COUNTIF(年計!$P$3:$U$86,BN16) -> 8 | AG17: =COUNTIF(年計!$P$3:$U$86,BO16) -> 7 | AH17: =COUNTIF(年計!$P$3:$U$86,BP16) -> 8 | AM17: 月５ | AN17: 火５ | AO17: 水５ | AP17: 木５ | AQ17: 金５ | AR17: 月５ | AS17: 火５ | AT17: 水５ | AU17: 木５ | AV17: 金５ | AW17: 月５ | AX17: 火５ | AY17: 水５ | AZ17: 木５ | BA17: 金５ | BB17: 月５ | BC17: 火５ | BD17: 水５ | BE17: 木５ | BF17: 金５ | BG17: 月５ | BH17: 火５ | BI17: 水５ | BJ17: 木５ | BK17: 金５ | BL17: 月５ | BM17: 火５ | BN17: 水５ | BO17: 木５ | BP17: 金５
A18: 5 | B18: =COUNTIF(年計!$D$49:$I$86,AM17) -> 4 | C18: =COUNTIF(年計!$D$49:$I$86,AN17) -> 5 | D18: =COUNTIF(年計!$D$49:$I$86,AO17) -> 5 | E18: =COUNTIF(年計!$D$49:$I$86,AP17) -> 6 | F18: =COUNTIF(年計!$D$49:$I$86,AQ17) -> 4 | G18: =COUNTIF(年計!$J$49:$O$86,AR17) -> 4 | H18: =COUNTIF(年計!$J$49:$O$86,AS17) -> 5 | I18: =COUNTIF(年計!$J$49:$O$86,AT17) -> 5 | J18: =COUNTIF(年計!$J$49:$O$86,AU17) -> 6 | K18: =COUNTIF(年計!$J$49:$O$86,AV17) -> 4 | L18: =COUNTIF(年計!$P$49:$U$86,AW17) -> 3 | M18: =COUNTIF(年計!$P$49:$U$86,AX17) -> 4 | N18: =COUNTIF(年計!$P$49:$U$86,AY17) -> 4 | O18: =COUNTIF(年計!$P$49:$U$86,AZ17) -> 4 | P18: =COUNTIF(年計!$P$49:$U$86,BA17) -> 3 | S18: 5 | T18: =COUNTIF(年計!$D$3:$I$86,BB17) -> 8 | U18: =COUNTIF(年計!$D$3:$I$86,BC17) -> 8 | V18: =COUNTIF(年計!$D$3:$I$86,BD17) -> 8 | W18: =COUNTIF(年計!$D$3:$I$86,BE17) -> 9 | X18: =COUNTIF(年計!$D$3:$I$86,BF17) -> 8 | Y18: =COUNTIF(年計!$J$3:$O$86,BG17) -> 8 | Z18: =COUNTIF(年計!$J$3:$O$86,BH17) -> 8 | AA18: =COUNTIF(年計!$J$3:$O$86,BI17) -> 8 | AB18: =COUNTIF(年計!$J$3:$O$86,BJ17) -> 9 | AC18: =COUNTIF(年計!$J$3:$O$86,BK17) -> 8 | AD18: =COUNTIF(年計!$P$3:$U$86,BL17) -> 6 | AE18: =COUNTIF(年計!$P$3:$U$86,BM17) -> 7 | AF18: =COUNTIF(年計!$P$3:$U$86,BN17) -> 7 | AG18: =COUNTIF(年計!$P$3:$U$86,BO17) -> 7 | AH18: =COUNTIF(年計!$P$3:$U$86,BP17) -> 7 | AM18: 月６ | AN18: 火６ | AO18: 水６ | AP18: 木６ | AQ18: 金６ | AR18: 月６ | AS18: 火６ | AT18: 水６ | AU18: 木６ | AV18: 金６ | AW18: 月６ | AX18: 火６ | AY18: 水６ | AZ18: 木６ | BA18: 金６ | BB18: 月６ | BC18: 火６ | BD18: 水６ | BE18: 木６ | BF18: 金６ | BG18: 月６ | BH18: 火６ | BI18: 水６ | BJ18: 木６ | BK18: 金６ | BL18: 月６ | BM18: 火６ | BN18: 水６ | BO18: 木６ | BP18: 金６
A19: 6 | B19: =COUNTIF(年計!$D$49:$I$86,AM18) -> 5 | C19: =COUNTIF(年計!$D$49:$I$86,AN18) -> 5 | D19: =COUNTIF(年計!$D$49:$I$86,AO18) -> 5 | F19: =COUNTIF(年計!$D$49:$I$86,AQ18) -> 5 | G19: =COUNTIF(年計!$J$49:$O$86,AR18) -> 5 | H19: =COUNTIF(年計!$J$49:$O$86,AS18) -> 5 | I19: =COUNTIF(年計!$J$49:$O$86,AT18) -> 5 | J19: =COUNTIF(年計!$J$49:$O$86,AU18) -> 0 | K19: =COUNTIF(年計!$J$49:$O$86,AV18) -> 5 | L19: =COUNTIF(年計!$P$49:$U$86,AW18) -> 4 | M19: =COUNTIF(年計!$P$49:$U$86,AX18) -> 3 | N19: =COUNTIF(年計!$P$49:$U$86,AY18) -> 4 | O19: =COUNTIF(年計!$P$49:$U$86,AZ18) -> 0 | P19: =COUNTIF(年計!$P$49:$U$86,BA18) -> 4 | S19: 6 | T19: =COUNTIF(年計!$D$3:$I$86,BB18) -> 9 | U19: =COUNTIF(年計!$D$3:$I$86,BC18) -> 8 | V19: =COUNTIF(年計!$D$3:$I$86,BD18) -> 9 | X19: =COUNTIF(年計!$D$3:$I$86,BF18) -> 9 | Y19: =COUNTIF(年計!$J$3:$O$86,BG18) -> 9 | Z19: =COUNTIF(年計!$J$3:$O$86,BH18) -> 8 | AA19: =COUNTIF(年計!$J$3:$O$86,BI18) -> 9 | AB19: =COUNTIF(年計!$J$3:$O$86,BJ18) -> 0 | AC19: =COUNTIF(年計!$J$3:$O$86,BK18) -> 9 | AD19: =COUNTIF(年計!$P$3:$U$86,BL18) -> 8 | AE19: =COUNTIF(年計!$P$3:$U$86,BM18) -> 6 | AF19: =COUNTIF(年計!$P$3:$U$86,BN18) -> 8 | AG19: =COUNTIF(年計!$P$3:$U$86,BO18) -> 0 | AH19: =COUNTIF(年計!$P$3:$U$86,BP18) -> 7
A20: ＜１期末テ～２期中テ＞ | S20: ＜２期中テまで 累計＞
B21: 月 | C21: 火 | D21: 水 | E21: 木 | F21: 金 | G21: 月 | H21: 火 | I21: 水 | J21: 木 | K21: 金 | L21: 月 | M21: 火 | N21: 水 | O21: 木 | P21: 金 | T21: 月 | U21: 火 | V21: 水 | W21: 木 | X21: 金 | Y21: 月 | Z21: 火 | AA21: 水 | AB21: 木 | AC21: 金 | AD21: 月 | AE21: 火 | AF21: 水 | AG21: 木 | AH21: 金 | AM21: 月１ | AN21: 火１ | AO21: 水１ | AP21: 木１ | AQ21: 金１ | AR21: 月１ | AS21: 火１ | AT21: 水１ | AU21: 木１ | AV21: 金１ | AW21: 月１ | AX21: 火１ | AY21: 水１ | AZ21: 木１ | BA21: 金１ | BB21: 月１ | BC21: 火１ | BD21: 水１ | BE21: 木１ | BF21: 金１ | BG21: 月１ | BH21: 火１ | BI21: 水１ | BJ21: 木１ | BK21: 金１ | BL21: 月１ | BM21: 火１ | BN21: 水１ | BO21: 木１ | BP21: 金１
A22: 1 | B22: =COUNTIF(年計!$D$87:$I$181,AM21) -> 5 | C22: =COUNTIF(年計!$D$87:$I$181,AN21) -> 6 | D22: =COUNTIF(年計!$D$87:$I$181,AO21) -> 5 | E22: =COUNTIF(年計!$D$87:$I$181,AP21) -> 5 | F22: =COUNTIF(年計!$D$87:$I$181,AQ21) -> 5 | G22: =COUNTIF(年計!$J$87:$O$181,AR21) -> 5 | H22: =COUNTIF(年計!$J$87:$O$181,AS21) -> 6 | I22: =COUNTIF(年計!$J$87:$O$181,AT21) -> 5 | J22: =COUNTIF(年計!$J$87:$O$181,AU21) -> 5 | K22: =COUNTIF(年計!$J$87:$O$181,AV21) -> 5 | L22: =COUNTIF(年計!$P$87:$U$181,AW21) -> 5 | M22: =COUNTIF(年計!$P$87:$U$181,AX21) -> 6 | N22: =COUNTIF(年計!$P$87:$U$181,AY21) -> 5 | O22: =COUNTIF(年計!$P$87:$U$181,AZ21) -> 5 | P22: =COUNTIF(年計!$P$87:$U$181,BA21) -> 5 | S22: 1 | T22: =COUNTIF(年計!$D$3:$I$181,BB21) -> 13 | U22: =COUNTIF(年計!$D$3:$I$181,BC21) -> 14 | V22: =COUNTIF(年計!$D$3:$I$181,BD21) -> 13 | W22: =COUNTIF(年計!$D$3:$I$181,BE21) -> 14 | X22: =COUNTIF(年計!$D$3:$I$181,BF21) -> 13 | Y22: =COUNTIF(年計!$J$3:$O$181,BG21) -> 13 | Z22: =COUNTIF(年計!$J$3:$O$181,BH21) -> 14 | AA22: =COUNTIF(年計!$J$3:$O$181,BI21) -> 13 | AB22: =COUNTIF(年計!$J$3:$O$181,BJ21) -> 14 | AC22: =COUNTIF(年計!$J$3:$O$181,BK21) -> 13 | AD22: =COUNTIF(年計!$P$3:$U$181,BL21) -> 12 | AE22: =COUNTIF(年計!$P$3:$U$181,BM21) -> 12 | AF22: =COUNTIF(年計!$P$3:$U$181,BN21) -> 13 | AG22: =COUNTIF(年計!$P$3:$U$181,BO21) -> 11 | AH22: =COUNTIF(年計!$P$3:$U$181,BP21) -> 13 | AI22: 定期テスト③ | AJ22: =IFERROR(MATCH(AI22,年計!$C$2:$C$368,0),"") | AM22: 月２ | AN22: 火２ | AO22: 水２ | AP22: 木２ | AQ22: 金２ | AR22: 月２ | AS22: 火２ | AT22: 水２ | AU22: 木２ | AV22: 金２ | AW22: 月２ | AX22: 火２ | AY22: 水２ | AZ22: 木２ | BA22: 金２ | BB22: 月２ | BC22: 火２ | BD22: 水２ | BE22: 木２ | BF22: 金２ | BG22: 月２ | BH22: 火２ | BI22: 水２ | BJ22: 木２ | BK22: 金２ | BL22: 月２ | BM22: 火２ | BN22: 水２ | BO22: 木２ | BP22: 金２
A23: 2 | B23: =COUNTIF(年計!$D$87:$I$181,AM22) -> 5 | C23: =COUNTIF(年計!$D$87:$I$181,AN22) -> 6 | D23: =COUNTIF(年計!$D$87:$I$181,AO22) -> 6 | E23: =COUNTIF(年計!$D$87:$I$181,AP22) -> 6 | F23: =COUNTIF(年計!$D$87:$I$181,AQ22) -> 5 | G23: =COUNTIF(年計!$J$87:$O$181,AR22) -> 5 | H23: =COUNTIF(年計!$J$87:$O$181,AS22) -> 6 | I23: =COUNTIF(年計!$J$87:$O$181,AT22) -> 6 | J23: =COUNTIF(年計!$J$87:$O$181,AU22) -> 6 | K23: =COUNTIF(年計!$J$87:$O$181,AV22) -> 5 | L23: =COUNTIF(年計!$P$87:$U$181,AW22) -> 5 | M23: =COUNTIF(年計!$P$87:$U$181,AX22) -> 6 | N23: =COUNTIF(年計!$P$87:$U$181,AY22) -> 6 | O23: =COUNTIF(年計!$P$87:$U$181,AZ22) -> 6 | P23: =COUNTIF(年計!$P$87:$U$181,BA22) -> 5 | S23: 2 | T23: =COUNTIF(年計!$D$3:$I$181,BB22) -> 14 | U23: =COUNTIF(年計!$D$3:$I$181,BC22) -> 15 | V23: =COUNTIF(年計!$D$3:$I$181,BD22) -> 14 | W23: =COUNTIF(年計!$D$3:$I$181,BE22) -> 15 | X23: =COUNTIF(年計!$D$3:$I$181,BF22) -> 14 | Y23: =COUNTIF(年計!$J$3:$O$181,BG22) -> 14 | Z23: =COUNTIF(年計!$J$3:$O$181,BH22) -> 15 | AA23: =COUNTIF(年計!$J$3:$O$181,BI22) -> 14 | AB23: =COUNTIF(年計!$J$3:$O$181,BJ22) -> 15 | AC23: =COUNTIF(年計!$J$3:$O$181,BK22) -> 14 | AD23: =COUNTIF(年計!$P$3:$U$181,BL22) -> 13 | AE23: =COUNTIF(年計!$P$3:$U$181,BM22) -> 14 | AF23: =COUNTIF(年計!$P$3:$U$181,BN22) -> 13 | AG23: =COUNTIF(年計!$P$3:$U$181,BO22) -> 12 | AH23: =COUNTIF(年計!$P$3:$U$181,BP22) -> 13 | AM23: 月３ | AN23: 火３ | AO23: 水３ | AP23: 木３ | AQ23: 金３ | AR23: 月３ | AS23: 火３ | AT23: 水３ | AU23: 木３ | AV23: 金３ | AW23: 月３ | AX23: 火３ | AY23: 水３ | AZ23: 木３ | BA23: 金３ | BB23: 月３ | BC23: 火３ | BD23: 水３ | BE23: 木３ | BF23: 金３ | BG23: 月３ | BH23: 火３ | BI23: 水３ | BJ23: 木３ | BK23: 金３ | BL23: 月３ | BM23: 火３ | BN23: 水３ | BO23: 木３ | BP23: 金３
A24: 3 | B24: =COUNTIF(年計!$D$87:$I$181,AM23) -> 5 | C24: =COUNTIF(年計!$D$87:$I$181,AN23) -> 5 | D24: =COUNTIF(年計!$D$87:$I$181,AO23) -> 6 | E24: =COUNTIF(年計!$D$87:$I$181,AP23) -> 6 | F24: =COUNTIF(年計!$D$87:$I$181,AQ23) -> 5 | G24: =COUNTIF(年計!$J$87:$O$181,AR23) -> 5 | H24: =COUNTIF(年計!$J$87:$O$181,AS23) -> 5 | I24: =COUNTIF(年計!$J$87:$O$181,AT23) -> 6 | J24: =COUNTIF(年計!$J$87:$O$181,AU23) -> 6 | K24: =COUNTIF(年計!$J$87:$O$181,AV23) -> 5 | L24: =COUNTIF(年計!$P$87:$U$181,AW23) -> 5 | M24: =COUNTIF(年計!$P$87:$U$181,AX23) -> 5 | N24: =COUNTIF(年計!$P$87:$U$181,AY23) -> 6 | O24: =COUNTIF(年計!$P$87:$U$181,AZ23) -> 5 | P24: =COUNTIF(年計!$P$87:$U$181,BA23) -> 5 | S24: 3 | T24: =COUNTIF(年計!$D$3:$I$181,BB23) -> 14 | U24: =COUNTIF(年計!$D$3:$I$181,BC23) -> 14 | V24: =COUNTIF(年計!$D$3:$I$181,BD23) -> 14 | W24: =COUNTIF(年計!$D$3:$I$181,BE23) -> 15 | X24: =COUNTIF(年計!$D$3:$I$181,BF23) -> 14 | Y24: =COUNTIF(年計!$J$3:$O$181,BG23) -> 14 | Z24: =COUNTIF(年計!$J$3:$O$181,BH23) -> 14 | AA24: =COUNTIF(年計!$J$3:$O$181,BI23) -> 14 | AB24: =COUNTIF(年計!$J$3:$O$181,BJ23) -> 15 | AC24: =COUNTIF(年計!$J$3:$O$181,BK23) -> 14 | AD24: =COUNTIF(年計!$P$3:$U$181,BL23) -> 13 | AE24: =COUNTIF(年計!$P$3:$U$181,BM23) -> 13 | AF24: =COUNTIF(年計!$P$3:$U$181,BN23) -> 13 | AG24: =COUNTIF(年計!$P$3:$U$181,BO23) -> 11 | AH24: =COUNTIF(年計!$P$3:$U$181,BP23) -> 13 | AM24: 月４ | AN24: 火４ | AO24: 水４ | AP24: 木４ | AQ24: 金４ | AR24: 月４ | AS24: 火４ | AT24: 水４ | AU24: 木４ | AV24: 金４ | AW24: 月４ | AX24: 火４ | AY24: 水４ | AZ24: 木４ | BA24: 金４ | BB24: 月４ | BC24: 火４ | BD24: 水４ | BE24: 木４ | BF24: 金４ | BG24: 月４ | BH24: 火４ | BI24: 水４ | BJ24: 木４ | BK24: 金４ | BL24: 月４ | BM24: 火４ | BN24: 水４ | BO24: 木４ | BP24: 金４
A25: 4 | B25: =COUNTIF(年計!$D$87:$I$181,AM24) -> 6 | C25: =COUNTIF(年計!$D$87:$I$181,AN24) -> 6 | D25: =COUNTIF(年計!$D$87:$I$181,AO24) -> 5 | E25: =COUNTIF(年計!$D$87:$I$181,AP24) -> 6 | F25: =COUNTIF(年計!$D$87:$I$181,AQ24) -> 5 | G25: =COUNTIF(年計!$J$87:$O$181,AR24) -> 6 | H25: =COUNTIF(年計!$J$87:$O$181,AS24) -> 6 | I25: =COUNTIF(年計!$J$87:$O$181,AT24) -> 5 | J25: =COUNTIF(年計!$J$87:$O$181,AU24) -> 6 | K25: =COUNTIF(年計!$J$87:$O$181,AV24) -> 5 | L25: =COUNTIF(年計!$P$87:$U$181,AW24) -> 5 | M25: =COUNTIF(年計!$P$87:$U$181,AX24) -> 6 | N25: =COUNTIF(年計!$P$87:$U$181,AY24) -> 5 | O25: =COUNTIF(年計!$P$87:$U$181,AZ24) -> 6 | P25: =COUNTIF(年計!$P$87:$U$181,BA24) -> 5 | S25: 4 | T25: =COUNTIF(年計!$D$3:$I$181,BB24) -> 15 | U25: =COUNTIF(年計!$D$3:$I$181,BC24) -> 14 | V25: =COUNTIF(年計!$D$3:$I$181,BD24) -> 14 | W25: =COUNTIF(年計!$D$3:$I$181,BE24) -> 15 | X25: =COUNTIF(年計!$D$3:$I$181,BF24) -> 14 | Y25: =COUNTIF(年計!$J$3:$O$181,BG24) -> 15 | Z25: =COUNTIF(年計!$J$3:$O$181,BH24) -> 14 | AA25: =COUNTIF(年計!$J$3:$O$181,BI24) -> 14 | AB25: =COUNTIF(年計!$J$3:$O$181,BJ24) -> 15 | AC25: =COUNTIF(年計!$J$3:$O$181,BK24) -> 14 | AD25: =COUNTIF(年計!$P$3:$U$181,BL24) -> 13 | AE25: =COUNTIF(年計!$P$3:$U$181,BM24) -> 13 | AF25: =COUNTIF(年計!$P$3:$U$181,BN24) -> 13 | AG25: =COUNTIF(年計!$P$3:$U$181,BO24) -> 13 | AH25: =COUNTIF(年計!$P$3:$U$181,BP24) -> 13 | AM25: 月５ | AN25: 火５ | AO25: 水５ | AP25: 木５ | AQ25: 金５ | AR25: 月５ | AS25: 火５ | AT25: 水５ | AU25: 木５ | AV25: 金５ | AW25: 月５ | AX25: 火５ | AY25: 水５ | AZ25: 木５ | BA25: 金５ | BB25: 月５ | BC25: 火５ | BD25: 水５ | BE25: 木５ | BF25: 金５ | BG25: 月５ | BH25: 火５ | BI25: 水５ | BJ25: 木５ | BK25: 金５ | BL25: 月５ | BM25: 火５ | BN25: 水５ | BO25: 木５ | BP25: 金５
A26: 5 | B26: =COUNTIF(年計!$D$87:$I$181,AM25) -> 5 | C26: =COUNTIF(年計!$D$87:$I$181,AN25) -> 4 | D26: =COUNTIF(年計!$D$87:$I$181,AO25) -> 4 | E26: =COUNTIF(年計!$D$87:$I$181,AP25) -> 5 | F26: =COUNTIF(年計!$D$87:$I$181,AQ25) -> 5 | G26: =COUNTIF(年計!$J$87:$O$181,AR25) -> 5 | H26: =COUNTIF(年計!$J$87:$O$181,AS25) -> 4 | I26: =COUNTIF(年計!$J$87:$O$181,AT25) -> 4 | J26: =COUNTIF(年計!$J$87:$O$181,AU25) -> 5 | K26: =COUNTIF(年計!$J$87:$O$181,AV25) -> 5 | L26: =COUNTIF(年計!$P$87:$U$181,AW25) -> 5 | M26: =COUNTIF(年計!$P$87:$U$181,AX25) -> 4 | N26: =COUNTIF(年計!$P$87:$U$181,AY25) -> 4 | O26: =COUNTIF(年計!$P$87:$U$181,AZ25) -> 4 | P26: =COUNTIF(年計!$P$87:$U$181,BA25) -> 4 | S26: 5 | T26: =COUNTIF(年計!$D$3:$I$181,BB25) -> 13 | U26: =COUNTIF(年計!$D$3:$I$181,BC25) -> 12 | V26: =COUNTIF(年計!$D$3:$I$181,BD25) -> 12 | W26: =COUNTIF(年計!$D$3:$I$181,BE25) -> 14 | X26: =COUNTIF(年計!$D$3:$I$181,BF25) -> 13 | Y26: =COUNTIF(年計!$J$3:$O$181,BG25) -> 13 | Z26: =COUNTIF(年計!$J$3:$O$181,BH25) -> 12 | AA26: =COUNTIF(年計!$J$3:$O$181,BI25) -> 12 | AB26: =COUNTIF(年計!$J$3:$O$181,BJ25) -> 14 | AC26: =COUNTIF(年計!$J$3:$O$181,BK25) -> 13 | AD26: =COUNTIF(年計!$P$3:$U$181,BL25) -> 11 | AE26: =COUNTIF(年計!$P$3:$U$181,BM25) -> 11 | AF26: =COUNTIF(年計!$P$3:$U$181,BN25) -> 11 | AG26: =COUNTIF(年計!$P$3:$U$181,BO25) -> 11 | AH26: =COUNTIF(年計!$P$3:$U$181,BP25) -> 11 | AM26: 月６ | AN26: 火６ | AO26: 水６ | AP26: 木６ | AQ26: 金６ | AR26: 月６ | AS26: 火６ | AT26: 水６ | AU26: 木６ | AV26: 金６ | AW26: 月６ | AX26: 火６ | AY26: 水６ | AZ26: 木６ | BA26: 金６ | BB26: 月６ | BC26: 火６ | BD26: 水６ | BE26: 木６ | BF26: 金６ | BG26: 月６ | BH26: 火６ | BI26: 水６ | BJ26: 木６ | BK26: 金６ | BL26: 月６ | BM26: 火６ | BN26: 水６ | BO26: 木６ | BP26: 金６
A27: 6 | B27: =COUNTIF(年計!$D$87:$I$181,AM26) -> 5 | C27: =COUNTIF(年計!$D$87:$I$181,AN26) -> 6 | D27: =COUNTIF(年計!$D$87:$I$181,AO26) -> 5 | E27: =COUNTIF(年計!$D$87:$I$181,AP26) -> 0 | F27: =COUNTIF(年計!$D$87:$I$181,AQ26) -> 6 | G27: =COUNTIF(年計!$J$87:$O$181,AR26) -> 5 | H27: =COUNTIF(年計!$J$87:$O$181,AS26) -> 6 | I27: =COUNTIF(年計!$J$87:$O$181,AT26) -> 5 | J27: =COUNTIF(年計!$J$87:$O$181,AU26) -> 0 | K27: =COUNTIF(年計!$J$87:$O$181,AV26) -> 6 | L27: =COUNTIF(年計!$P$87:$U$181,AW26) -> 5 | M27: =COUNTIF(年計!$P$87:$U$181,AX26) -> 6 | N27: =COUNTIF(年計!$P$87:$U$181,AY26) -> 5 | O27: =COUNTIF(年計!$P$87:$U$181,AZ26) -> 0 | P27: =COUNTIF(年計!$P$87:$U$181,BA26) -> 5 | S27: 6 | T27: =COUNTIF(年計!$D$3:$I$181,BB26) -> 14 | U27: =COUNTIF(年計!$D$3:$I$181,BC26) -> 14 | V27: =COUNTIF(年計!$D$3:$I$181,BD26) -> 14 | W27: =COUNTIF(年計!$D$3:$I$181,BE26) -> 0 | X27: =COUNTIF(年計!$D$3:$I$181,BF26) -> 15 | Y27: =COUNTIF(年計!$J$3:$O$181,BG26) -> 14 | Z27: =COUNTIF(年計!$J$3:$O$181,BH26) -> 14 | AA27: =COUNTIF(年計!$J$3:$O$181,BI26) -> 14 | AB27: =COUNTIF(年計!$J$3:$O$181,BJ26) -> 0 | AC27: =COUNTIF(年計!$J$3:$O$181,BK26) -> 15 | AD27: =COUNTIF(年計!$P$3:$U$181,BL26) -> 13 | AE27: =COUNTIF(年計!$P$3:$U$181,BM26) -> 12 | AF27: =COUNTIF(年計!$P$3:$U$181,BN26) -> 13 | AG27: =COUNTIF(年計!$P$3:$U$181,BO26) -> 0 | AH27: =COUNTIF(年計!$P$3:$U$181,BP26) -> 12
A28: ＜２期中テ～２期末テ＞ | S28: ＜２期末テまで 累計＞
B29: 月 | C29: 火 | D29: 水 | E29: 木 | F29: 金 | G29: 月 | H29: 火 | I29: 水 | J29: 木 | K29: 金 | L29: 月 | M29: 火 | N29: 水 | O29: 木 | P29: 金 | T29: 月 | U29: 火 | V29: 水 | W29: 木 | X29: 金 | Y29: 月 | Z29: 火 | AA29: 水 | AB29: 木 | AC29: 金 | AD29: 月 | AE29: 火 | AF29: 水 | AG29: 木 | AH29: 金 | AM29: 月１ | AN29: 火１ | AO29: 水１ | AP29: 木１ | AQ29: 金１ | AR29: 月１ | AS29: 火１ | AT29: 水１ | AU29: 木１ | AV29: 金１ | AW29: 月１ | AX29: 火１ | AY29: 水１ | AZ29: 木１ | BA29: 金１ | BB29: 月１ | BC29: 火１ | BD29: 水１ | BE29: 木１ | BF29: 金１ | BG29: 月１ | BH29: 火１ | BI29: 水１ | BJ29: 木１ | BK29: 金１ | BL29: 月１ | BM29: 火１ | BN29: 水１ | BO29: 木１ | BP29: 金１
A30: 1 | B30: =COUNTIF(年計!$D$182:$I$232,AM29) -> 6 | C30: =COUNTIF(年計!$D$182:$I$232,AN29) -> 5 | D30: =COUNTIF(年計!$D$182:$I$232,AO29) -> 6 | E30: =COUNTIF(年計!$D$182:$I$232,AP29) -> 5 | F30: =COUNTIF(年計!$D$182:$I$232,AQ29) -> 6 | G30: =COUNTIF(年計!$J$182:$O$232,AR29) -> 6 | H30: =COUNTIF(年計!$J$182:$O$232,AS29) -> 5 | I30: =COUNTIF(年計!$J$182:$O$232,AT29) -> 6 | J30: =COUNTIF(年計!$J$182:$O$232,AU29) -> 5 | K30: =COUNTIF(年計!$J$182:$O$232,AV29) -> 6 | L30: =COUNTIF(年計!$P$182:$U$232,AW29) -> 6 | M30: =COUNTIF(年計!$P$182:$U$232,AX29) -> 5 | N30: =COUNTIF(年計!$P$182:$U$232,AY29) -> 6 | O30: =COUNTIF(年計!$P$182:$U$232,AZ29) -> 5 | P30: =COUNTIF(年計!$P$182:$U$232,BA29) -> 5 | S30: 1 | T30: =COUNTIF(年計!$D$3:$I$232,BB29) -> 19 | U30: =COUNTIF(年計!$D$3:$I$232,BC29) -> 19 | V30: =COUNTIF(年計!$D$3:$I$232,BD29) -> 19 | W30: =COUNTIF(年計!$D$3:$I$232,BE29) -> 19 | X30: =COUNTIF(年計!$D$3:$I$232,BF29) -> 19 | Y30: =COUNTIF(年計!$J$3:$O$232,BG29) -> 19 | Z30: =COUNTIF(年計!$J$3:$O$232,BH29) -> 19 | AA30: =COUNTIF(年計!$J$3:$O$232,BI29) -> 19 | AB30: =COUNTIF(年計!$J$3:$O$232,BJ29) -> 19 | AC30: =COUNTIF(年計!$J$3:$O$232,BK29) -> 19 | AD30: =COUNTIF(年計!$P$3:$U$232,BL29) -> 18 | AE30: =COUNTIF(年計!$P$3:$U$232,BM29) -> 17 | AF30: =COUNTIF(年計!$P$3:$U$232,BN29) -> 19 | AG30: =COUNTIF(年計!$P$3:$U$232,BO29) -> 16 | AH30: =COUNTIF(年計!$P$3:$U$232,BP29) -> 18 | AI30: 定期テスト④ | AJ30: =IFERROR(MATCH(AI30,年計!$C$2:$C$368,0),"") | AM30: 月２ | AN30: 火２ | AO30: 水２ | AP30: 木２ | AQ30: 金２ | AR30: 月２ | AS30: 火２ | AT30: 水２ | AU30: 木２ | AV30: 金２ | AW30: 月２ | AX30: 火２ | AY30: 水２ | AZ30: 木２ | BA30: 金２ | BB30: 月２ | BC30: 火２ | BD30: 水２ | BE30: 木２ | BF30: 金２ | BG30: 月２ | BH30: 火２ | BI30: 水２ | BJ30: 木２ | BK30: 金２ | BL30: 月２ | BM30: 火２ | BN30: 水２ | BO30: 木２ | BP30: 金２
A31: 2 | B31: =COUNTIF(年計!$D$182:$I$232,AM30) -> 6 | C31: =COUNTIF(年計!$D$182:$I$232,AN30) -> 5 | D31: =COUNTIF(年計!$D$182:$I$232,AO30) -> 5 | E31: =COUNTIF(年計!$D$182:$I$232,AP30) -> 5 | F31: =COUNTIF(年計!$D$182:$I$232,AQ30) -> 6 | G31: =COUNTIF(年計!$J$182:$O$232,AR30) -> 6 | H31: =COUNTIF(年計!$J$182:$O$232,AS30) -> 5 | I31: =COUNTIF(年計!$J$182:$O$232,AT30) -> 5 | J31: =COUNTIF(年計!$J$182:$O$232,AU30) -> 5 | K31: =COUNTIF(年計!$J$182:$O$232,AV30) -> 6 | L31: =COUNTIF(年計!$P$182:$U$232,AW30) -> 6 | M31: =COUNTIF(年計!$P$182:$U$232,AX30) -> 5 | N31: =COUNTIF(年計!$P$182:$U$232,AY30) -> 5 | O31: =COUNTIF(年計!$P$182:$U$232,AZ30) -> 5 | P31: =COUNTIF(年計!$P$182:$U$232,BA30) -> 5 | S31: 2 | T31: =COUNTIF(年計!$D$3:$I$232,BB30) -> 20 | U31: =COUNTIF(年計!$D$3:$I$232,BC30) -> 20 | V31: =COUNTIF(年計!$D$3:$I$232,BD30) -> 19 | W31: =COUNTIF(年計!$D$3:$I$232,BE30) -> 20 | X31: =COUNTIF(年計!$D$3:$I$232,BF30) -> 20 | Y31: =COUNTIF(年計!$J$3:$O$232,BG30) -> 20 | Z31: =COUNTIF(年計!$J$3:$O$232,BH30) -> 20 | AA31: =COUNTIF(年計!$J$3:$O$232,BI30) -> 19 | AB31: =COUNTIF(年計!$J$3:$O$232,BJ30) -> 20 | AC31: =COUNTIF(年計!$J$3:$O$232,BK30) -> 20 | AD31: =COUNTIF(年計!$P$3:$U$232,BL30) -> 19 | AE31: =COUNTIF(年計!$P$3:$U$232,BM30) -> 19 | AF31: =COUNTIF(年計!$P$3:$U$232,BN30) -> 18 | AG31: =COUNTIF(年計!$P$3:$U$232,BO30) -> 17 | AH31: =COUNTIF(年計!$P$3:$U$232,BP30) -> 18 | AM31: 月３ | AN31: 火３ | AO31: 水３ | AP31: 木３ | AQ31: 金３ | AR31: 月３ | AS31: 火３ | AT31: 水３ | AU31: 木３ | AV31: 金３ | AW31: 月３ | AX31: 火３ | AY31: 水３ | AZ31: 木３ | BA31: 金３ | BB31: 月３ | BC31: 火３ | BD31: 水３ | BE31: 木３ | BF31: 金３ | BG31: 月３ | BH31: 火３ | BI31: 水３ | BJ31: 木３ | BK31: 金３ | BL31: 月３ | BM31: 火３ | BN31: 水３ | BO31: 木３ | BP31: 金３
A32: 3 | B32: =COUNTIF(年計!$D$182:$I$232,AM31) -> 6 | C32: =COUNTIF(年計!$D$182:$I$232,AN31) -> 6 | D32: =COUNTIF(年計!$D$182:$I$232,AO31) -> 5 | E32: =COUNTIF(年計!$D$182:$I$232,AP31) -> 5 | F32: =COUNTIF(年計!$D$182:$I$232,AQ31) -> 6 | G32: =COUNTIF(年計!$J$182:$O$232,AR31) -> 6 | H32: =COUNTIF(年計!$J$182:$O$232,AS31) -> 6 | I32: =COUNTIF(年計!$J$182:$O$232,AT31) -> 5 | J32: =COUNTIF(年計!$J$182:$O$232,AU31) -> 5 | K32: =COUNTIF(年計!$J$182:$O$232,AV31) -> 6 | L32: =COUNTIF(年計!$P$182:$U$232,AW31) -> 6 | M32: =COUNTIF(年計!$P$182:$U$232,AX31) -> 6 | N32: =COUNTIF(年計!$P$182:$U$232,AY31) -> 5 | O32: =COUNTIF(年計!$P$182:$U$232,AZ31) -> 5 | P32: =COUNTIF(年計!$P$182:$U$232,BA31) -> 5 | S32: 3 | T32: =COUNTIF(年計!$D$3:$I$232,BB31) -> 20 | U32: =COUNTIF(年計!$D$3:$I$232,BC31) -> 20 | V32: =COUNTIF(年計!$D$3:$I$232,BD31) -> 19 | W32: =COUNTIF(年計!$D$3:$I$232,BE31) -> 20 | X32: =COUNTIF(年計!$D$3:$I$232,BF31) -> 20 | Y32: =COUNTIF(年計!$J$3:$O$232,BG31) -> 20 | Z32: =COUNTIF(年計!$J$3:$O$232,BH31) -> 20 | AA32: =COUNTIF(年計!$J$3:$O$232,BI31) -> 19 | AB32: =COUNTIF(年計!$J$3:$O$232,BJ31) -> 20 | AC32: =COUNTIF(年計!$J$3:$O$232,BK31) -> 20 | AD32: =COUNTIF(年計!$P$3:$U$232,BL31) -> 19 | AE32: =COUNTIF(年計!$P$3:$U$232,BM31) -> 19 | AF32: =COUNTIF(年計!$P$3:$U$232,BN31) -> 18 | AG32: =COUNTIF(年計!$P$3:$U$232,BO31) -> 16 | AH32: =COUNTIF(年計!$P$3:$U$232,BP31) -> 18 | AM32: 月４ | AN32: 火４ | AO32: 水４ | AP32: 木４ | AQ32: 金４ | AR32: 月４ | AS32: 火４ | AT32: 水４ | AU32: 木４ | AV32: 金４ | AW32: 月４ | AX32: 火４ | AY32: 水４ | AZ32: 木４ | BA32: 金４ | BB32: 月４ | BC32: 火４ | BD32: 水４ | BE32: 木４ | BF32: 金４ | BG32: 月４ | BH32: 火４ | BI32: 水４ | BJ32: 木４ | BK32: 金４ | BL32: 月４ | BM32: 火４ | BN32: 水４ | BO32: 木４ | BP32: 金４
A33: 4 | B33: =COUNTIF(年計!$D$182:$I$232,AM32) -> 5 | C33: =COUNTIF(年計!$D$182:$I$232,AN32) -> 5 | D33: =COUNTIF(年計!$D$182:$I$232,AO32) -> 5 | E33: =COUNTIF(年計!$D$182:$I$232,AP32) -> 5 | F33: =COUNTIF(年計!$D$182:$I$232,AQ32) -> 5 | G33: =COUNTIF(年計!$J$182:$O$232,AR32) -> 5 | H33: =COUNTIF(年計!$J$182:$O$232,AS32) -> 5 | I33: =COUNTIF(年計!$J$182:$O$232,AT32) -> 5 | J33: =COUNTIF(年計!$J$182:$O$232,AU32) -> 5 | K33: =COUNTIF(年計!$J$182:$O$232,AV32) -> 5 | L33: =COUNTIF(年計!$P$182:$U$232,AW32) -> 5 | M33: =COUNTIF(年計!$P$182:$U$232,AX32) -> 5 | N33: =COUNTIF(年計!$P$182:$U$232,AY32) -> 5 | O33: =COUNTIF(年計!$P$182:$U$232,AZ32) -> 5 | P33: =COUNTIF(年計!$P$182:$U$232,BA32) -> 4 | S33: 4 | T33: =COUNTIF(年計!$D$3:$I$232,BB32) -> 20 | U33: =COUNTIF(年計!$D$3:$I$232,BC32) -> 19 | V33: =COUNTIF(年計!$D$3:$I$232,BD32) -> 19 | W33: =COUNTIF(年計!$D$3:$I$232,BE32) -> 20 | X33: =COUNTIF(年計!$D$3:$I$232,BF32) -> 19 | Y33: =COUNTIF(年計!$J$3:$O$232,BG32) -> 20 | Z33: =COUNTIF(年計!$J$3:$O$232,BH32) -> 19 | AA33: =COUNTIF(年計!$J$3:$O$232,BI32) -> 19 | AB33: =COUNTIF(年計!$J$3:$O$232,BJ32) -> 20 | AC33: =COUNTIF(年計!$J$3:$O$232,BK32) -> 19 | AD33: =COUNTIF(年計!$P$3:$U$232,BL32) -> 18 | AE33: =COUNTIF(年計!$P$3:$U$232,BM32) -> 18 | AF33: =COUNTIF(年計!$P$3:$U$232,BN32) -> 18 | AG33: =COUNTIF(年計!$P$3:$U$232,BO32) -> 18 | AH33: =COUNTIF(年計!$P$3:$U$232,BP32) -> 17 | AM33: 月５ | AN33: 火５ | AO33: 水５ | AP33: 木５ | AQ33: 金５ | AR33: 月５ | AS33: 火５ | AT33: 水５ | AU33: 木５ | AV33: 金５ | AW33: 月５ | AX33: 火５ | AY33: 水５ | AZ33: 木５ | BA33: 金５ | BB33: 月５ | BC33: 火５ | BD33: 水５ | BE33: 木５ | BF33: 金５ | BG33: 月５ | BH33: 火５ | BI33: 水５ | BJ33: 木５ | BK33: 金５ | BL33: 月５ | BM33: 火５ | BN33: 水５ | BO33: 木５ | BP33: 金５
A34: 5 | B34: =COUNTIF(年計!$D$182:$I$232,AM33) -> 5 | C34: =COUNTIF(年計!$D$182:$I$232,AN33) -> 5 | D34: =COUNTIF(年計!$D$182:$I$232,AO33) -> 5 | E34: =COUNTIF(年計!$D$182:$I$232,AP33) -> 4 | F34: =COUNTIF(年計!$D$182:$I$232,AQ33) -> 5 | G34: =COUNTIF(年計!$J$182:$O$232,AR33) -> 5 | H34: =COUNTIF(年計!$J$182:$O$232,AS33) -> 5 | I34: =COUNTIF(年計!$J$182:$O$232,AT33) -> 5 | J34: =COUNTIF(年計!$J$182:$O$232,AU33) -> 4 | K34: =COUNTIF(年計!$J$182:$O$232,AV33) -> 5 | L34: =COUNTIF(年計!$P$182:$U$232,AW33) -> 5 | M34: =COUNTIF(年計!$P$182:$U$232,AX33) -> 4 | N34: =COUNTIF(年計!$P$182:$U$232,AY33) -> 5 | O34: =COUNTIF(年計!$P$182:$U$232,AZ33) -> 4 | P34: =COUNTIF(年計!$P$182:$U$232,BA33) -> 4 | S34: 5 | T34: =COUNTIF(年計!$D$3:$I$232,BB33) -> 18 | U34: =COUNTIF(年計!$D$3:$I$232,BC33) -> 17 | V34: =COUNTIF(年計!$D$3:$I$232,BD33) -> 17 | W34: =COUNTIF(年計!$D$3:$I$232,BE33) -> 18 | X34: =COUNTIF(年計!$D$3:$I$232,BF33) -> 18 | Y34: =COUNTIF(年計!$J$3:$O$232,BG33) -> 18 | Z34: =COUNTIF(年計!$J$3:$O$232,BH33) -> 17 | AA34: =COUNTIF(年計!$J$3:$O$232,BI33) -> 17 | AB34: =COUNTIF(年計!$J$3:$O$232,BJ33) -> 18 | AC34: =COUNTIF(年計!$J$3:$O$232,BK33) -> 18 | AD34: =COUNTIF(年計!$P$3:$U$232,BL33) -> 16 | AE34: =COUNTIF(年計!$P$3:$U$232,BM33) -> 15 | AF34: =COUNTIF(年計!$P$3:$U$232,BN33) -> 16 | AG34: =COUNTIF(年計!$P$3:$U$232,BO33) -> 15 | AH34: =COUNTIF(年計!$P$3:$U$232,BP33) -> 15 | AM34: 月６ | AN34: 火６ | AO34: 水６ | AP34: 木６ | AQ34: 金６ | AR34: 月６ | AS34: 火６ | AT34: 水６ | AU34: 木６ | AV34: 金６ | AW34: 月６ | AX34: 火６ | AY34: 水６ | AZ34: 木６ | BA34: 金６ | BB34: 月６ | BC34: 火６ | BD34: 水６ | BE34: 木６ | BF34: 金６ | BG34: 月６ | BH34: 火６ | BI34: 水６ | BJ34: 木６ | BK34: 金６ | BL34: 月６ | BM34: 火６ | BN34: 水６ | BO34: 木６ | BP34: 金６
A35: 6 | B35: =COUNTIF(年計!$D$182:$I$232,AM34) -> 5 | C35: =COUNTIF(年計!$D$182:$I$232,AN34) -> 6 | D35: =COUNTIF(年計!$D$182:$I$232,AO34) -> 5 | E35: =COUNTIF(年計!$D$182:$I$232,AP34) -> 0 | F35: =COUNTIF(年計!$D$182:$I$232,AQ34) -> 5 | G35: =COUNTIF(年計!$J$182:$O$232,AR34) -> 5 | H35: =COUNTIF(年計!$J$182:$O$232,AS34) -> 6 | I35: =COUNTIF(年計!$J$182:$O$232,AT34) -> 5 | J35: =COUNTIF(年計!$J$182:$O$232,AU34) -> 0 | K35: =COUNTIF(年計!$J$182:$O$232,AV34) -> 5 | L35: =COUNTIF(年計!$P$182:$U$232,AW34) -> 5 | M35: =COUNTIF(年計!$P$182:$U$232,AX34) -> 5 | N35: =COUNTIF(年計!$P$182:$U$232,AY34) -> 5 | O35: =COUNTIF(年計!$P$182:$U$232,AZ34) -> 0 | P35: =COUNTIF(年計!$P$182:$U$232,BA34) -> 5 | S35: 6 | T35: =COUNTIF(年計!$D$3:$I$232,BB34) -> 19 | U35: =COUNTIF(年計!$D$3:$I$232,BC34) -> 20 | V35: =COUNTIF(年計!$D$3:$I$232,BD34) -> 19 | W35: =COUNTIF(年計!$D$3:$I$232,BE34) -> 0 | X35: =COUNTIF(年計!$D$3:$I$232,BF34) -> 20 | Y35: =COUNTIF(年計!$J$3:$O$232,BG34) -> 19 | Z35: =COUNTIF(年計!$J$3:$O$232,BH34) -> 20 | AA35: =COUNTIF(年計!$J$3:$O$232,BI34) -> 19 | AB35: =COUNTIF(年計!$J$3:$O$232,BJ34) -> 0 | AC35: =COUNTIF(年計!$J$3:$O$232,BK34) -> 20 | AD35: =COUNTIF(年計!$P$3:$U$232,BL34) -> 18 | AE35: =COUNTIF(年計!$P$3:$U$232,BM34) -> 17 | AF35: =COUNTIF(年計!$P$3:$U$232,BN34) -> 18 | AG35: =COUNTIF(年計!$P$3:$U$232,BO34) -> 0 | AH35: =COUNTIF(年計!$P$3:$U$232,BP34) -> 17
A36: ＜２期末テ～12月末＞ | S36: ＜12月末まで 累計＞
B37: 月 | C37: 火 | D37: 水 | E37: 木 | F37: 金 | G37: 月 | H37: 火 | I37: 水 | J37: 木 | K37: 金 | L37: 月 | M37: 火 | N37: 水 | O37: 木 | P37: 金 | T37: 月 | U37: 火 | V37: 水 | W37: 木 | X37: 金 | Y37: 月 | Z37: 火 | AA37: 水 | AB37: 木 | AC37: 金 | AD37: 月 | AE37: 火 | AF37: 水 | AG37: 木 | AH37: 金 | AM37: 月１ | AN37: 火１ | AO37: 水１ | AP37: 木１ | AQ37: 金１ | AR37: 月１ | AS37: 火１ | AT37: 水１ | AU37: 木１ | AV37: 金１ | AW37: 月１ | AX37: 火１ | AY37: 水１ | AZ37: 木１ | BA37: 金１ | BB37: 月１ | BC37: 火１ | BD37: 水１ | BE37: 木１ | BF37: 金１ | BG37: 月１ | BH37: 火１ | BI37: 水１ | BJ37: 木１ | BK37: 金１ | BL37: 月１ | BM37: 火１ | BN37: 水１ | BO37: 木１ | BP37: 金１
A38: 1 | B38: =COUNTIF(年計!$D$233:$I$277,AM37) -> 5 | C38: =COUNTIF(年計!$D$233:$I$277,AN37) -> 5 | D38: =COUNTIF(年計!$D$233:$I$277,AO37) -> 4 | E38: =COUNTIF(年計!$D$233:$I$277,AP37) -> 3 | F38: =COUNTIF(年計!$D$233:$I$277,AQ37) -> 4 | G38: =COUNTIF(年計!$J$233:$O$277,AR37) -> 5 | H38: =COUNTIF(年計!$J$233:$O$277,AS37) -> 5 | I38: =COUNTIF(年計!$J$233:$O$277,AT37) -> 4 | J38: =COUNTIF(年計!$J$233:$O$277,AU37) -> 3 | K38: =COUNTIF(年計!$J$233:$O$277,AV37) -> 4 | L38: =COUNTIF(年計!$P$233:$U$277,AW37) -> 5 | M38: =COUNTIF(年計!$P$233:$U$277,AX37) -> 5 | N38: =COUNTIF(年計!$P$233:$U$277,AY37) -> 4 | O38: =COUNTIF(年計!$P$233:$U$277,AZ37) -> 3 | P38: =COUNTIF(年計!$P$233:$U$277,BA37) -> 3 | S38: 1 | T38: =COUNTIF(年計!$D$3:$I$277,BB37) -> 24 | U38: =COUNTIF(年計!$D$3:$I$277,BC37) -> 24 | V38: =COUNTIF(年計!$D$3:$I$277,BD37) -> 23 | W38: =COUNTIF(年計!$D$3:$I$277,BE37) -> 22 | X38: =COUNTIF(年計!$D$3:$I$277,BF37) -> 23 | Y38: =COUNTIF(年計!$J$3:$O$277,BG37) -> 24 | Z38: =COUNTIF(年計!$J$3:$O$277,BH37) -> 24 | AA38: =COUNTIF(年計!$J$3:$O$277,BI37) -> 23 | AB38: =COUNTIF(年計!$J$3:$O$277,BJ37) -> 22 | AC38: =COUNTIF(年計!$J$3:$O$277,BK37) -> 23 | AD38: =COUNTIF(年計!$P$3:$U$277,BL37) -> 23 | AE38: =COUNTIF(年計!$P$3:$U$277,BM37) -> 22 | AF38: =COUNTIF(年計!$P$3:$U$277,BN37) -> 23 | AG38: =COUNTIF(年計!$P$3:$U$277,BO37) -> 19 | AH38: =COUNTIF(年計!$P$3:$U$277,BP37) -> 21 | AI38: 2学期終業式 | AJ38: =IFERROR(MATCH(AI38,年計!$C$2:$C$368,0),"") | AM38: 月２ | AN38: 火２ | AO38: 水２ | AP38: 木２ | AQ38: 金２ | AR38: 月２ | AS38: 火２ | AT38: 水２ | AU38: 木２ | AV38: 金２ | AW38: 月２ | AX38: 火２ | AY38: 水２ | AZ38: 木２ | BA38: 金２ | BB38: 月２ | BC38: 火２ | BD38: 水２ | BE38: 木２ | BF38: 金２ | BG38: 月２ | BH38: 火２ | BI38: 水２ | BJ38: 木２ | BK38: 金２ | BL38: 月２ | BM38: 火２ | BN38: 水２ | BO38: 木２ | BP38: 金２
A39: 2 | B39: =COUNTIF(年計!$D$233:$I$277,AM38) -> 4 | C39: =COUNTIF(年計!$D$233:$I$277,AN38) -> 5 | D39: =COUNTIF(年計!$D$233:$I$277,AO38) -> 4 | E39: =COUNTIF(年計!$D$233:$I$277,AP38) -> 4 | F39: =COUNTIF(年計!$D$233:$I$277,AQ38) -> 4 | G39: =COUNTIF(年計!$J$233:$O$277,AR38) -> 4 | H39: =COUNTIF(年計!$J$233:$O$277,AS38) -> 5 | I39: =COUNTIF(年計!$J$233:$O$277,AT38) -> 4 | J39: =COUNTIF(年計!$J$233:$O$277,AU38) -> 4 | K39: =COUNTIF(年計!$J$233:$O$277,AV38) -> 4 | L39: =COUNTIF(年計!$P$233:$U$277,AW38) -> 4 | M39: =COUNTIF(年計!$P$233:$U$277,AX38) -> 4 | N39: =COUNTIF(年計!$P$233:$U$277,AY38) -> 4 | O39: =COUNTIF(年計!$P$233:$U$277,AZ38) -> 4 | P39: =COUNTIF(年計!$P$233:$U$277,BA38) -> 4 | S39: 2 | T39: =COUNTIF(年計!$D$3:$I$277,BB38) -> 24 | U39: =COUNTIF(年計!$D$3:$I$277,BC38) -> 25 | V39: =COUNTIF(年計!$D$3:$I$277,BD38) -> 23 | W39: =COUNTIF(年計!$D$3:$I$277,BE38) -> 24 | X39: =COUNTIF(年計!$D$3:$I$277,BF38) -> 24 | Y39: =COUNTIF(年計!$J$3:$O$277,BG38) -> 24 | Z39: =COUNTIF(年計!$J$3:$O$277,BH38) -> 25 | AA39: =COUNTIF(年計!$J$3:$O$277,BI38) -> 23 | AB39: =COUNTIF(年計!$J$3:$O$277,BJ38) -> 24 | AC39: =COUNTIF(年計!$J$3:$O$277,BK38) -> 24 | AD39: =COUNTIF(年計!$P$3:$U$277,BL38) -> 23 | AE39: =COUNTIF(年計!$P$3:$U$277,BM38) -> 23 | AF39: =COUNTIF(年計!$P$3:$U$277,BN38) -> 22 | AG39: =COUNTIF(年計!$P$3:$U$277,BO38) -> 21 | AH39: =COUNTIF(年計!$P$3:$U$277,BP38) -> 22 | AM39: 月３ | AN39: 火３ | AO39: 水３ | AP39: 木３ | AQ39: 金３ | AR39: 月３ | AS39: 火３ | AT39: 水３ | AU39: 木３ | AV39: 金３ | AW39: 月３ | AX39: 火３ | AY39: 水３ | AZ39: 木３ | BA39: 金３ | BB39: 月３ | BC39: 火３ | BD39: 水３ | BE39: 木３ | BF39: 金３ | BG39: 月３ | BH39: 火３ | BI39: 水３ | BJ39: 木３ | BK39: 金３ | BL39: 月３ | BM39: 火３ | BN39: 水３ | BO39: 木３ | BP39: 金３
A40: 3 | B40: =COUNTIF(年計!$D$233:$I$277,AM39) -> 4 | C40: =COUNTIF(年計!$D$233:$I$277,AN39) -> 4 | D40: =COUNTIF(年計!$D$233:$I$277,AO39) -> 4 | E40: =COUNTIF(年計!$D$233:$I$277,AP39) -> 4 | F40: =COUNTIF(年計!$D$233:$I$277,AQ39) -> 5 | G40: =COUNTIF(年計!$J$233:$O$277,AR39) -> 4 | H40: =COUNTIF(年計!$J$233:$O$277,AS39) -> 4 | I40: =COUNTIF(年計!$J$233:$O$277,AT39) -> 5 | J40: =COUNTIF(年計!$J$233:$O$277,AU39) -> 4 | K40: =COUNTIF(年計!$J$233:$O$277,AV39) -> 5 | L40: =COUNTIF(年計!$P$233:$U$277,AW39) -> 4 | M40: =COUNTIF(年計!$P$233:$U$277,AX39) -> 4 | N40: =COUNTIF(年計!$P$233:$U$277,AY39) -> 4 | O40: =COUNTIF(年計!$P$233:$U$277,AZ39) -> 4 | P40: =COUNTIF(年計!$P$233:$U$277,BA39) -> 4 | S40: 3 | T40: =COUNTIF(年計!$D$3:$I$277,BB39) -> 24 | U40: =COUNTIF(年計!$D$3:$I$277,BC39) -> 24 | V40: =COUNTIF(年計!$D$3:$I$277,BD39) -> 23 | W40: =COUNTIF(年計!$D$3:$I$277,BE39) -> 24 | X40: =COUNTIF(年計!$D$3:$I$277,BF39) -> 25 | Y40: =COUNTIF(年計!$J$3:$O$277,BG39) -> 24 | Z40: =COUNTIF(年計!$J$3:$O$277,BH39) -> 24 | AA40: =COUNTIF(年計!$J$3:$O$277,BI39) -> 24 | AB40: =COUNTIF(年計!$J$3:$O$277,BJ39) -> 24 | AC40: =COUNTIF(年計!$J$3:$O$277,BK39) -> 25 | AD40: =COUNTIF(年計!$P$3:$U$277,BL39) -> 23 | AE40: =COUNTIF(年計!$P$3:$U$277,BM39) -> 23 | AF40: =COUNTIF(年計!$P$3:$U$277,BN39) -> 22 | AG40: =COUNTIF(年計!$P$3:$U$277,BO39) -> 20 | AH40: =COUNTIF(年計!$P$3:$U$277,BP39) -> 22 | AM40: 月４ | AN40: 火４ | AO40: 水４ | AP40: 木４ | AQ40: 金４ | AR40: 月４ | AS40: 火４ | AT40: 水４ | AU40: 木４ | AV40: 金４ | AW40: 月４ | AX40: 火４ | AY40: 水４ | AZ40: 木４ | BA40: 金４ | BB40: 月４ | BC40: 火４ | BD40: 水４ | BE40: 木４ | BF40: 金４ | BG40: 月４ | BH40: 火４ | BI40: 水４ | BJ40: 木４ | BK40: 金４ | BL40: 月４ | BM40: 火４ | BN40: 水４ | BO40: 木４ | BP40: 金４
A41: 4 | B41: =COUNTIF(年計!$D$233:$I$277,AM40) -> 4 | C41: =COUNTIF(年計!$D$233:$I$277,AN40) -> 5 | D41: =COUNTIF(年計!$D$233:$I$277,AO40) -> 4 | E41: =COUNTIF(年計!$D$233:$I$277,AP40) -> 4 | F41: =COUNTIF(年計!$D$233:$I$277,AQ40) -> 5 | G41: =COUNTIF(年計!$J$233:$O$277,AR40) -> 4 | H41: =COUNTIF(年計!$J$233:$O$277,AS40) -> 5 | I41: =COUNTIF(年計!$J$233:$O$277,AT40) -> 4 | J41: =COUNTIF(年計!$J$233:$O$277,AU40) -> 4 | K41: =COUNTIF(年計!$J$233:$O$277,AV40) -> 5 | L41: =COUNTIF(年計!$P$233:$U$277,AW40) -> 4 | M41: =COUNTIF(年計!$P$233:$U$277,AX40) -> 5 | N41: =COUNTIF(年計!$P$233:$U$277,AY40) -> 4 | O41: =COUNTIF(年計!$P$233:$U$277,AZ40) -> 4 | P41: =COUNTIF(年計!$P$233:$U$277,BA40) -> 4 | S41: 4 | T41: =COUNTIF(年計!$D$3:$I$277,BB40) -> 24 | U41: =COUNTIF(年計!$D$3:$I$277,BC40) -> 24 | V41: =COUNTIF(年計!$D$3:$I$277,BD40) -> 23 | W41: =COUNTIF(年計!$D$3:$I$277,BE40) -> 24 | X41: =COUNTIF(年計!$D$3:$I$277,BF40) -> 24 | Y41: =COUNTIF(年計!$J$3:$O$277,BG40) -> 24 | Z41: =COUNTIF(年計!$J$3:$O$277,BH40) -> 24 | AA41: =COUNTIF(年計!$J$3:$O$277,BI40) -> 23 | AB41: =COUNTIF(年計!$J$3:$O$277,BJ40) -> 24 | AC41: =COUNTIF(年計!$J$3:$O$277,BK40) -> 24 | AD41: =COUNTIF(年計!$P$3:$U$277,BL40) -> 22 | AE41: =COUNTIF(年計!$P$3:$U$277,BM40) -> 23 | AF41: =COUNTIF(年計!$P$3:$U$277,BN40) -> 22 | AG41: =COUNTIF(年計!$P$3:$U$277,BO40) -> 22 | AH41: =COUNTIF(年計!$P$3:$U$277,BP40) -> 21 | AM41: 月５ | AN41: 火５ | AO41: 水５ | AP41: 木５ | AQ41: 金５ | AR41: 月５ | AS41: 火５ | AT41: 水５ | AU41: 木５ | AV41: 金５ | AW41: 月５ | AX41: 火５ | AY41: 水５ | AZ41: 木５ | BA41: 金５ | BB41: 月５ | BC41: 火５ | BD41: 水５ | BE41: 木５ | BF41: 金５ | BG41: 月５ | BH41: 火５ | BI41: 水５ | BJ41: 木５ | BK41: 金５ | BL41: 月５ | BM41: 火５ | BN41: 水５ | BO41: 木５ | BP41: 金５
...

Sheet 年計から貼り付け
B1: ３ 月 | F1: 1行目 | G1: 会議 | H1: 貼り付け用データ
A2: 1 | B2: 3送会準備・リハ② | E2: {=INDEX($A:$A,ROW(A1)*2)} -> 1 | F2: {=INDEX($B:$B,ROW(A1)*2)&INDEX($B:$B,ROW(A1)*2+1)} -> 3送会準備・リハ② | G2: {=INDEX($C:$C,ROW(B1)*2)&INDEX($C:$C,ROW(B1)*2+1)} | H2: =IF(OR(F2="",G2="",TRIM(H1)=""),F2&G2,F2&"・"&G2) -> 3送会準備・リハ②
A3: 月 | E3: {=INDEX($A:$A,ROW(A1)*2+2)} -> 2 | F3: {=INDEX($B:$B,ROW(A2)*2)&" "&INDEX($B:$B,ROW(A2)*2+1)} -> 3年生を送る会 | G3: {=INDEX($C:$C,ROW(B2)*2)&INDEX($C:$C,ROW(B2)*2+1)} | H3: =IF(OR(F3="",G3="",TRIM(H2)=""),F3&G3,F3&"・"&G3) -> 3年生を送る会
A4: 2 | B4: 3年生を送る会 | E4: {=INDEX($A:$A,ROW(A2)*2+2)} -> 3 | F4: {=INDEX($B:$B,ROW(A3)*2)&" "&INDEX($B:$B,ROW(A3)*2+1)} | G4: {=INDEX($C:$C,ROW(B3)*2)&INDEX($C:$C,ROW(B3)*2+1)} | H4: =IF(OR(F4="",G4="",TRIM(H3)=""),F4&G4,F4&"・"&G4)
A5: 火 | E5: {=INDEX($A:$A,ROW(A3)*2+2)} -> 4 | F5: {=INDEX($B:$B,ROW(A4)*2)&" "&INDEX($B:$B,ROW(A4)*2+1)} -> 卒業式準備 | G5: {=INDEX($C:$C,ROW(B4)*2)&INDEX($C:$C,ROW(B4)*2+1)} | H5: =IF(OR(F5="",G5="",TRIM(H4)=""),F5&G5,F5&"・"&G5) -> 卒業式準備
A6: 3 | E6: {=INDEX($A:$A,ROW(A4)*2+2)} -> 5 | F6: {=INDEX($B:$B,ROW(A5)*2)&" "&INDEX($B:$B,ROW(A5)*2+1)} -> 卒業式 | G6: {=INDEX($C:$C,ROW(B5)*2)&INDEX($C:$C,ROW(B5)*2+1)} -> 定1･2年成績一覧表提出 | H6: =IF(OR(F6="",G6="",TRIM(H5)=""),F6&G6,F6&"・"&G6) -> 卒業式 ・定1･2年成績一覧表提出
A7: 水 | E7: {=INDEX($A:$A,ROW(A5)*2+2)} -> 6 | F7: {=INDEX($B:$B,ROW(A6)*2)&" "&INDEX($B:$B,ROW(A6)*2+1)} | G7: {=INDEX($C:$C,ROW(B6)*2)&INDEX($C:$C,ROW(B6)*2+1)} | H7: =IF(OR(F7="",G7="",TRIM(H6)=""),F7&G7,F7&"・"&G7)
A8: 4 | B8: 卒業式準備 | E8: {=INDEX($A:$A,ROW(A6)*2+2)} -> 7 | F8: {=INDEX($B:$B,ROW(A7)*2)&" "&INDEX($B:$B,ROW(A7)*2+1)} | G8: {=INDEX($C:$C,ROW(B7)*2)&INDEX($C:$C,ROW(B7)*2+1)} | H8: =IF(OR(F8="",G8="",TRIM(H7)=""),F8&G8,F8&"・"&G8)
A9: 木 | E9: {=INDEX($A:$A,ROW(A7)*2+2)} -> 8 | F9: {=INDEX($B:$B,ROW(A8)*2)&" "&INDEX($B:$B,ROW(A8)*2+1)} -> 【公立一般合格発表】 | G9: {=INDEX($C:$C,ROW(B8)*2)&INDEX($C:$C,ROW(B8)*2+1)} -> 進認職11 | H9: =IF(OR(F9="",G9="",TRIM(H8)=""),F9&G9,F9&"・"&G9) -> 【公立一般合格発表】進認職11
A10: 5 | B10: 卒業式 | C10: 定 | E10: {=INDEX($A:$A,ROW(A8)*2+2)} -> 9 | F10: {=INDEX($B:$B,ROW(A9)*2)&" "&INDEX($B:$B,ROW(A9)*2+1)} -> 選挙管理委員会 ▼小中連絡会(汐路) 1･2年通知表（本）提出 | G10: {=INDEX($C:$C,ROW(B9)*2)&INDEX($C:$C,ROW(B9)*2+1)} | H10: =IF(OR(F10="",G10="",TRIM(H9)=""),F10&G10,F10&"・"&G10) -> 選挙管理委員会 ▼小中連絡会(汐路) 1･2年通知表（本）提出
A11: 金 | C11: 1･2年成績一覧表提出 | E11: {=INDEX($A:$A,ROW(A9)*2+2)} -> 10 | F11: {=INDEX($B:$B,ROW(A10)*2)&" "&INDEX($B:$B,ROW(A10)*2+1)} | G11: {=INDEX($C:$C,ROW(B10)*2)&INDEX($C:$C,ROW(B10)*2+1)} -> ▼小中連絡会(陽明) | H11: =IF(OR(F11="",G11="",TRIM(H10)=""),F11&G11,F11&"・"&G11) -> ・▼小中連絡会(陽明)
A12: 6 | E12: {=INDEX($A:$A,ROW(A10)*2+2)} -> 11 | F12: {=INDEX($B:$B,ROW(A11)*2)&" "&INDEX($B:$B,ROW(A11)*2+1)} -> 学年保護者会(2年) 立候補者連絡会 | G12: {=INDEX($C:$C,ROW(B11)*2)&INDEX($C:$C,ROW(B11)*2+1)} -> 委 | H12: =IF(OR(F12="",G12="",TRIM(H11)=""),F12&G12,F12&"・"&G12) -> 学年保護者会(2年) 立候補者連絡会・委
A13: 土 | E13: {=INDEX($A:$A,ROW(A11)*2+2)} -> 12 | F13: {=INDEX($B:$B,ROW(A12)*2)&" "&INDEX($B:$B,ROW(A12)*2+1)} | G13: {=INDEX($C:$C,ROW(B12)*2)&INDEX($C:$C,ROW(B12)*2+1)} -> 編1 | H13: =IF(OR(F13="",G13="",TRIM(H12)=""),F13&G13,F13&"・"&G13) -> ・編1
A14: 7 | E14: {=INDEX($A:$A,ROW(A12)*2+2)} -> 13 | F14: {=INDEX($B:$B,ROW(A13)*2)&" "&INDEX($B:$B,ROW(A13)*2+1)} | G14: {=INDEX($C:$C,ROW(B13)*2)&INDEX($C:$C,ROW(B13)*2+1)} | H14: =IF(OR(F14="",G14="",TRIM(H13)=""),F14&G14,F14&"・"&G14)
A15: 日 | E15: {=INDEX($A:$A,ROW(A13)*2+2)} -> 14 | F15: {=INDEX($B:$B,ROW(A14)*2)&" "&INDEX($B:$B,ROW(A14)*2+1)} -> ノー部活デー | G15: {=INDEX($C:$C,ROW(B14)*2)&INDEX($C:$C,ROW(B14)*2+1)} | H15: =IF(OR(F15="",G15="",TRIM(H14)=""),F15&G15,F15&"・"&G15) -> ノー部活デー
A16: 8 | C16: 進認 | E16: {=INDEX($A:$A,ROW(A14)*2+2)} -> 15 | F16: {=INDEX($B:$B,ROW(A15)*2)&" "&INDEX($B:$B,ROW(A15)*2+1)} -> 立会演説会・選管 | G16: {=INDEX($C:$C,ROW(B15)*2)&INDEX($C:$C,ROW(B15)*2+1)} -> 1･2年通知表（本）提出 | H16: =IF(OR(F16="",G16="",TRIM(H15)=""),F16&G16,F16&"・"&G16) -> 立会演説会・選管 ・1･2年通知表（本）提出
A17: 月 | B17: 【公立一般合格発表】 | C17: 職11 | E17: {=INDEX($A:$A,ROW(A15)*2+2)} -> 16 | F17: {=INDEX($B:$B,ROW(A16)*2)&" "&INDEX($B:$B,ROW(A16)*2+1)} -> R7生徒会オリ(リハ) 【全日制･定時制２次選抜】 | G17: {=INDEX($C:$C,ROW(B16)*2)&INDEX($C:$C,ROW(B16)*2+1)} | H17: =IF(OR(F17="",G17="",TRIM(H16)=""),F17&G17,F17&"・"&G17) -> R7生徒会オリ(リハ) 【全日制･定時制２次選抜】
A18: 9 | B18: 選挙管理委員会 ▼小中連絡会(汐路) | E18: {=INDEX($A:$A,ROW(A16)*2+2)} -> 17 | F18: {=INDEX($B:$B,ROW(A17)*2)&" "&INDEX($B:$B,ROW(A17)*2+1)} -> 【全日制･定時制２次合格発表】 | G18: {=INDEX($C:$C,ROW(B17)*2)&INDEX($C:$C,ROW(B17)*2+1)} | H18: =IF(OR(F18="",G18="",TRIM(H17)=""),F18&G18,F18&"・"&G18) -> 【全日制･定時制２次合格発表】
A19: 火 | B19: 1･2年通知表（本）提出 | E19: {=INDEX($A:$A,ROW(A17)*2+2)} -> 18 | F19: {=INDEX($B:$B,ROW(A18)*2)&" "&INDEX($B:$B,ROW(A18)*2+1)} -> (小学校卒業式) | G19: {=INDEX($C:$C,ROW(B18)*2)&INDEX($C:$C,ROW(B18)*2+1)} -> 編2 | H19: =IF(OR(F19="",G19="",TRIM(H18)=""),F19&G19,F19&"・"&G19) -> (小学校卒業式)・編2
A20: 10 | E20: {=INDEX($A:$A,ROW(A18)*2+2)} -> 19 | F20: {=INDEX($B:$B,ROW(A19)*2)&" "&INDEX($B:$B,ROW(A19)*2+1)} | G20: {=INDEX($C:$C,ROW(B19)*2)&INDEX($C:$C,ROW(B19)*2+1)} -> 採 | H20: =IF(OR(F20="",G20="",TRIM(H19)=""),F20&G20,F20&"・"&G20) -> ・採
A21: 水 | C21: ▼小中連絡会(陽明) | E21: {=INDEX($A:$A,ROW(A19)*2+2)} -> 20 | F21: {=INDEX($B:$B,ROW(A20)*2)&" "&INDEX($B:$B,ROW(A20)*2+1)} | G21: {=INDEX($C:$C,ROW(B20)*2)&INDEX($C:$C,ROW(B20)*2+1)} | H21: =IF(OR(F21="",G21="",TRIM(H20)=""),F21&G21,F21&"・"&G21)
A22: 11 | B22: 学年保護者会(2年) | E22: {=INDEX($A:$A,ROW(A20)*2+2)} -> 21 | F22: {=INDEX($B:$B,ROW(A21)*2)&" "&INDEX($B:$B,ROW(A21)*2+1)} -> 春分の日 | G22: {=INDEX($C:$C,ROW(B21)*2)&INDEX($C:$C,ROW(B21)*2+1)} | H22: =IF(OR(F22="",G22="",TRIM(H21)=""),F22&G22,F22&"・"&G22) -> 春分の日
A23: 木 | B23: 立候補者連絡会 | C23: 委 | E23: {=INDEX($A:$A,ROW(A21)*2+2)} -> 22 | F23: {=INDEX($B:$B,ROW(A22)*2)&" "&INDEX($B:$B,ROW(A22)*2+1)} -> 日曜日祝日による休業日 | G23: {=INDEX($C:$C,ROW(B22)*2)&INDEX($C:$C,ROW(B22)*2+1)} | H23: =IF(OR(F23="",G23="",TRIM(H22)=""),F23&G23,F23&"・"&G23) -> 日曜日祝日による休業日
A24: 12 | C24: 編1 | E24: {=INDEX($A:$A,ROW(A22)*2+2)} -> 23 | F24: {=INDEX($B:$B,ROW(A23)*2)&" "&INDEX($B:$B,ROW(A23)*2+1)} -> 大掃除 【通信制後期入試】 | G24: {=INDEX($C:$C,ROW(B23)*2)&INDEX($C:$C,ROW(B23)*2+1)} | H24: =IF(OR(F24="",G24="",TRIM(H23)=""),F24&G24,F24&"・"&G24) -> 大掃除 【通信制後期入試】
A25: 金 | E25: {=INDEX($A:$A,ROW(A23)*2+2)} -> 24 | F25: {=INDEX($B:$B,ROW(A24)*2)&" "&INDEX($B:$B,ROW(A24)*2+1)} -> 修了式・離任式 【通信制後期合格発表】 | G25: {=INDEX($C:$C,ROW(B24)*2)&INDEX($C:$C,ROW(B24)*2+1)} | H25: =IF(OR(F25="",G25="",TRIM(H24)=""),F25&G25,F25&"・"&G25) -> 修了式・離任式 【通信制後期合格発表】
A26: 13 | E26: {=INDEX($A:$A,ROW(A24)*2+2)} -> 25 | F26: {=INDEX($B:$B,ROW(A25)*2)&" "&INDEX($B:$B,ROW(A25)*2+1)} -> 学年末休業開始 | G26: {=INDEX($C:$C,ROW(B25)*2)&INDEX($C:$C,ROW(B25)*2+1)} | H26: =IF(OR(F26="",G26="",TRIM(H25)=""),F26&G26,F26&"・"&G26) -> 学年末休業開始
A27: 土 | E27: {=INDEX($A:$A,ROW(A25)*2+2)} -> 26 | F27: {=INDEX($B:$B,ROW(A26)*2)&" "&INDEX($B:$B,ROW(A26)*2+1)} | G27: {=INDEX($C:$C,ROW(B26)*2)&INDEX($C:$C,ROW(B26)*2+1)} -> 旧運 | H27: =IF(OR(F27="",G27="",TRIM(H26)=""),F27&G27,F27&"・"&G27) -> ・旧運
A28: 14 | B28: ノー部活デー | E28: {=INDEX($A:$A,ROW(A26)*2+2)} -> 27 | F28: {=INDEX($B:$B,ROW(A27)*2)&" "&INDEX($B:$B,ROW(A27)*2+1)} | G28: {=INDEX($C:$C,ROW(B27)*2)&INDEX($C:$C,ROW(B27)*2+1)} | H28: =IF(OR(F28="",G28="",TRIM(H27)=""),F28&G28,F28&"・"&G28)
A29: 日 | E29: {=INDEX($A:$A,ROW(A27)*2+2)} -> 28 | F29: {=INDEX($B:$B,ROW(A28)*2)&" "&INDEX($B:$B,ROW(A28)*2+1)} | G29: {=INDEX($C:$C,ROW(B28)*2)&INDEX($C:$C,ROW(B28)*2+1)} | H29: =IF(OR(F29="",G29="",TRIM(H28)=""),F29&G29,F29&"・"&G29)
A30: 15 | B30: 立会演説会・選管 | E30: {=INDEX($A:$A,ROW(A28)*2+2)} -> 29 | F30: {=INDEX($B:$B,ROW(A29)*2)&" "&INDEX($B:$B,ROW(A29)*2+1)} | G30: {=INDEX($C:$C,ROW(B29)*2)&INDEX($C:$C,ROW(B29)*2+1)} | H30: =IF(OR(F30="",G30="",TRIM(H29)=""),F30&G30,F30&"・"&G30)
A31: 月 | C31: 1･2年通知表（本）提出 | E31: {=INDEX($A:$A,ROW(A29)*2+2)} -> 30 | F31: {=INDEX($B:$B,ROW(A30)*2)&" "&INDEX($B:$B,ROW(A30)*2+1)} | G31: {=INDEX($C:$C,ROW(B30)*2)&INDEX($C:$C,ROW(B30)*2+1)} | H31: =IF(OR(F31="",G31="",TRIM(H30)=""),F31&G31,F31&"・"&G31)
A32: 16 | B32: R7生徒会オリ(リハ) | E32: {=INDEX($A:$A,ROW(A30)*2+2)} -> 31 | F32: {=INDEX($B:$B,ROW(A31)*2)&" "&INDEX($B:$B,ROW(A31)*2+1)} | G32: {=INDEX($C:$C,ROW(B31)*2)&INDEX($C:$C,ROW(B31)*2+1)} | H32: =IF(OR(F32="",G32="",TRIM(H31)=""),F32&G32,F32&"・"&G32)
A33: 火 | B33: 【全日制･定時制２次選抜】 | G33: {=INDEX($C:$C,ROW(B32)*2)&INDEX($C:$C,ROW(B32)*2+1)} | H33: =IF(OR(F33="",G33="",TRIM(H32)=""),F33&G33,F33&"・"&G33)
A34: 17
A35: 水 | B35: 【全日制･定時制２次合格発表】
A36: 18 | C36: 編2
A37: 木 | B37: (小学校卒業式)
A38: 19 | C38: 採
A39: 金
A40: 20
...
