Workbook

Sheet 年計
D1: 1年生 | J1: 2年生 | P1: ３年生
A2: 月 | B2: 日 | D2: 1 | E2: 2 | F2: 3 | G2: 4 | H2: 5 | I2: 6 | J2: 1 | K2: 2 | L2: 3 | M2: 4 | N2: 5 | O2: 6 | P2: 1 | Q2: 2 | R2: 3 | S2: 4 | T2: 5 | U2: 6
A3: 46113 | B3: 水 | C3: 月６ | D3: 道徳
A4: 46114 | B4: 木 | C4: 火６ | D4: 総合２３
A5: 46115 | B5: 金 | C5: 水６ | D5: 学活
A6: 46116 | B6: 土 | C6: 金６ | D6: 総合
A7: 46117 | B7: 日 | W7: 入学式
A8: 46118 | B8: 月 | C8: 着任式 始業式 | J8: 式 | K8: 水６ | L8: 入学式準備 | P8: 式 | Q8: 水６ | R8: 入学式準備
A9: 46119 | B9: 火 | C9: 入学式 | D9: 式 | F9: 水６ | K9: 家庭学習 | Q9: 家庭学習 | X9: 月１ | Y9: 月２ | Z9: 月３ | AA9: 月４ | AB9: 月５ | AC9: 月６ | AD9: 月１ | AE9: 月２ | AF9: 月３ | AG9: 月４ | AH9: 月５ | AI9: 月６ | AJ9: 月１ | AK9: 月２ | AL9: 月３ | AM9: 月４ | AN9: 月５ | AO9: 月６
A10: 46120 | B10: 水 | C10: 生徒会オリ・対面式 身体測定(3年) | D10: 式 | E10: 集会 | F10: 水６ | G10: 水６ | J10: 式 | K10: 水６ | L10: 国テ | M10: 水６ | P10: 式 | Q10: 水６ | R10: 身体測定 | X10: 火１ | Y10: 火２ | Z10: 火３ | AA10: 火４ | AB10: 火５ | AC10: 火６ | AD10: 火１ | AE10: 火２ | AF10: 火３ | AG10: 火４ | AH10: 火５ | AI10: 火６ | AJ10: 火１ | AK10: 火２ | AL10: 火３ | AM10: 火４ | AN10: 火５ | AO10: 火６
A11: 46121 | B11: 木 | C11: 身体測定(1年･IJ)ノー部活デー | D11: 水６ | E11: 数テ | F11: 身体測定 | J11: 英テ | K11: 集会 | L11: 水６ | M11: 水６ | P11: 集会 | Q11: 水６ | R11: 国テ | S11: 水６ | X11: 水１ | Y11: 水２ | Z11: 水３ | AA11: 水４ | AB11: 水５ | AC11: 水６ | AD11: 水１ | AE11: 水２ | AF11: 水３ | AG11: 水４ | AH11: 水５ | AI11: 水６ | AJ11: 水１ | AK11: 水２ | AL11: 水３ | AM11: 水４ | AN11: 水５ | AO11: 水６
A12: 46122 | B12: 金 | C12: 身体測定(2年)（ランチ４月スタート分〆切） | D12: 水６ | E12: 国テ | F12: 英テ | G12: 水６ | J12: 水６ | K12: 数テ | L12: 身体測定 | P12: 英テ | Q12: 数テ | R12: 水６ | S12: 水６ | X12: 木１ | Y12: 木２ | Z12: 木３ | AA12: 木４ | AB12: 木５ | AD12: 木１ | AE12: 木２ | AF12: 木３ | AG12: 木４ | AH12: 木５ | AJ12: 木１ | AK12: 木２ | AL12: 木３ | AM12: 木４ | AN12: 木５
A13: 46123 | B13: 土 | X13: 金１ | Y13: 金２ | Z13: 金３ | AA13: 金４ | AB13: 金５ | AC13: 金６ | AD13: 金１ | AE13: 金２ | AF13: 金３ | AG13: 金４ | AH13: 金５ | AI13: 金６ | AJ13: 金１ | AK13: 金２ | AL13: 金３ | AM13: 金４ | AN13: 金５ | AO13: 金６
A14: 46124 | B14: 日
A15: 46125 | B15: 月 | C15: 学級写真撮影 部活紹介 | D15: 写真 | E15: 水６ | F15: 水６ | G15: 部活動 | J15: 写真 | K15: 水６ | L15: 水６ | P15: 写真 | Q15: 水６ | R15: 水６
A16: 46126 | B16: 火 | C16: 身体測定(欠席者)仮時間割 ランチ開始 | D16: 火１ | E16: 火２ | F16: 火３ | G16: 火４ | H16: 火５ | J16: 火１ | K16: 火２ | L16: 火３ | M16: 火４ | N16: 火５ | P16: 火１ | Q16: 火２ | R16: 火３ | S16: 火４ | T16: 火５
A17: 46127 | B17: 水 | D17: 水１ | E17: 水２ | F17: 水３ | G17: 水４ | H17: 水５ | I17: 水６ | J17: 水１ | K17: 水２ | L17: 水３ | M17: 水４ | N17: 水５ | O17: 水６ | P17: 水１ | Q17: 水２ | R17: 水３ | S17: 水４ | T17: 水５ | U17: 水６
A18: 46128 | B18: 木 | D18: 木１ | E18: 木２ | F18: 木３ | G18: 木４ | H18: 木５ | J18: 木１ | K18: 木２ | L18: 木３ | M18: 木４ | N18: 木５ | P18: 木１ | Q18: 木２ | R18: 木３ | S18: 木４ | T18: 木５
A19: 46129 | B19: 金 | C19: 避難訓練 | D19: 金１ | E19: 金２ | F19: 金３ | G19: 金４ | H19: 金５ | I19: 訓練 | J19: 金１ | K19: 金２ | L19: 金３ | M19: 金４ | N19: 金５ | O19: 訓練 | P19: 金１ | Q19: 金２ | R19: 金３ | S19: 金４ | T19: 金５ | U19: 訓練
A20: 46130 | B20: 土
A21: 46131 | B21: 日
A22: 46132 | B22: 月 | C22: 認証式 | D22: 月１ | E22: 月２ | F22: 月３ | G22: 月４ | H22: 月５ | I22: 月６ | J22: 月１ | K22: 月２ | L22: 月３ | M22: 月４ | N22: 月５ | O22: 月６ | P22: 月１ | Q22: 月２ | R22: 月３ | S22: 月４ | T22: 月５ | U22: 月６
A23: 46133 | B23: 火 | C23: 眼科検診(2･3年午後) | D23: 火１ | E23: 火２ | F23: 火３ | G23: 火４ | H23: 火５ | I23: 火６ | J23: 火１ | K23: 火２ | L23: 火３ | M23: 火４ | N23: 火５ | O23: 火６ | P23: 火１ | Q23: 火２ | R23: 火３ | S23: 火４ | T23: 火５ | U23: 火６
A24: 46134 | B24: 水 | C24: 稲武野外学習説明会(2年) | D24: 水１ | E24: 水２ | F24: 水３ | G24: 水４ | H24: 水５ | I24: 木５ | J24: 水１ | K24: 水２ | L24: 水３ | M24: 水４ | N24: 水５ | O24: 木５ | P24: 水１ | Q24: 水２ | R24: 水３ | S24: 水４ | T24: 水５ | U24: 木５
A25: 46135 | B25: 木 | C25: 全国学調(国･数･英3技能･質) | D25: 木１ | E25: 木２ | F25: 木３ | G25: 木４ | H25: 水６ | J25: 木１ | K25: 木２ | L25: 木３ | M25: 木４ | N25: 説明会 | P25: 全 | Q25: 国 | R25: 学 | S25: テ | T25: 水６
A26: 46136 | B26: 金 | C26: 眼科検診(IJ･1年･色覚午後)部活動集会 | D26: 金１ | E26: 金２ | F26: 金３ | G26: 金４ | H26: 金５ | I26: 金６ | J26: 金１ | K26: 金２ | L26: 金３ | M26: 金４ | N26: 金５ | O26: 金６ | P26: 金１ | Q26: 金２ | R26: 金３ | S26: 金４ | T26: 金５ | U26: 金６
A27: 46137 | B27: 土
A28: 46138 | B28: 日
A29: 46139 | B29: 月 | C29: 授業参観(午前)Ｐ総会・学級懇(午後) | D29: 月１ | E29: 月２ | F29: 月３ | G29: 月４ | H29: PTA総会 | I29: 学級懇 | J29: 月１ | K29: 月２ | L29: 月３ | M29: 月４ | N29: PTA総会 | O29: 学級懇 | P29: 月１ | Q29: 月２ | R29: 月３ | S29: 月４ | T29: PTA総会 | U29: 学級懇
A30: 46140 | B30: 火 | C30: 内科検診(3年午後) | D30: 火１ | E30: 火２ | F30: 火３ | G30: 火４ | H30: 火５ | I30: 金５ | J30: 火１ | K30: 火２ | L30: 火３ | M30: 火４ | N30: 火５ | O30: 金５ | P30: 火１ | Q30: 火２ | R30: 火３ | S30: 火４ | T30: 火５ | U30: 金５
A31: 46141 | B31: 水 | C31: 昭和の日
A32: 46142 | B32: 木 | C32: ⑤全国学調(英話すこと） | D32: 木１ | E32: 木２ | F32: 木３ | G32: 木４ | H32: 木５ | J32: 木１ | K32: 木２ | L32: 木３ | M32: 木４ | N32: 木５ | P32: 木１ | Q32: 木２ | R32: 木３ | S32: 木４ | T32: 学調
A33: 46143 | B33: 金 | C33: ⑤⑥修学旅行・進路説明会(3年)部活保護者会 | D33: 金１ | E33: 金２ | F33: 金３ | G33: 金４ | H33: 水６ | I33: 金６ | J33: 金１ | K33: 金２ | L33: 金３ | M33: 金４ | N33: 水６ | O33: 金６ | P33: 金１ | Q33: 金２ | R33: 金３ | S33: 金４ | T33: 修学旅行 | U33: 進路説明会
A34: 46144 | B34: 土
A35: 46145 | B35: 日 | C35: 憲法記念日
A36: 46146 | B36: 月 | C36: みどりの日
A37: 46147 | B37: 火 | C37: こどもの日
A38: 46148 | B38: 水 | C38: 日曜日祝日による休業日
A39: 46149 | B39: 木 | C39: 本時間割新体力テスト準備 | D39: 月１ | E39: 月２ | F39: 月３ | G39: 月４ | H39: 月５ | J39: 月１ | K39: 月２ | L39: 月３ | M39: 月４ | N39: 月５ | P39: 月１ | Q39: 月２ | R39: 月３ | S39: 月４ | T39: 月５
A40: 46150 | B40: 金 | C40: 新体力テスト | D40: 新体力テスト | H40: 整理 | J40: 新体力テスト | N40: 整理 | P40: 新体力テスト | T40: 整理
...

Sheet 合計
A2: 教育カレンダー 時間数
B3: １年 | G3: ２年 | L3: ３年
A4: ＜確認テストまで＞ | T4: 月６ | U4: 道徳
B5: 月 | C5: 火 | D5: 水 | E5: 木 | F5: 金 | G5: 月 | H5: 火 | I5: 水 | J5: 木 | K5: 金 | L5: 月 | M5: 火 | N5: 水 | O5: 木 | P5: 金 | T5: 火６ | U5: 総合２３ | AI5: 入学式 | AJ5: =MATCH(AI5,年計!$C$2:$C$367,0) -> #N/A | AM5: 月１ | AN5: 火１ | AO5: 水１ | AP5: 木１ | AQ5: 金１ | AR5: 月１ | AS5: 火１ | AT5: 水１ | AU5: 木１ | AV5: 金１ | AW5: 月１ | AX5: 火１ | AY5: 水１ | AZ5: 木１ | BA5: 金１
A6: 1 | B6: =COUNTIF(年計!$D$3:$I$47,AM5) -> 4 | C6: =COUNTIF(年計!$D$3:$I$47,AN5) -> 4 | D6: =COUNTIF(年計!$D$3:$I$47,AO5) -> 3 | E6: =COUNTIF(年計!$D$3:$I$47,AP5) -> 4 | F6: =COUNTIF(年計!$D$3:$I$47,AQ5) -> 4 | G6: =COUNTIF(年計!$J$3:$O$47,AR5) -> 4 | H6: =COUNTIF(年計!$J$3:$O$47,AS5) -> 4 | I6: =COUNTIF(年計!$J$3:$O$47,AT5) -> 3 | J6: =COUNTIF(年計!$J$3:$O$47,AU5) -> 4 | K6: =COUNTIF(年計!$J$3:$O$47,AV5) -> 4 | L6: =COUNTIF(年計!$P$3:$U$47,AW5) -> 4 | M6: =COUNTIF(年計!$P$3:$U$47,AX5) -> 4 | N6: =COUNTIF(年計!$P$3:$U$47,AY5) -> 3 | O6: =COUNTIF(年計!$P$3:$U$47,AZ5) -> 3 | P6: =COUNTIF(年計!$P$3:$U$47,BA5) -> 4 | T6: 水６ | U6: 学活 | AI6: 定期テスト① | AJ6: =MATCH(AI6,年計!$C$2:$C$367,0) -> #N/A | AM6: 月２ | AN6: 火２ | AO6: 水２ | AP6: 木２ | AQ6: 金２ | AR6: 月２ | AS6: 火２ | AT6: 水２ | AU6: 木２ | AV6: 金２ | AW6: 月２ | AX6: 火２ | AY6: 水２ | AZ6: 木２ | BA6: 金２
A7: 2 | B7: =COUNTIF(年計!$D$3:$I$47,AM6) -> 4 | C7: =COUNTIF(年計!$D$3:$I$47,AN6) -> 4 | D7: =COUNTIF(年計!$D$3:$I$47,AO6) -> 3 | E7: =COUNTIF(年計!$D$3:$I$47,AP6) -> 4 | F7: =COUNTIF(年計!$D$3:$I$47,AQ6) -> 4 | G7: =COUNTIF(年計!$J$3:$O$47,AR6) -> 4 | H7: =COUNTIF(年計!$J$3:$O$47,AS6) -> 4 | I7: =COUNTIF(年計!$J$3:$O$47,AT6) -> 3 | J7: =COUNTIF(年計!$J$3:$O$47,AU6) -> 4 | K7: =COUNTIF(年計!$J$3:$O$47,AV6) -> 4 | L7: =COUNTIF(年計!$P$3:$U$47,AW6) -> 4 | M7: =COUNTIF(年計!$P$3:$U$47,AX6) -> 4 | N7: =COUNTIF(年計!$P$3:$U$47,AY6) -> 3 | O7: =COUNTIF(年計!$P$3:$U$47,AZ6) -> 3 | P7: =COUNTIF(年計!$P$3:$U$47,BA6) -> 4 | T7: 金６ | U7: 総合 | AM7: 月３ | AN7: 火３ | AO7: 水３ | AP7: 木３ | AQ7: 金３ | AR7: 月３ | AS7: 火３ | AT7: 水３ | AU7: 木３ | AV7: 金３ | AW7: 月３ | AX7: 火３ | AY7: 水３ | AZ7: 木３ | BA7: 金３
A8: 3 | B8: =COUNTIF(年計!$D$3:$I$47,AM7) -> 4 | C8: =COUNTIF(年計!$D$3:$I$47,AN7) -> 4 | D8: =COUNTIF(年計!$D$3:$I$47,AO7) -> 3 | E8: =COUNTIF(年計!$D$3:$I$47,AP7) -> 4 | F8: =COUNTIF(年計!$D$3:$I$47,AQ7) -> 4 | G8: =COUNTIF(年計!$J$3:$O$47,AR7) -> 4 | H8: =COUNTIF(年計!$J$3:$O$47,AS7) -> 4 | I8: =COUNTIF(年計!$J$3:$O$47,AT7) -> 3 | J8: =COUNTIF(年計!$J$3:$O$47,AU7) -> 4 | K8: =COUNTIF(年計!$J$3:$O$47,AV7) -> 4 | L8: =COUNTIF(年計!$P$3:$U$47,AW7) -> 4 | M8: =COUNTIF(年計!$P$3:$U$47,AX7) -> 4 | N8: =COUNTIF(年計!$P$3:$U$47,AY7) -> 3 | O8: =COUNTIF(年計!$P$3:$U$47,AZ7) -> 3 | P8: =COUNTIF(年計!$P$3:$U$47,BA7) -> 4 | AM8: 月４ | AN8: 火４ | AO8: 水４ | AP8: 木４ | AQ8: 金４ | AR8: 月４ | AS8: 火４ | AT8: 水４ | AU8: 木４ | AV8: 金４ | AW8: 月４ | AX8: 火４ | AY8: 水４ | AZ8: 木４ | BA8: 金４
A9: 4 | B9: =COUNTIF(年計!$D$3:$I$47,AM8) -> 4 | C9: =COUNTIF(年計!$D$3:$I$47,AN8) -> 4 | D9: =COUNTIF(年計!$D$3:$I$47,AO8) -> 3 | E9: =COUNTIF(年計!$D$3:$I$47,AP8) -> 4 | F9: =COUNTIF(年計!$D$3:$I$47,AQ8) -> 4 | G9: =COUNTIF(年計!$J$3:$O$47,AR8) -> 4 | H9: =COUNTIF(年計!$J$3:$O$47,AS8) -> 4 | I9: =COUNTIF(年計!$J$3:$O$47,AT8) -> 3 | J9: =COUNTIF(年計!$J$3:$O$47,AU8) -> 4 | K9: =COUNTIF(年計!$J$3:$O$47,AV8) -> 4 | L9: =COUNTIF(年計!$P$3:$U$47,AW8) -> 4 | M9: =COUNTIF(年計!$P$3:$U$47,AX8) -> 4 | N9: =COUNTIF(年計!$P$3:$U$47,AY8) -> 3 | O9: =COUNTIF(年計!$P$3:$U$47,AZ8) -> 3 | P9: =COUNTIF(年計!$P$3:$U$47,BA8) -> 4 | AM9: 月５ | AN9: 火５ | AO9: 水５ | AP9: 木５ | AQ9: 金５ | AR9: 月５ | AS9: 火５ | AT9: 水５ | AU9: 木５ | AV9: 金５ | AW9: 月５ | AX9: 火５ | AY9: 水５ | AZ9: 木５ | BA9: 金５
A10: 5 | B10: =COUNTIF(年計!$D$3:$I$47,AM9) -> 3 | C10: =COUNTIF(年計!$D$3:$I$47,AN9) -> 4 | D10: =COUNTIF(年計!$D$3:$I$47,AO9) -> 3 | E10: =COUNTIF(年計!$D$3:$I$47,AP9) -> 4 | F10: =COUNTIF(年計!$D$3:$I$47,AQ9) -> 4 | G10: =COUNTIF(年計!$J$3:$O$47,AR9) -> 3 | H10: =COUNTIF(年計!$J$3:$O$47,AS9) -> 4 | I10: =COUNTIF(年計!$J$3:$O$47,AT9) -> 3 | J10: =COUNTIF(年計!$J$3:$O$47,AU9) -> 4 | K10: =COUNTIF(年計!$J$3:$O$47,AV9) -> 4 | L10: =COUNTIF(年計!$P$3:$U$47,AW9) -> 3 | M10: =COUNTIF(年計!$P$3:$U$47,AX9) -> 4 | N10: =COUNTIF(年計!$P$3:$U$47,AY9) -> 3 | O10: =COUNTIF(年計!$P$3:$U$47,AZ9) -> 3 | P10: =COUNTIF(年計!$P$3:$U$47,BA9) -> 4 | AM10: 月６ | AN10: 火６ | AO10: 水６ | AP10: 木６ | AQ10: 金６ | AR10: 月６ | AS10: 火６ | AT10: 水６ | AU10: 木６ | AV10: 金６ | AW10: 月６ | AX10: 火６ | AY10: 水６ | AZ10: 木６ | BA10: 金６
A11: 6 | B11: =COUNTIF(年計!$D$3:$I$47,AM10) -> 2 | C11: =COUNTIF(年計!$D$3:$I$47,AN10) -> 2 | D11: =COUNTIF(年計!$D$3:$I$47,AO10) -> 12 | F11: =COUNTIF(年計!$D$3:$I$47,AQ10) -> 2 | G11: =COUNTIF(年計!$J$3:$O$47,AR10) -> 2 | H11: =COUNTIF(年計!$J$3:$O$47,AS10) -> 2 | I11: =COUNTIF(年計!$J$3:$O$47,AT10) -> 11 | J11: =COUNTIF(年計!$J$3:$O$47,AU10) -> 0 | K11: =COUNTIF(年計!$J$3:$O$47,AV10) -> 2 | L11: =COUNTIF(年計!$P$3:$U$47,AW10) -> 2 | M11: =COUNTIF(年計!$P$3:$U$47,AX10) -> 2 | N11: =COUNTIF(年計!$P$3:$U$47,AY10) -> 11 | O11: =COUNTIF(年計!$P$3:$U$47,AZ10) -> 0 | P11: =COUNTIF(年計!$P$3:$U$47,BA10) -> 1 | S11: １年 | X11: ２年 | AC11: ３年
A12: ＜確テ～１期末テ＞ | S12: ＜１期末テまで 累計＞
B13: 月 | C13: 火 | D13: 水 | E13: 木 | F13: 金 | G13: 月 | H13: 火 | I13: 水 | J13: 木 | K13: 金 | L13: 月 | M13: 火 | N13: 水 | O13: 木 | P13: 金 | T13: 月 | U13: 火 | V13: 水 | W13: 木 | X13: 金 | Y13: 月 | Z13: 火 | AA13: 水 | AB13: 木 | AC13: 金 | AD13: 月 | AE13: 火 | AF13: 水 | AG13: 木 | AH13: 金 | AM13: 月１ | AN13: 火１ | AO13: 水１ | AP13: 木１ | AQ13: 金１ | AR13: 月１ | AS13: 火１ | AT13: 水１ | AU13: 木１ | AV13: 金１ | AW13: 月１ | AX13: 火１ | AY13: 水１ | AZ13: 木１ | BA13: 金１ | BB13: 月１ | BC13: 火１ | BD13: 水１ | BE13: 木１ | BF13: 金１ | BG13: 月１ | BH13: 火１ | BI13: 水１ | BJ13: 木１ | BK13: 金１ | BL13: 月１ | BM13: 火１ | BN13: 水１ | BO13: 木１ | BP13: 金１
A14: 1 | B14: =COUNTIF(年計!$D$48:$I$87,AM13) -> 5 | C14: =COUNTIF(年計!$D$48:$I$87,AN13) -> 5 | D14: =COUNTIF(年計!$D$48:$I$87,AO13) -> 5 | E14: =COUNTIF(年計!$D$48:$I$87,AP13) -> 5 | F14: =COUNTIF(年計!$D$48:$I$87,AQ13) -> 5 | G14: =COUNTIF(年計!$J$48:$O$87,AR13) -> 4 | H14: =COUNTIF(年計!$J$48:$O$87,AS13) -> 5 | I14: =COUNTIF(年計!$J$48:$O$87,AT13) -> 4 | J14: =COUNTIF(年計!$J$48:$O$87,AU13) -> 4 | K14: =COUNTIF(年計!$J$48:$O$87,AV13) -> 4 | L14: =COUNTIF(年計!$P$48:$U$87,AW13) -> 4 | M14: =COUNTIF(年計!$P$48:$U$87,AX13) -> 4 | N14: =COUNTIF(年計!$P$48:$U$87,AY13) -> 4 | O14: =COUNTIF(年計!$P$48:$U$87,AZ13) -> 4 | P14: =COUNTIF(年計!$P$48:$U$87,BA13) -> 4 | S14: 1 | T14: =COUNTIF(年計!$D$2:$I$87,BB13) -> 9 | U14: =COUNTIF(年計!$D$2:$I$87,BC13) -> 9 | V14: =COUNTIF(年計!$D$2:$I$87,BD13) -> 8 | W14: =COUNTIF(年計!$D$2:$I$87,BE13) -> 9 | X14: =COUNTIF(年計!$D$2:$I$87,BF13) -> 9 | Y14: =COUNTIF(年計!$J$2:$O$87,BG13) -> 8 | Z14: =COUNTIF(年計!$J$2:$O$87,BH13) -> 9 | AA14: =COUNTIF(年計!$J$2:$O$87,BI13) -> 7 | AB14: =COUNTIF(年計!$J$2:$O$87,BJ13) -> 8 | AC14: =COUNTIF(年計!$J$2:$O$87,BK13) -> 8 | AD14: =COUNTIF(年計!$P$2:$U$87,BL13) -> 8 | AE14: =COUNTIF(年計!$P$2:$U$87,BM13) -> 8 | AF14: =COUNTIF(年計!$P$2:$U$87,BN13) -> 7 | AG14: =COUNTIF(年計!$P$2:$U$87,BO13) -> 7 | AH14: =COUNTIF(年計!$P$2:$U$87,BP13) -> 8 | AI14: 定期テスト② | AJ14: =MATCH(AI14,年計!$C$2:$C$367,0) -> #N/A | AM14: 月２ | AN14: 火２ | AO14: 水２ | AP14: 木２ | AQ14: 金２ | AR14: 月２ | AS14: 火２ | AT14: 水２ | AU14: 木２ | AV14: 金２ | AW14: 月２ | AX14: 火２ | AY14: 水２ | AZ14: 木２ | BA14: 金２ | BB14: 月２ | BC14: 火２ | BD14: 水２ | BE14: 木２ | BF14: 金２ | BG14: 月２ | BH14: 火２ | BI14: 水２ | BJ14: 木２ | BK14: 金２ | BL14: 月２ | BM14: 火２ | BN14: 水２ | BO14: 木２ | BP14: 金２
A15: 2 | B15: =COUNTIF(年計!$D$48:$I$87,AM14) -> 5 | C15: =COUNTIF(年計!$D$48:$I$87,AN14) -> 5 | D15: =COUNTIF(年計!$D$48:$I$87,AO14) -> 5 | E15: =COUNTIF(年計!$D$48:$I$87,AP14) -> 5 | F15: =COUNTIF(年計!$D$48:$I$87,AQ14) -> 4 | G15: =COUNTIF(年計!$J$48:$O$87,AR14) -> 4 | H15: =COUNTIF(年計!$J$48:$O$87,AS14) -> 5 | I15: =COUNTIF(年計!$J$48:$O$87,AT14) -> 4 | J15: =COUNTIF(年計!$J$48:$O$87,AU14) -> 4 | K15: =COUNTIF(年計!$J$48:$O$87,AV14) -> 3 | L15: =COUNTIF(年計!$P$48:$U$87,AW14) -> 4 | M15: =COUNTIF(年計!$P$48:$U$87,AX14) -> 4 | N15: =COUNTIF(年計!$P$48:$U$87,AY14) -> 4 | O15: =COUNTIF(年計!$P$48:$U$87,AZ14) -> 4 | P15: =COUNTIF(年計!$P$48:$U$87,BA14) -> 3 | S15: 2 | T15: =COUNTIF(年計!$D$2:$I$87,BB14) -> 9 | U15: =COUNTIF(年計!$D$2:$I$87,BC14) -> 9 | V15: =COUNTIF(年計!$D$2:$I$87,BD14) -> 8 | W15: =COUNTIF(年計!$D$2:$I$87,BE14) -> 9 | X15: =COUNTIF(年計!$D$2:$I$87,BF14) -> 8 | Y15: =COUNTIF(年計!$J$2:$O$87,BG14) -> 8 | Z15: =COUNTIF(年計!$J$2:$O$87,BH14) -> 9 | AA15: =COUNTIF(年計!$J$2:$O$87,BI14) -> 7 | AB15: =COUNTIF(年計!$J$2:$O$87,BJ14) -> 8 | AC15: =COUNTIF(年計!$J$2:$O$87,BK14) -> 7 | AD15: =COUNTIF(年計!$P$2:$U$87,BL14) -> 8 | AE15: =COUNTIF(年計!$P$2:$U$87,BM14) -> 8 | AF15: =COUNTIF(年計!$P$2:$U$87,BN14) -> 7 | AG15: =COUNTIF(年計!$P$2:$U$87,BO14) -> 7 | AH15: =COUNTIF(年計!$P$2:$U$87,BP14) -> 7 | AM15: 月３ | AN15: 火３ | AO15: 水３ | AP15: 木３ | AQ15: 金３ | AR15: 月３ | AS15: 火３ | AT15: 水３ | AU15: 木３ | AV15: 金３ | AW15: 月３ | AX15: 火３ | AY15: 水３ | AZ15: 木３ | BA15: 金３ | BB15: 月３ | BC15: 火３ | BD15: 水３ | BE15: 木３ | BF15: 金３ | BG15: 月３ | BH15: 火３ | BI15: 水３ | BJ15: 木３ | BK15: 金３ | BL15: 月３ | BM15: 火３ | BN15: 水３ | BO15: 木３ | BP15: 金３
A16: 3 | B16: =COUNTIF(年計!$D$48:$I$87,AM15) -> 5 | C16: =COUNTIF(年計!$D$48:$I$87,AN15) -> 5 | D16: =COUNTIF(年計!$D$48:$I$87,AO15) -> 5 | E16: =COUNTIF(年計!$D$48:$I$87,AP15) -> 5 | F16: =COUNTIF(年計!$D$48:$I$87,AQ15) -> 4 | G16: =COUNTIF(年計!$J$48:$O$87,AR15) -> 4 | H16: =COUNTIF(年計!$J$48:$O$87,AS15) -> 5 | I16: =COUNTIF(年計!$J$48:$O$87,AT15) -> 4 | J16: =COUNTIF(年計!$J$48:$O$87,AU15) -> 4 | K16: =COUNTIF(年計!$J$48:$O$87,AV15) -> 3 | L16: =COUNTIF(年計!$P$48:$U$87,AW15) -> 4 | M16: =COUNTIF(年計!$P$48:$U$87,AX15) -> 4 | N16: =COUNTIF(年計!$P$48:$U$87,AY15) -> 4 | O16: =COUNTIF(年計!$P$48:$U$87,AZ15) -> 4 | P16: =COUNTIF(年計!$P$48:$U$87,BA15) -> 3 | S16: 3 | T16: =COUNTIF(年計!$D$2:$I$87,BB15) -> 9 | U16: =COUNTIF(年計!$D$2:$I$87,BC15) -> 9 | V16: =COUNTIF(年計!$D$2:$I$87,BD15) -> 8 | W16: =COUNTIF(年計!$D$2:$I$87,BE15) -> 9 | X16: =COUNTIF(年計!$D$2:$I$87,BF15) -> 8 | Y16: =COUNTIF(年計!$J$2:$O$87,BG15) -> 8 | Z16: =COUNTIF(年計!$J$2:$O$87,BH15) -> 9 | AA16: =COUNTIF(年計!$J$2:$O$87,BI15) -> 7 | AB16: =COUNTIF(年計!$J$2:$O$87,BJ15) -> 8 | AC16: =COUNTIF(年計!$J$2:$O$87,BK15) -> 7 | AD16: =COUNTIF(年計!$P$2:$U$87,BL15) -> 8 | AE16: =COUNTIF(年計!$P$2:$U$87,BM15) -> 8 | AF16: =COUNTIF(年計!$P$2:$U$87,BN15) -> 7 | AG16: =COUNTIF(年計!$P$2:$U$87,BO15) -> 7 | AH16: =COUNTIF(年計!$P$2:$U$87,BP15) -> 7 | AM16: 月４ | AN16: 火４ | AO16: 水４ | AP16: 木４ | AQ16: 金４ | AR16: 月４ | AS16: 火４ | AT16: 水４ | AU16: 木４ | AV16: 金４ | AW16: 月４ | AX16: 火４ | AY16: 水４ | AZ16: 木４ | BA16: 金４ | BB16: 月４ | BC16: 火４ | BD16: 水４ | BE16: 木４ | BF16: 金４ | BG16: 月４ | BH16: 火４ | BI16: 水４ | BJ16: 木４ | BK16: 金４ | BL16: 月４ | BM16: 火４ | BN16: 水４ | BO16: 木４ | BP16: 金４
A17: 4 | B17: =COUNTIF(年計!$D$48:$I$87,AM16) -> 5 | C17: =COUNTIF(年計!$D$48:$I$87,AN16) -> 5 | D17: =COUNTIF(年計!$D$48:$I$87,AO16) -> 5 | E17: =COUNTIF(年計!$D$48:$I$87,AP16) -> 5 | F17: =COUNTIF(年計!$D$48:$I$87,AQ16) -> 5 | G17: =COUNTIF(年計!$J$48:$O$87,AR16) -> 4 | H17: =COUNTIF(年計!$J$48:$O$87,AS16) -> 5 | I17: =COUNTIF(年計!$J$48:$O$87,AT16) -> 4 | J17: =COUNTIF(年計!$J$48:$O$87,AU16) -> 4 | K17: =COUNTIF(年計!$J$48:$O$87,AV16) -> 4 | L17: =COUNTIF(年計!$P$48:$U$87,AW16) -> 4 | M17: =COUNTIF(年計!$P$48:$U$87,AX16) -> 4 | N17: =COUNTIF(年計!$P$48:$U$87,AY16) -> 4 | O17: =COUNTIF(年計!$P$48:$U$87,AZ16) -> 4 | P17: =COUNTIF(年計!$P$48:$U$87,BA16) -> 4 | S17: 4 | T17: =COUNTIF(年計!$D$2:$I$87,BB16) -> 9 | U17: =COUNTIF(年計!$D$2:$I$87,BC16) -> 9 | V17: =COUNTIF(年計!$D$2:$I$87,BD16) -> 8 | W17: =COUNTIF(年計!$D$2:$I$87,BE16) -> 9 | X17: =COUNTIF(年計!$D$2:$I$87,BF16) -> 9 | Y17: =COUNTIF(年計!$J$2:$O$87,BG16) -> 8 | Z17: =COUNTIF(年計!$J$2:$O$87,BH16) -> 9 | AA17: =COUNTIF(年計!$J$2:$O$87,BI16) -> 7 | AB17: =COUNTIF(年計!$J$2:$O$87,BJ16) -> 8 | AC17: =COUNTIF(年計!$J$2:$O$87,BK16) -> 8 | AD17: =COUNTIF(年計!$P$2:$U$87,BL16) -> 8 | AE17: =COUNTIF(年計!$P$2:$U$87,BM16) -> 8 | AF17: =COUNTIF(年計!$P$2:$U$87,BN16) -> 7 | AG17: =COUNTIF(年計!$P$2:$U$87,BO16) -> 7 | AH17: =COUNTIF(年計!$P$2:$U$87,BP16) -> 8 | AM17: 月５ | AN17: 火５ | AO17: 水５ | AP17: 木５ | AQ17: 金５ | AR17: 月５ | AS17: 火５ | AT17: 水５ | AU17: 木５ | AV17: 金５ | AW17: 月５ | AX17: 火５ | AY17: 水５ | AZ17: 木５ | BA17: 金５ | BB17: 月５ | BC17: 火５ | BD17: 水５ | BE17: 木５ | BF17: 金５ | BG17: 月５ | BH17: 火５ | BI17: 水５ | BJ17: 木５ | BK17: 金５ | BL17: 月５ | BM17: 火５ | BN17: 水５ | BO17: 木５ | BP17: 金５
A18: 5 | B18: =COUNTIF(年計!$D$48:$I$87,AM17) -> 6 | C18: =COUNTIF(年計!$D$48:$I$87,AN17) -> 5 | D18: =COUNTIF(年計!$D$48:$I$87,AO17) -> 5 | E18: =COUNTIF(年計!$D$48:$I$87,AP17) -> 5 | F18: =COUNTIF(年計!$D$48:$I$87,AQ17) -> 4 | G18: =COUNTIF(年計!$J$48:$O$87,AR17) -> 5 | H18: =COUNTIF(年計!$J$48:$O$87,AS17) -> 5 | I18: =COUNTIF(年計!$J$48:$O$87,AT17) -> 4 | J18: =COUNTIF(年計!$J$48:$O$87,AU17) -> 4 | K18: =COUNTIF(年計!$J$48:$O$87,AV17) -> 3 | L18: =COUNTIF(年計!$P$48:$U$87,AW17) -> 5 | M18: =COUNTIF(年計!$P$48:$U$87,AX17) -> 4 | N18: =COUNTIF(年計!$P$48:$U$87,AY17) -> 4 | O18: =COUNTIF(年計!$P$48:$U$87,AZ17) -> 4 | P18: =COUNTIF(年計!$P$48:$U$87,BA17) -> 3 | S18: 5 | T18: =COUNTIF(年計!$D$2:$I$87,BB17) -> 9 | U18: =COUNTIF(年計!$D$2:$I$87,BC17) -> 9 | V18: =COUNTIF(年計!$D$2:$I$87,BD17) -> 8 | W18: =COUNTIF(年計!$D$2:$I$87,BE17) -> 9 | X18: =COUNTIF(年計!$D$2:$I$87,BF17) -> 8 | Y18: =COUNTIF(年計!$J$2:$O$87,BG17) -> 8 | Z18: =COUNTIF(年計!$J$2:$O$87,BH17) -> 9 | AA18: =COUNTIF(年計!$J$2:$O$87,BI17) -> 7 | AB18: =COUNTIF(年計!$J$2:$O$87,BJ17) -> 8 | AC18: =COUNTIF(年計!$J$2:$O$87,BK17) -> 7 | AD18: =COUNTIF(年計!$P$2:$U$87,BL17) -> 8 | AE18: =COUNTIF(年計!$P$2:$U$87,BM17) -> 8 | AF18: =COUNTIF(年計!$P$2:$U$87,BN17) -> 7 | AG18: =COUNTIF(年計!$P$2:$U$87,BO17) -> 7 | AH18: =COUNTIF(年計!$P$2:$U$87,BP17) -> 7 | AM18: 月６ | AN18: 火６ | AO18: 水６ | AP18: 木６ | AQ18: 金６ | AR18: 月６ | AS18: 火６ | AT18: 水６ | AU18: 木６ | AV18: 金６ | AW18: 月６ | AX18: 火６ | AY18: 水６ | AZ18: 木６ | BA18: 金６ | BB18: 月６ | BC18: 火６ | BD18: 水６ | BE18: 木６ | BF18: 金６ | BG18: 月６ | BH18: 火６ | BI18: 水６ | BJ18: 木６ | BK18: 金６ | BL18: 月６ | BM18: 火６ | BN18: 水６ | BO18: 木６ | BP18: 金６
A19: 6 | B19: =COUNTIF(年計!$D$48:$I$87,AM18) -> 5 | C19: =COUNTIF(年計!$D$48:$I$87,AN18) -> 6 | D19: =COUNTIF(年計!$D$48:$I$87,AO18) -> 5 | F19: =COUNTIF(年計!$D$48:$I$87,AQ18) -> 5 | G19: =COUNTIF(年計!$J$48:$O$87,AR18) -> 4 | H19: =COUNTIF(年計!$J$48:$O$87,AS18) -> 6 | I19: =COUNTIF(年計!$J$48:$O$87,AT18) -> 4 | J19: =COUNTIF(年計!$J$48:$O$87,AU18) -> 0 | K19: =COUNTIF(年計!$J$48:$O$87,AV18) -> 4 | L19: =COUNTIF(年計!$P$48:$U$87,AW18) -> 4 | M19: =COUNTIF(年計!$P$48:$U$87,AX18) -> 5 | N19: =COUNTIF(年計!$P$48:$U$87,AY18) -> 4 | O19: =COUNTIF(年計!$P$48:$U$87,AZ18) -> 0 | P19: =COUNTIF(年計!$P$48:$U$87,BA18) -> 4 | S19: 6 | T19: =COUNTIF(年計!$D$2:$I$87,BB18) -> 7 | U19: =COUNTIF(年計!$D$2:$I$87,BC18) -> 8 | V19: =COUNTIF(年計!$D$2:$I$87,BD18) -> 17 | X19: =COUNTIF(年計!$D$2:$I$87,BF18) -> 7 | Y19: =COUNTIF(年計!$J$2:$O$87,BG18) -> 6 | Z19: =COUNTIF(年計!$J$2:$O$87,BH18) -> 8 | AA19: =COUNTIF(年計!$J$2:$O$87,BI18) -> 15 | AB19: =COUNTIF(年計!$J$2:$O$87,BJ18) -> 0 | AC19: =COUNTIF(年計!$J$2:$O$87,BK18) -> 6 | AD19: =COUNTIF(年計!$P$2:$U$87,BL18) -> 6 | AE19: =COUNTIF(年計!$P$2:$U$87,BM18) -> 7 | AF19: =COUNTIF(年計!$P$2:$U$87,BN18) -> 15 | AG19: =COUNTIF(年計!$P$2:$U$87,BO18) -> 0 | AH19: =COUNTIF(年計!$P$2:$U$87,BP18) -> 5
A20: ＜１期末テ～２期中テ＞ | S20: ＜２期中テまで 累計＞
B21: 月 | C21: 火 | D21: 水 | E21: 木 | F21: 金 | G21: 月 | H21: 火 | I21: 水 | J21: 木 | K21: 金 | L21: 月 | M21: 火 | N21: 水 | O21: 木 | P21: 金 | T21: 月 | U21: 火 | V21: 水 | W21: 木 | X21: 金 | Y21: 月 | Z21: 火 | AA21: 水 | AB21: 木 | AC21: 金 | AD21: 月 | AE21: 火 | AF21: 水 | AG21: 木 | AH21: 金 | AM21: 月１ | AN21: 火１ | AO21: 水１ | AP21: 木１ | AQ21: 金１ | AR21: 月１ | AS21: 火１ | AT21: 水１ | AU21: 木１ | AV21: 金１ | AW21: 月１ | AX21: 火１ | AY21: 水１ | AZ21: 木１ | BA21: 金１ | BB21: 月１ | BC21: 火１ | BD21: 水１ | BE21: 木１ | BF21: 金１ | BG21: 月１ | BH21: 火１ | BI21: 水１ | BJ21: 木１ | BK21: 金１ | BL21: 月１ | BM21: 火１ | BN21: 水１ | BO21: 木１ | BP21: 金１
A22: 1 | B22: =COUNTIF(年計!$D$88:$I$180,AM21) -> 4 | C22: =COUNTIF(年計!$D$90:$I$180,AN21) -> 4 | D22: =COUNTIF(年計!$D$90:$I$180,AO21) -> 6 | E22: =COUNTIF(年計!$D$90:$I$180,AP21) -> 5 | F22: =COUNTIF(年計!$D$90:$I$180,AQ21) -> 5 | G22: =COUNTIF(年計!$J$90:$O$180,AR21) -> 4 | H22: =COUNTIF(年計!$J$90:$O$180,AS21) -> 4 | I22: =COUNTIF(年計!$J$90:$O$180,AT21) -> 6 | J22: =COUNTIF(年計!$J$90:$O$180,AU21) -> 5 | K22: =COUNTIF(年計!$J$90:$O$180,AV21) -> 5 | L22: =COUNTIF(年計!$P$90:$U$180,AW21) -> 4 | M22: =COUNTIF(年計!$P$90:$U$180,AX21) -> 4 | N22: =COUNTIF(年計!$P$90:$U$180,AY21) -> 5 | O22: =COUNTIF(年計!$P$90:$U$180,AZ21) -> 5 | P22: =COUNTIF(年計!$P$90:$U$180,BA21) -> 5 | S22: 1 | T22: =COUNTIF(年計!$D$2:$I$180,BB21) -> 13 | U22: =COUNTIF(年計!$D$2:$I$180,BC21) -> 13 | V22: =COUNTIF(年計!$D$2:$I$180,BD21) -> 14 | W22: =COUNTIF(年計!$D$2:$I$180,BE21) -> 14 | X22: =COUNTIF(年計!$D$2:$I$180,BF21) -> 14 | Y22: =COUNTIF(年計!$J$2:$O$180,BG21) -> 12 | Z22: =COUNTIF(年計!$J$2:$O$180,BH21) -> 13 | AA22: =COUNTIF(年計!$J$2:$O$180,BI21) -> 13 | AB22: =COUNTIF(年計!$J$2:$O$180,BJ21) -> 13 | AC22: =COUNTIF(年計!$J$2:$O$180,BK21) -> 13 | AD22: =COUNTIF(年計!$P$2:$U$180,BL21) -> 12 | AE22: =COUNTIF(年計!$P$2:$U$180,BM21) -> 12 | AF22: =COUNTIF(年計!$P$2:$U$180,BN21) -> 12 | AG22: =COUNTIF(年計!$P$2:$U$180,BO21) -> 12 | AH22: =COUNTIF(年計!$P$2:$U$180,BP21) -> 13 | AI22: 定期テスト③ | AJ22: =MATCH(AI22,年計!$C$2:$C$367,0) -> #N/A | AM22: 月２ | AN22: 火２ | AO22: 水２ | AP22: 木２ | AQ22: 金２ | AR22: 月２ | AS22: 火２ | AT22: 水２ | AU22: 木２ | AV22: 金２ | AW22: 月２ | AX22: 火２ | AY22: 水２ | AZ22: 木２ | BA22: 金２ | BB22: 月２ | BC22: 火２ | BD22: 水２ | BE22: 木２ | BF22: 金２ | BG22: 月２ | BH22: 火２ | BI22: 水２ | BJ22: 木２ | BK22: 金２ | BL22: 月２ | BM22: 火２ | BN22: 水２ | BO22: 木２ | BP22: 金２
A23: 2 | B23: =COUNTIF(年計!$D$88:$I$180,AM22) -> 4 | C23: =COUNTIF(年計!$D$90:$I$180,AN22) -> 4 | D23: =COUNTIF(年計!$D$90:$I$180,AO22) -> 6 | E23: =COUNTIF(年計!$D$90:$I$180,AP22) -> 6 | F23: =COUNTIF(年計!$D$90:$I$180,AQ22) -> 5 | G23: =COUNTIF(年計!$J$90:$O$180,AR22) -> 4 | H23: =COUNTIF(年計!$J$90:$O$180,AS22) -> 4 | I23: =COUNTIF(年計!$J$90:$O$180,AT22) -> 6 | J23: =COUNTIF(年計!$J$90:$O$180,AU22) -> 6 | K23: =COUNTIF(年計!$J$90:$O$180,AV22) -> 5 | L23: =COUNTIF(年計!$P$90:$U$180,AW22) -> 4 | M23: =COUNTIF(年計!$P$90:$U$180,AX22) -> 4 | N23: =COUNTIF(年計!$P$90:$U$180,AY22) -> 5 | O23: =COUNTIF(年計!$P$90:$U$180,AZ22) -> 6 | P23: =COUNTIF(年計!$P$90:$U$180,BA22) -> 5 | S23: 2 | T23: =COUNTIF(年計!$D$2:$I$180,BB22) -> 13 | U23: =COUNTIF(年計!$D$2:$I$180,BC22) -> 13 | V23: =COUNTIF(年計!$D$2:$I$180,BD22) -> 14 | W23: =COUNTIF(年計!$D$2:$I$180,BE22) -> 15 | X23: =COUNTIF(年計!$D$2:$I$180,BF22) -> 13 | Y23: =COUNTIF(年計!$J$2:$O$180,BG22) -> 12 | Z23: =COUNTIF(年計!$J$2:$O$180,BH22) -> 13 | AA23: =COUNTIF(年計!$J$2:$O$180,BI22) -> 13 | AB23: =COUNTIF(年計!$J$2:$O$180,BJ22) -> 14 | AC23: =COUNTIF(年計!$J$2:$O$180,BK22) -> 12 | AD23: =COUNTIF(年計!$P$2:$U$180,BL22) -> 12 | AE23: =COUNTIF(年計!$P$2:$U$180,BM22) -> 12 | AF23: =COUNTIF(年計!$P$2:$U$180,BN22) -> 12 | AG23: =COUNTIF(年計!$P$2:$U$180,BO22) -> 13 | AH23: =COUNTIF(年計!$P$2:$U$180,BP22) -> 12 | AM23: 月３ | AN23: 火３ | AO23: 水３ | AP23: 木３ | AQ23: 金３ | AR23: 月３ | AS23: 火３ | AT23: 水３ | AU23: 木３ | AV23: 金３ | AW23: 月３ | AX23: 火３ | AY23: 水３ | AZ23: 木３ | BA23: 金３ | BB23: 月３ | BC23: 火３ | BD23: 水３ | BE23: 木３ | BF23: 金３ | BG23: 月３ | BH23: 火３ | BI23: 水３ | BJ23: 木３ | BK23: 金３ | BL23: 月３ | BM23: 火３ | BN23: 水３ | BO23: 木３ | BP23: 金３
A24: 3 | B24: =COUNTIF(年計!$D$88:$I$180,AM23) -> 4 | C24: =COUNTIF(年計!$D$90:$I$180,AN23) -> 4 | D24: =COUNTIF(年計!$D$90:$I$180,AO23) -> 5 | E24: =COUNTIF(年計!$D$90:$I$180,AP23) -> 6 | F24: =COUNTIF(年計!$D$90:$I$180,AQ23) -> 5 | G24: =COUNTIF(年計!$J$90:$O$180,AR23) -> 4 | H24: =COUNTIF(年計!$J$90:$O$180,AS23) -> 4 | I24: =COUNTIF(年計!$J$90:$O$180,AT23) -> 5 | J24: =COUNTIF(年計!$J$90:$O$180,AU23) -> 6 | K24: =COUNTIF(年計!$J$90:$O$180,AV23) -> 5 | L24: =COUNTIF(年計!$P$90:$U$180,AW23) -> 4 | M24: =COUNTIF(年計!$P$90:$U$180,AX23) -> 4 | N24: =COUNTIF(年計!$P$90:$U$180,AY23) -> 5 | O24: =COUNTIF(年計!$P$90:$U$180,AZ23) -> 5 | P24: =COUNTIF(年計!$P$90:$U$180,BA23) -> 5 | S24: 3 | T24: =COUNTIF(年計!$D$2:$I$180,BB23) -> 13 | U24: =COUNTIF(年計!$D$2:$I$180,BC23) -> 13 | V24: =COUNTIF(年計!$D$2:$I$180,BD23) -> 13 | W24: =COUNTIF(年計!$D$2:$I$180,BE23) -> 15 | X24: =COUNTIF(年計!$D$2:$I$180,BF23) -> 13 | Y24: =COUNTIF(年計!$J$2:$O$180,BG23) -> 12 | Z24: =COUNTIF(年計!$J$2:$O$180,BH23) -> 13 | AA24: =COUNTIF(年計!$J$2:$O$180,BI23) -> 12 | AB24: =COUNTIF(年計!$J$2:$O$180,BJ23) -> 14 | AC24: =COUNTIF(年計!$J$2:$O$180,BK23) -> 12 | AD24: =COUNTIF(年計!$P$2:$U$180,BL23) -> 12 | AE24: =COUNTIF(年計!$P$2:$U$180,BM23) -> 12 | AF24: =COUNTIF(年計!$P$2:$U$180,BN23) -> 12 | AG24: =COUNTIF(年計!$P$2:$U$180,BO23) -> 12 | AH24: =COUNTIF(年計!$P$2:$U$180,BP23) -> 12 | AM24: 月４ | AN24: 火４ | AO24: 水４ | AP24: 木４ | AQ24: 金４ | AR24: 月４ | AS24: 火４ | AT24: 水４ | AU24: 木４ | AV24: 金４ | AW24: 月４ | AX24: 火４ | AY24: 水４ | AZ24: 木４ | BA24: 金４ | BB24: 月４ | BC24: 火４ | BD24: 水４ | BE24: 木４ | BF24: 金４ | BG24: 月４ | BH24: 火４ | BI24: 水４ | BJ24: 木４ | BK24: 金４ | BL24: 月４ | BM24: 火４ | BN24: 水４ | BO24: 木４ | BP24: 金４
A25: 4 | B25: =COUNTIF(年計!$D$88:$I$180,AM24) -> 4 | C25: =COUNTIF(年計!$D$90:$I$180,AN24) -> 4 | D25: =COUNTIF(年計!$D$90:$I$180,AO24) -> 4 | E25: =COUNTIF(年計!$D$90:$I$180,AP24) -> 5 | F25: =COUNTIF(年計!$D$90:$I$180,AQ24) -> 4 | G25: =COUNTIF(年計!$J$90:$O$180,AR24) -> 4 | H25: =COUNTIF(年計!$J$90:$O$180,AS24) -> 4 | I25: =COUNTIF(年計!$J$90:$O$180,AT24) -> 4 | J25: =COUNTIF(年計!$J$90:$O$180,AU24) -> 6 | K25: =COUNTIF(年計!$J$90:$O$180,AV24) -> 4 | L25: =COUNTIF(年計!$P$90:$U$180,AW24) -> 4 | M25: =COUNTIF(年計!$P$90:$U$180,AX24) -> 4 | N25: =COUNTIF(年計!$P$90:$U$180,AY24) -> 4 | O25: =COUNTIF(年計!$P$90:$U$180,AZ24) -> 5 | P25: =COUNTIF(年計!$P$90:$U$180,BA24) -> 4 | S25: 4 | T25: =COUNTIF(年計!$D$2:$I$180,BB24) -> 13 | U25: =COUNTIF(年計!$D$2:$I$180,BC24) -> 13 | V25: =COUNTIF(年計!$D$2:$I$180,BD24) -> 12 | W25: =COUNTIF(年計!$D$2:$I$180,BE24) -> 14 | X25: =COUNTIF(年計!$D$2:$I$180,BF24) -> 13 | Y25: =COUNTIF(年計!$J$2:$O$180,BG24) -> 12 | Z25: =COUNTIF(年計!$J$2:$O$180,BH24) -> 13 | AA25: =COUNTIF(年計!$J$2:$O$180,BI24) -> 11 | AB25: =COUNTIF(年計!$J$2:$O$180,BJ24) -> 14 | AC25: =COUNTIF(年計!$J$2:$O$180,BK24) -> 12 | AD25: =COUNTIF(年計!$P$2:$U$180,BL24) -> 12 | AE25: =COUNTIF(年計!$P$2:$U$180,BM24) -> 12 | AF25: =COUNTIF(年計!$P$2:$U$180,BN24) -> 11 | AG25: =COUNTIF(年計!$P$2:$U$180,BO24) -> 12 | AH25: =COUNTIF(年計!$P$2:$U$180,BP24) -> 12 | AM25: 月５ | AN25: 火５ | AO25: 水５ | AP25: 木５ | AQ25: 金５ | AR25: 月５ | AS25: 火５ | AT25: 水５ | AU25: 木５ | AV25: 金５ | AW25: 月５ | AX25: 火５ | AY25: 水５ | AZ25: 木５ | BA25: 金５ | BB25: 月５ | BC25: 火５ | BD25: 水５ | BE25: 木５ | BF25: 金５ | BG25: 月５ | BH25: 火５ | BI25: 水５ | BJ25: 木５ | BK25: 金５ | BL25: 月５ | BM25: 火５ | BN25: 水５ | BO25: 木５ | BP25: 金５
A26: 5 | B26: =COUNTIF(年計!$D$88:$I$180,AM25) -> 4 | C26: =COUNTIF(年計!$D$90:$I$180,AN25) -> 5 | D26: =COUNTIF(年計!$D$90:$I$180,AO25) -> 5 | E26: =COUNTIF(年計!$D$90:$I$180,AP25) -> 6 | F26: =COUNTIF(年計!$D$90:$I$180,AQ25) -> 5 | G26: =COUNTIF(年計!$J$90:$O$180,AR25) -> 4 | H26: =COUNTIF(年計!$J$90:$O$180,AS25) -> 4 | I26: =COUNTIF(年計!$J$90:$O$180,AT25) -> 5 | J26: =COUNTIF(年計!$J$90:$O$180,AU25) -> 6 | K26: =COUNTIF(年計!$J$90:$O$180,AV25) -> 5 | L26: =COUNTIF(年計!$P$90:$U$180,AW25) -> 4 | M26: =COUNTIF(年計!$P$90:$U$180,AX25) -> 4 | N26: =COUNTIF(年計!$P$90:$U$180,AY25) -> 5 | O26: =COUNTIF(年計!$P$90:$U$180,AZ25) -> 5 | P26: =COUNTIF(年計!$P$90:$U$180,BA25) -> 5 | S26: 5 | T26: =COUNTIF(年計!$D$2:$I$180,BB25) -> 13 | U26: =COUNTIF(年計!$D$2:$I$180,BC25) -> 14 | V26: =COUNTIF(年計!$D$2:$I$180,BD25) -> 13 | W26: =COUNTIF(年計!$D$2:$I$180,BE25) -> 15 | X26: =COUNTIF(年計!$D$2:$I$180,BF25) -> 13 | Y26: =COUNTIF(年計!$J$2:$O$180,BG25) -> 12 | Z26: =COUNTIF(年計!$J$2:$O$180,BH25) -> 13 | AA26: =COUNTIF(年計!$J$2:$O$180,BI25) -> 12 | AB26: =COUNTIF(年計!$J$2:$O$180,BJ25) -> 14 | AC26: =COUNTIF(年計!$J$2:$O$180,BK25) -> 12 | AD26: =COUNTIF(年計!$P$2:$U$180,BL25) -> 12 | AE26: =COUNTIF(年計!$P$2:$U$180,BM25) -> 12 | AF26: =COUNTIF(年計!$P$2:$U$180,BN25) -> 12 | AG26: =COUNTIF(年計!$P$2:$U$180,BO25) -> 12 | AH26: =COUNTIF(年計!$P$2:$U$180,BP25) -> 12 | AM26: 月６ | AN26: 火６ | AO26: 水６ | AP26: 木６ | AQ26: 金６ | AR26: 月６ | AS26: 火６ | AT26: 水６ | AU26: 木６ | AV26: 金６ | AW26: 月６ | AX26: 火６ | AY26: 水６ | AZ26: 木６ | BA26: 金６ | BB26: 月６ | BC26: 火６ | BD26: 水６ | BE26: 木６ | BF26: 金６ | BG26: 月６ | BH26: 火６ | BI26: 水６ | BJ26: 木６ | BK26: 金６ | BL26: 月６ | BM26: 火６ | BN26: 水６ | BO26: 木６ | BP26: 金６
A27: 6 | B27: =COUNTIF(年計!$D$88:$I$180,AM26) -> 4 | C27: =COUNTIF(年計!$D$90:$I$180,AN26) -> 6 | D27: =COUNTIF(年計!$D$90:$I$180,AO26) -> 9 | E27: =COUNTIF(年計!$D$90:$I$180,AP26) -> 0 | F27: =COUNTIF(年計!$D$90:$I$180,AQ26) -> 5 | G27: =COUNTIF(年計!$J$90:$O$180,AR26) -> 4 | H27: =COUNTIF(年計!$J$90:$O$180,AS26) -> 6 | I27: =COUNTIF(年計!$J$90:$O$180,AT26) -> 9 | J27: =COUNTIF(年計!$J$90:$O$180,AU26) -> 0 | K27: =COUNTIF(年計!$J$90:$O$180,AV26) -> 5 | L27: =COUNTIF(年計!$P$90:$U$180,AW26) -> 4 | M27: =COUNTIF(年計!$P$90:$U$180,AX26) -> 5 | N27: =COUNTIF(年計!$P$90:$U$180,AY26) -> 9 | O27: =COUNTIF(年計!$P$90:$U$180,AZ26) -> 0 | P27: =COUNTIF(年計!$P$90:$U$180,BA26) -> 4 | S27: 6 | T27: =COUNTIF(年計!$D$2:$I$180,BB26) -> 11 | U27: =COUNTIF(年計!$D$2:$I$180,BC26) -> 14 | V27: =COUNTIF(年計!$D$2:$I$180,BD26) -> 26 | W27: =COUNTIF(年計!$D$2:$I$180,BE26) -> 0 | X27: =COUNTIF(年計!$D$2:$I$180,BF26) -> 12 | Y27: =COUNTIF(年計!$J$2:$O$180,BG26) -> 10 | Z27: =COUNTIF(年計!$J$2:$O$180,BH26) -> 14 | AA27: =COUNTIF(年計!$J$2:$O$180,BI26) -> 24 | AB27: =COUNTIF(年計!$J$2:$O$180,BJ26) -> 0 | AC27: =COUNTIF(年計!$J$2:$O$180,BK26) -> 11 | AD27: =COUNTIF(年計!$P$2:$U$180,BL26) -> 10 | AE27: =COUNTIF(年計!$P$2:$U$180,BM26) -> 12 | AF27: =COUNTIF(年計!$P$2:$U$180,BN26) -> 24 | AG27: =COUNTIF(年計!$P$2:$U$180,BO26) -> 0 | AH27: =COUNTIF(年計!$P$2:$U$180,BP26) -> 9
A28: ＜２期中テ～２期末テ＞ | S28: ＜２期末テまで 累計＞
B29: 月 | C29: 火 | D29: 水 | E29: 木 | F29: 金 | G29: 月 | H29: 火 | I29: 水 | J29: 木 | K29: 金 | L29: 月 | M29: 火 | N29: 水 | O29: 木 | P29: 金 | T29: 月 | U29: 火 | V29: 水 | W29: 木 | X29: 金 | Y29: 月 | Z29: 火 | AA29: 水 | AB29: 木 | AC29: 金 | AD29: 月 | AE29: 火 | AF29: 水 | AG29: 木 | AH29: 金 | AM29: 月１ | AN29: 火１ | AO29: 水１ | AP29: 木１ | AQ29: 金１ | AR29: 月１ | AS29: 火１ | AT29: 水１ | AU29: 木１ | AV29: 金１ | AW29: 月１ | AX29: 火１ | AY29: 水１ | AZ29: 木１ | BA29: 金１ | BB29: 月１ | BC29: 火１ | BD29: 水１ | BE29: 木１ | BF29: 金１ | BG29: 月１ | BH29: 火１ | BI29: 水１ | BJ29: 木１ | BK29: 金１ | BL29: 月１ | BM29: 火１ | BN29: 水１ | BO29: 木１ | BP29: 金１
A30: 1 | B30: =COUNTIF(年計!$D$185:$I$232,AM29) -> 6 | C30: =COUNTIF(年計!$D$185:$I$232,AN29) -> 6 | D30: =COUNTIF(年計!$D$185:$I$232,AO29) -> 4 | E30: =COUNTIF(年計!$D$185:$I$232,AP29) -> 5 | F30: =COUNTIF(年計!$D$185:$I$232,AQ29) -> 5 | G30: =COUNTIF(年計!$J$185:$O$232,AR29) -> 6 | H30: =COUNTIF(年計!$J$185:$O$232,AS29) -> 6 | I30: =COUNTIF(年計!$J$185:$O$232,AT29) -> 5 | J30: =COUNTIF(年計!$J$185:$O$232,AU29) -> 5 | K30: =COUNTIF(年計!$J$185:$O$232,AV29) -> 5 | L30: =COUNTIF(年計!$P$185:$U$232,AW29) -> 6 | M30: =COUNTIF(年計!$P$185:$U$232,AX29) -> 6 | N30: =COUNTIF(年計!$P$185:$U$232,AY29) -> 5 | O30: =COUNTIF(年計!$P$185:$U$232,AZ29) -> 5 | P30: =COUNTIF(年計!$P$185:$U$232,BA29) -> 4 | S30: 1 | T30: =COUNTIF(年計!$D$2:$I$232,BB29) -> 19 | U30: =COUNTIF(年計!$D$2:$I$232,BC29) -> 19 | V30: =COUNTIF(年計!$D$2:$I$232,BD29) -> 18 | W30: =COUNTIF(年計!$D$2:$I$232,BE29) -> 19 | X30: =COUNTIF(年計!$D$2:$I$232,BF29) -> 19 | Y30: =COUNTIF(年計!$J$2:$O$232,BG29) -> 18 | Z30: =COUNTIF(年計!$J$2:$O$232,BH29) -> 19 | AA30: =COUNTIF(年計!$J$2:$O$232,BI29) -> 18 | AB30: =COUNTIF(年計!$J$2:$O$232,BJ29) -> 18 | AC30: =COUNTIF(年計!$J$2:$O$232,BK29) -> 18 | AD30: =COUNTIF(年計!$P$2:$U$232,BL29) -> 18 | AE30: =COUNTIF(年計!$P$2:$U$232,BM29) -> 18 | AF30: =COUNTIF(年計!$P$2:$U$232,BN29) -> 17 | AG30: =COUNTIF(年計!$P$2:$U$232,BO29) -> 17 | AH30: =COUNTIF(年計!$P$2:$U$232,BP29) -> 17 | AI30: 定期テスト④ | AJ30: =MATCH(AI30,年計!$C$2:$C$367,0) -> #N/A | AM30: 月２ | AN30: 火２ | AO30: 水２ | AP30: 木２ | AQ30: 金２ | AR30: 月２ | AS30: 火２ | AT30: 水２ | AU30: 木２ | AV30: 金２ | AW30: 月２ | AX30: 火２ | AY30: 水２ | AZ30: 木２ | BA30: 金２ | BB30: 月２ | BC30: 火２ | BD30: 水２ | BE30: 木２ | BF30: 金２ | BG30: 月２ | BH30: 火２ | BI30: 水２ | BJ30: 木２ | BK30: 金２ | BL30: 月２ | BM30: 火２ | BN30: 水２ | BO30: 木２ | BP30: 金２
A31: 2 | B31: =COUNTIF(年計!$D$185:$I$232,AM30) -> 6 | C31: =COUNTIF(年計!$D$185:$I$232,AN30) -> 5 | D31: =COUNTIF(年計!$D$185:$I$232,AO30) -> 5 | E31: =COUNTIF(年計!$D$185:$I$232,AP30) -> 4 | F31: =COUNTIF(年計!$D$185:$I$232,AQ30) -> 6 | G31: =COUNTIF(年計!$J$185:$O$232,AR30) -> 6 | H31: =COUNTIF(年計!$J$185:$O$232,AS30) -> 5 | I31: =COUNTIF(年計!$J$185:$O$232,AT30) -> 4 | J31: =COUNTIF(年計!$J$185:$O$232,AU30) -> 4 | K31: =COUNTIF(年計!$J$185:$O$232,AV30) -> 6 | L31: =COUNTIF(年計!$P$185:$U$232,AW30) -> 6 | M31: =COUNTIF(年計!$P$185:$U$232,AX30) -> 5 | N31: =COUNTIF(年計!$P$185:$U$232,AY30) -> 4 | O31: =COUNTIF(年計!$P$185:$U$232,AZ30) -> 4 | P31: =COUNTIF(年計!$P$185:$U$232,BA30) -> 5 | S31: 2 | T31: =COUNTIF(年計!$D$2:$I$232,BB30) -> 19 | U31: =COUNTIF(年計!$D$2:$I$232,BC30) -> 18 | V31: =COUNTIF(年計!$D$2:$I$232,BD30) -> 19 | W31: =COUNTIF(年計!$D$2:$I$232,BE30) -> 19 | X31: =COUNTIF(年計!$D$2:$I$232,BF30) -> 19 | Y31: =COUNTIF(年計!$J$2:$O$232,BG30) -> 18 | Z31: =COUNTIF(年計!$J$2:$O$232,BH30) -> 18 | AA31: =COUNTIF(年計!$J$2:$O$232,BI30) -> 17 | AB31: =COUNTIF(年計!$J$2:$O$232,BJ30) -> 18 | AC31: =COUNTIF(年計!$J$2:$O$232,BK30) -> 18 | AD31: =COUNTIF(年計!$P$2:$U$232,BL30) -> 18 | AE31: =COUNTIF(年計!$P$2:$U$232,BM30) -> 17 | AF31: =COUNTIF(年計!$P$2:$U$232,BN30) -> 16 | AG31: =COUNTIF(年計!$P$2:$U$232,BO30) -> 17 | AH31: =COUNTIF(年計!$P$2:$U$232,BP30) -> 17 | AM31: 月３ | AN31: 火３ | AO31: 水３ | AP31: 木３ | AQ31: 金３ | AR31: 月３ | AS31: 火３ | AT31: 水３ | AU31: 木３ | AV31: 金３ | AW31: 月３ | AX31: 火３ | AY31: 水３ | AZ31: 木３ | BA31: 金３ | BB31: 月３ | BC31: 火３ | BD31: 水３ | BE31: 木３ | BF31: 金３ | BG31: 月３ | BH31: 火３ | BI31: 水３ | BJ31: 木３ | BK31: 金３ | BL31: 月３ | BM31: 火３ | BN31: 水３ | BO31: 木３ | BP31: 金３
A32: 3 | B32: =COUNTIF(年計!$D$185:$I$232,AM31) -> 5 | C32: =COUNTIF(年計!$D$185:$I$232,AN31) -> 5 | D32: =COUNTIF(年計!$D$185:$I$232,AO31) -> 5 | E32: =COUNTIF(年計!$D$185:$I$232,AP31) -> 4 | F32: =COUNTIF(年計!$D$185:$I$232,AQ31) -> 6 | G32: =COUNTIF(年計!$J$185:$O$232,AR31) -> 5 | H32: =COUNTIF(年計!$J$185:$O$232,AS31) -> 5 | I32: =COUNTIF(年計!$J$185:$O$232,AT31) -> 5 | J32: =COUNTIF(年計!$J$185:$O$232,AU31) -> 4 | K32: =COUNTIF(年計!$J$185:$O$232,AV31) -> 6 | L32: =COUNTIF(年計!$P$185:$U$232,AW31) -> 5 | M32: =COUNTIF(年計!$P$185:$U$232,AX31) -> 5 | N32: =COUNTIF(年計!$P$185:$U$232,AY31) -> 5 | O32: =COUNTIF(年計!$P$185:$U$232,AZ31) -> 4 | P32: =COUNTIF(年計!$P$185:$U$232,BA31) -> 5 | S32: 3 | T32: =COUNTIF(年計!$D$2:$I$232,BB31) -> 18 | U32: =COUNTIF(年計!$D$2:$I$232,BC31) -> 18 | V32: =COUNTIF(年計!$D$2:$I$232,BD31) -> 18 | W32: =COUNTIF(年計!$D$2:$I$232,BE31) -> 19 | X32: =COUNTIF(年計!$D$2:$I$232,BF31) -> 19 | Y32: =COUNTIF(年計!$J$2:$O$232,BG31) -> 17 | Z32: =COUNTIF(年計!$J$2:$O$232,BH31) -> 18 | AA32: =COUNTIF(年計!$J$2:$O$232,BI31) -> 17 | AB32: =COUNTIF(年計!$J$2:$O$232,BJ31) -> 18 | AC32: =COUNTIF(年計!$J$2:$O$232,BK31) -> 18 | AD32: =COUNTIF(年計!$P$2:$U$232,BL31) -> 17 | AE32: =COUNTIF(年計!$P$2:$U$232,BM31) -> 17 | AF32: =COUNTIF(年計!$P$2:$U$232,BN31) -> 17 | AG32: =COUNTIF(年計!$P$2:$U$232,BO31) -> 16 | AH32: =COUNTIF(年計!$P$2:$U$232,BP31) -> 17 | AM32: 月４ | AN32: 火４ | AO32: 水４ | AP32: 木４ | AQ32: 金４ | AR32: 月４ | AS32: 火４ | AT32: 水４ | AU32: 木４ | AV32: 金４ | AW32: 月４ | AX32: 火４ | AY32: 水４ | AZ32: 木４ | BA32: 金４ | BB32: 月４ | BC32: 火４ | BD32: 水４ | BE32: 木４ | BF32: 金４ | BG32: 月４ | BH32: 火４ | BI32: 水４ | BJ32: 木４ | BK32: 金４ | BL32: 月４ | BM32: 火４ | BN32: 水４ | BO32: 木４ | BP32: 金４
A33: 4 | B33: =COUNTIF(年計!$D$185:$I$232,AM32) -> 5 | C33: =COUNTIF(年計!$D$185:$I$232,AN32) -> 5 | D33: =COUNTIF(年計!$D$185:$I$232,AO32) -> 6 | E33: =COUNTIF(年計!$D$185:$I$232,AP32) -> 5 | F33: =COUNTIF(年計!$D$185:$I$232,AQ32) -> 6 | G33: =COUNTIF(年計!$J$185:$O$232,AR32) -> 5 | H33: =COUNTIF(年計!$J$185:$O$232,AS32) -> 5 | I33: =COUNTIF(年計!$J$185:$O$232,AT32) -> 6 | J33: =COUNTIF(年計!$J$185:$O$232,AU32) -> 5 | K33: =COUNTIF(年計!$J$185:$O$232,AV32) -> 6 | L33: =COUNTIF(年計!$P$185:$U$232,AW32) -> 5 | M33: =COUNTIF(年計!$P$185:$U$232,AX32) -> 5 | N33: =COUNTIF(年計!$P$185:$U$232,AY32) -> 6 | O33: =COUNTIF(年計!$P$185:$U$232,AZ32) -> 5 | P33: =COUNTIF(年計!$P$185:$U$232,BA32) -> 5 | S33: 4 | T33: =COUNTIF(年計!$D$2:$I$232,BB32) -> 18 | U33: =COUNTIF(年計!$D$2:$I$232,BC32) -> 18 | V33: =COUNTIF(年計!$D$2:$I$232,BD32) -> 18 | W33: =COUNTIF(年計!$D$2:$I$232,BE32) -> 19 | X33: =COUNTIF(年計!$D$2:$I$232,BF32) -> 19 | Y33: =COUNTIF(年計!$J$2:$O$232,BG32) -> 17 | Z33: =COUNTIF(年計!$J$2:$O$232,BH32) -> 18 | AA33: =COUNTIF(年計!$J$2:$O$232,BI32) -> 17 | AB33: =COUNTIF(年計!$J$2:$O$232,BJ32) -> 19 | AC33: =COUNTIF(年計!$J$2:$O$232,BK32) -> 18 | AD33: =COUNTIF(年計!$P$2:$U$232,BL32) -> 17 | AE33: =COUNTIF(年計!$P$2:$U$232,BM32) -> 17 | AF33: =COUNTIF(年計!$P$2:$U$232,BN32) -> 17 | AG33: =COUNTIF(年計!$P$2:$U$232,BO32) -> 17 | AH33: =COUNTIF(年計!$P$2:$U$232,BP32) -> 17 | AM33: 月５ | AN33: 火５ | AO33: 水５ | AP33: 木５ | AQ33: 金５ | AR33: 月５ | AS33: 火５ | AT33: 水５ | AU33: 木５ | AV33: 金５ | AW33: 月５ | AX33: 火５ | AY33: 水５ | AZ33: 木５ | BA33: 金５ | BB33: 月５ | BC33: 火５ | BD33: 水５ | BE33: 木５ | BF33: 金５ | BG33: 月５ | BH33: 火５ | BI33: 水５ | BJ33: 木５ | BK33: 金５ | BL33: 月５ | BM33: 火５ | BN33: 水５ | BO33: 木５ | BP33: 金５
A34: 5 | B34: =COUNTIF(年計!$D$185:$I$232,AM33) -> 5 | C34: =COUNTIF(年計!$D$185:$I$232,AN33) -> 5 | D34: =COUNTIF(年計!$D$185:$I$232,AO33) -> 5 | E34: =COUNTIF(年計!$D$185:$I$232,AP33) -> 4 | F34: =COUNTIF(年計!$D$185:$I$232,AQ33) -> 5 | G34: =COUNTIF(年計!$J$185:$O$232,AR33) -> 5 | H34: =COUNTIF(年計!$J$185:$O$232,AS33) -> 5 | I34: =COUNTIF(年計!$J$185:$O$232,AT33) -> 5 | J34: =COUNTIF(年計!$J$185:$O$232,AU33) -> 4 | K34: =COUNTIF(年計!$J$185:$O$232,AV33) -> 5 | L34: =COUNTIF(年計!$P$185:$U$232,AW33) -> 4 | M34: =COUNTIF(年計!$P$185:$U$232,AX33) -> 5 | N34: =COUNTIF(年計!$P$185:$U$232,AY33) -> 5 | O34: =COUNTIF(年計!$P$185:$U$232,AZ33) -> 4 | P34: =COUNTIF(年計!$P$185:$U$232,BA33) -> 5 | S34: 5 | T34: =COUNTIF(年計!$D$2:$I$232,BB33) -> 18 | U34: =COUNTIF(年計!$D$2:$I$232,BC33) -> 19 | V34: =COUNTIF(年計!$D$2:$I$232,BD33) -> 18 | W34: =COUNTIF(年計!$D$2:$I$232,BE33) -> 19 | X34: =COUNTIF(年計!$D$2:$I$232,BF33) -> 18 | Y34: =COUNTIF(年計!$J$2:$O$232,BG33) -> 17 | Z34: =COUNTIF(年計!$J$2:$O$232,BH33) -> 18 | AA34: =COUNTIF(年計!$J$2:$O$232,BI33) -> 17 | AB34: =COUNTIF(年計!$J$2:$O$232,BJ33) -> 18 | AC34: =COUNTIF(年計!$J$2:$O$232,BK33) -> 17 | AD34: =COUNTIF(年計!$P$2:$U$232,BL33) -> 16 | AE34: =COUNTIF(年計!$P$2:$U$232,BM33) -> 17 | AF34: =COUNTIF(年計!$P$2:$U$232,BN33) -> 17 | AG34: =COUNTIF(年計!$P$2:$U$232,BO33) -> 16 | AH34: =COUNTIF(年計!$P$2:$U$232,BP33) -> 17 | AM34: 月６ | AN34: 火６ | AO34: 水６ | AP34: 木６ | AQ34: 金６ | AR34: 月６ | AS34: 火６ | AT34: 水６ | AU34: 木６ | AV34: 金６ | AW34: 月６ | AX34: 火６ | AY34: 水６ | AZ34: 木６ | BA34: 金６ | BB34: 月６ | BC34: 火６ | BD34: 水６ | BE34: 木６ | BF34: 金６ | BG34: 月６ | BH34: 火６ | BI34: 水６ | BJ34: 木６ | BK34: 金６ | BL34: 月６ | BM34: 火６ | BN34: 水６ | BO34: 木６ | BP34: 金６
A35: 6 | B35: =COUNTIF(年計!$D$185:$I$232,AM34) -> 2 | C35: =COUNTIF(年計!$D$185:$I$232,AN34) -> 4 | D35: =COUNTIF(年計!$D$185:$I$232,AO34) -> 3 | E35: =COUNTIF(年計!$D$185:$I$232,AP34) -> 0 | F35: =COUNTIF(年計!$D$185:$I$232,AQ34) -> 3 | G35: =COUNTIF(年計!$J$185:$O$232,AR34) -> 3 | H35: =COUNTIF(年計!$J$185:$O$232,AS34) -> 4 | I35: =COUNTIF(年計!$J$185:$O$232,AT34) -> 3 | J35: =COUNTIF(年計!$J$185:$O$232,AU34) -> 0 | K35: =COUNTIF(年計!$J$185:$O$232,AV34) -> 3 | L35: =COUNTIF(年計!$P$185:$U$232,AW34) -> 3 | M35: =COUNTIF(年計!$P$185:$U$232,AX34) -> 2 | N35: =COUNTIF(年計!$P$185:$U$232,AY34) -> 3 | O35: =COUNTIF(年計!$P$185:$U$232,AZ34) -> 0 | P35: =COUNTIF(年計!$P$185:$U$232,BA34) -> 2 | S35: 6 | T35: =COUNTIF(年計!$D$2:$I$232,BB34) -> 13 | U35: =COUNTIF(年計!$D$2:$I$232,BC34) -> 18 | V35: =COUNTIF(年計!$D$2:$I$232,BD34) -> 29 | W35: =COUNTIF(年計!$D$2:$I$232,BE34) -> 0 | X35: =COUNTIF(年計!$D$2:$I$232,BF34) -> 15 | Y35: =COUNTIF(年計!$J$2:$O$232,BG34) -> 13 | Z35: =COUNTIF(年計!$J$2:$O$232,BH34) -> 18 | AA35: =COUNTIF(年計!$J$2:$O$232,BI34) -> 27 | AB35: =COUNTIF(年計!$J$2:$O$232,BJ34) -> 0 | AC35: =COUNTIF(年計!$J$2:$O$232,BK34) -> 14 | AD35: =COUNTIF(年計!$P$2:$U$232,BL34) -> 13 | AE35: =COUNTIF(年計!$P$2:$U$232,BM34) -> 14 | AF35: =COUNTIF(年計!$P$2:$U$232,BN34) -> 27 | AG35: =COUNTIF(年計!$P$2:$U$232,BO34) -> 0 | AH35: =COUNTIF(年計!$P$2:$U$232,BP34) -> 11
A36: ＜２期末テ～12月末＞ | S36: ＜12月末まで 累計＞
B37: 月 | C37: 火 | D37: 水 | E37: 木 | F37: 金 | G37: 月 | H37: 火 | I37: 水 | J37: 木 | K37: 金 | L37: 月 | M37: 火 | N37: 水 | O37: 木 | P37: 金 | T37: 月 | U37: 火 | V37: 水 | W37: 木 | X37: 金 | Y37: 月 | Z37: 火 | AA37: 水 | AB37: 木 | AC37: 金 | AD37: 月 | AE37: 火 | AF37: 水 | AG37: 木 | AH37: 金 | AM37: 月１ | AN37: 火１ | AO37: 水１ | AP37: 木１ | AQ37: 金１ | AR37: 月１ | AS37: 火１ | AT37: 水１ | AU37: 木１ | AV37: 金１ | AW37: 月１ | AX37: 火１ | AY37: 水１ | AZ37: 木１ | BA37: 金１ | BB37: 月１ | BC37: 火１ | BD37: 水１ | BE37: 木１ | BF37: 金１ | BG37: 月１ | BH37: 火１ | BI37: 水１ | BJ37: 木１ | BK37: 金１ | BL37: 月１ | BM37: 火１ | BN37: 水１ | BO37: 木１ | BP37: 金１
A38: 1 | B38: =COUNTIF(年計!$D$235:$I$267,AM37) -> 4 | C38: =COUNTIF(年計!$D$235:$I$267,AN37) -> 3 | D38: =COUNTIF(年計!$D$235:$I$267,AO37) -> 3 | E38: =COUNTIF(年計!$D$235:$I$267,AP37) -> 4 | F38: =COUNTIF(年計!$D$235:$I$267,AQ37) -> 4 | G38: =COUNTIF(年計!$J$235:$O$267,AR37) -> 4 | H38: =COUNTIF(年計!$J$235:$O$267,AS37) -> 3 | I38: =COUNTIF(年計!$J$235:$O$267,AT37) -> 3 | J38: =COUNTIF(年計!$J$235:$O$267,AU37) -> 4 | K38: =COUNTIF(年計!$J$235:$O$267,AV37) -> 4 | L38: =COUNTIF(年計!$P$235:$U$267,AW37) -> 4 | M38: =COUNTIF(年計!$P$235:$U$267,AX37) -> 3 | N38: =COUNTIF(年計!$P$235:$U$267,AY37) -> 3 | O38: =COUNTIF(年計!$P$235:$U$267,AZ37) -> 4 | P38: =COUNTIF(年計!$P$235:$U$267,BA37) -> 3 | S38: 1 | T38: =COUNTIF(年計!$D$2:$I$267,BB37) -> 23 | U38: =COUNTIF(年計!$D$2:$I$267,BC37) -> 22 | V38: =COUNTIF(年計!$D$2:$I$267,BD37) -> 21 | W38: =COUNTIF(年計!$D$2:$I$267,BE37) -> 23 | X38: =COUNTIF(年計!$D$2:$I$267,BF37) -> 23 | Y38: =COUNTIF(年計!$J$2:$O$267,BG37) -> 22 | Z38: =COUNTIF(年計!$J$2:$O$267,BH37) -> 22 | AA38: =COUNTIF(年計!$J$2:$O$267,BI37) -> 21 | AB38: =COUNTIF(年計!$J$2:$O$267,BJ37) -> 22 | AC38: =COUNTIF(年計!$J$2:$O$267,BK37) -> 22 | AD38: =COUNTIF(年計!$P$2:$U$267,BL37) -> 22 | AE38: =COUNTIF(年計!$P$2:$U$267,BM37) -> 21 | AF38: =COUNTIF(年計!$P$2:$U$267,BN37) -> 20 | AG38: =COUNTIF(年計!$P$2:$U$267,BO37) -> 21 | AH38: =COUNTIF(年計!$P$2:$U$267,BP37) -> 20 | AI38: 2学期終業式 | AJ38: =MATCH(AI38,年計!$C$2:$C$367,0) -> #N/A | AM38: 月２ | AN38: 火２ | AO38: 水２ | AP38: 木２ | AQ38: 金２ | AR38: 月２ | AS38: 火２ | AT38: 水２ | AU38: 木２ | AV38: 金２ | AW38: 月２ | AX38: 火２ | AY38: 水２ | AZ38: 木２ | BA38: 金２ | BB38: 月２ | BC38: 火２ | BD38: 水２ | BE38: 木２ | BF38: 金２ | BG38: 月２ | BH38: 火２ | BI38: 水２ | BJ38: 木２ | BK38: 金２ | BL38: 月２ | BM38: 火２ | BN38: 水２ | BO38: 木２ | BP38: 金２
A39: 2 | B39: =COUNTIF(年計!$D$235:$I$267,AM38) -> 3 | C39: =COUNTIF(年計!$D$235:$I$267,AN38) -> 4 | D39: =COUNTIF(年計!$D$235:$I$267,AO38) -> 3 | E39: =COUNTIF(年計!$D$235:$I$267,AP38) -> 4 | F39: =COUNTIF(年計!$D$235:$I$267,AQ38) -> 4 | G39: =COUNTIF(年計!$J$235:$O$267,AR38) -> 3 | H39: =COUNTIF(年計!$J$235:$O$267,AS38) -> 4 | I39: =COUNTIF(年計!$J$235:$O$267,AT38) -> 3 | J39: =COUNTIF(年計!$J$235:$O$267,AU38) -> 4 | K39: =COUNTIF(年計!$J$235:$O$267,AV38) -> 4 | L39: =COUNTIF(年計!$P$235:$U$267,AW38) -> 3 | M39: =COUNTIF(年計!$P$235:$U$267,AX38) -> 4 | N39: =COUNTIF(年計!$P$235:$U$267,AY38) -> 3 | O39: =COUNTIF(年計!$P$235:$U$267,AZ38) -> 4 | P39: =COUNTIF(年計!$P$235:$U$267,BA38) -> 4 | S39: 2 | T39: =COUNTIF(年計!$D$2:$I$267,BB38) -> 22 | U39: =COUNTIF(年計!$D$2:$I$267,BC38) -> 22 | V39: =COUNTIF(年計!$D$2:$I$267,BD38) -> 22 | W39: =COUNTIF(年計!$D$2:$I$267,BE38) -> 23 | X39: =COUNTIF(年計!$D$2:$I$267,BF38) -> 23 | Y39: =COUNTIF(年計!$J$2:$O$267,BG38) -> 21 | Z39: =COUNTIF(年計!$J$2:$O$267,BH38) -> 22 | AA39: =COUNTIF(年計!$J$2:$O$267,BI38) -> 20 | AB39: =COUNTIF(年計!$J$2:$O$267,BJ38) -> 22 | AC39: =COUNTIF(年計!$J$2:$O$267,BK38) -> 22 | AD39: =COUNTIF(年計!$P$2:$U$267,BL38) -> 21 | AE39: =COUNTIF(年計!$P$2:$U$267,BM38) -> 21 | AF39: =COUNTIF(年計!$P$2:$U$267,BN38) -> 19 | AG39: =COUNTIF(年計!$P$2:$U$267,BO38) -> 21 | AH39: =COUNTIF(年計!$P$2:$U$267,BP38) -> 21 | AM39: 月３ | AN39: 火３ | AO39: 水３ | AP39: 木３ | AQ39: 金３ | AR39: 月３ | AS39: 火３ | AT39: 水３ | AU39: 木３ | AV39: 金３ | AW39: 月３ | AX39: 火３ | AY39: 水３ | AZ39: 木３ | BA39: 金３ | BB39: 月３ | BC39: 火３ | BD39: 水３ | BE39: 木３ | BF39: 金３ | BG39: 月３ | BH39: 火３ | BI39: 水３ | BJ39: 木３ | BK39: 金３ | BL39: 月３ | BM39: 火３ | BN39: 水３ | BO39: 木３ | BP39: 金３
A40: 3 | B40: =COUNTIF(年計!$D$235:$I$267,AM39) -> 4 | C40: =COUNTIF(年計!$D$235:$I$267,AN39) -> 4 | D40: =COUNTIF(年計!$D$235:$I$267,AO39) -> 4 | E40: =COUNTIF(年計!$D$235:$I$267,AP39) -> 4 | F40: =COUNTIF(年計!$D$235:$I$267,AQ39) -> 4 | G40: =COUNTIF(年計!$J$235:$O$267,AR39) -> 4 | H40: =COUNTIF(年計!$J$235:$O$267,AS39) -> 4 | I40: =COUNTIF(年計!$J$235:$O$267,AT39) -> 4 | J40: =COUNTIF(年計!$J$235:$O$267,AU39) -> 4 | K40: =COUNTIF(年計!$J$235:$O$267,AV39) -> 4 | L40: =COUNTIF(年計!$P$235:$U$267,AW39) -> 4 | M40: =COUNTIF(年計!$P$235:$U$267,AX39) -> 4 | N40: =COUNTIF(年計!$P$235:$U$267,AY39) -> 4 | O40: =COUNTIF(年計!$P$235:$U$267,AZ39) -> 4 | P40: =COUNTIF(年計!$P$235:$U$267,BA39) -> 3 | S40: 3 | T40: =COUNTIF(年計!$D$2:$I$267,BB39) -> 22 | U40: =COUNTIF(年計!$D$2:$I$267,BC39) -> 22 | V40: =COUNTIF(年計!$D$2:$I$267,BD39) -> 22 | W40: =COUNTIF(年計!$D$2:$I$267,BE39) -> 23 | X40: =COUNTIF(年計!$D$2:$I$267,BF39) -> 23 | Y40: =COUNTIF(年計!$J$2:$O$267,BG39) -> 21 | Z40: =COUNTIF(年計!$J$2:$O$267,BH39) -> 22 | AA40: =COUNTIF(年計!$J$2:$O$267,BI39) -> 21 | AB40: =COUNTIF(年計!$J$2:$O$267,BJ39) -> 22 | AC40: =COUNTIF(年計!$J$2:$O$267,BK39) -> 22 | AD40: =COUNTIF(年計!$P$2:$U$267,BL39) -> 21 | AE40: =COUNTIF(年計!$P$2:$U$267,BM39) -> 21 | AF40: =COUNTIF(年計!$P$2:$U$267,BN39) -> 21 | AG40: =COUNTIF(年計!$P$2:$U$267,BO39) -> 20 | AH40: =COUNTIF(年計!$P$2:$U$267,BP39) -> 20 | AM40: 月４ | AN40: 火４ | AO40: 水４ | AP40: 木４ | AQ40: 金４ | AR40: 月４ | AS40: 火４ | AT40: 水４ | AU40: 木４ | AV40: 金４ | AW40: 月４ | AX40: 火４ | AY40: 水４ | AZ40: 木４ | BA40: 金４ | BB40: 月４ | BC40: 火４ | BD40: 水４ | BE40: 木４ | BF40: 金４ | BG40: 月４ | BH40: 火４ | BI40: 水４ | BJ40: 木４ | BK40: 金４ | BL40: 月４ | BM40: 火４ | BN40: 水４ | BO40: 木４ | BP40: 金４
A41: 4 | B41: =COUNTIF(年計!$D$235:$I$267,AM40) -> 4 | C41: =COUNTIF(年計!$D$235:$I$267,AN40) -> 4 | D41: =COUNTIF(年計!$D$235:$I$267,AO40) -> 4 | E41: =COUNTIF(年計!$D$235:$I$267,AP40) -> 3 | F41: =COUNTIF(年計!$D$235:$I$267,AQ40) -> 4 | G41: =COUNTIF(年計!$J$235:$O$267,AR40) -> 4 | H41: =COUNTIF(年計!$J$235:$O$267,AS40) -> 4 | I41: =COUNTIF(年計!$J$235:$O$267,AT40) -> 4 | J41: =COUNTIF(年計!$J$235:$O$267,AU40) -> 3 | K41: =COUNTIF(年計!$J$235:$O$267,AV40) -> 4 | L41: =COUNTIF(年計!$P$235:$U$267,AW40) -> 4 | M41: =COUNTIF(年計!$P$235:$U$267,AX40) -> 4 | N41: =COUNTIF(年計!$P$235:$U$267,AY40) -> 4 | O41: =COUNTIF(年計!$P$235:$U$267,AZ40) -> 3 | P41: =COUNTIF(年計!$P$235:$U$267,BA40) -> 3 | S41: 4 | T41: =COUNTIF(年計!$D$2:$I$267,BB40) -> 22 | U41: =COUNTIF(年計!$D$2:$I$267,BC40) -> 22 | V41: =COUNTIF(年計!$D$2:$I$267,BD40) -> 22 | W41: =COUNTIF(年計!$D$2:$I$267,BE40) -> 22 | X41: =COUNTIF(年計!$D$2:$I$267,BF40) -> 23 | Y41: =COUNTIF(年計!$J$2:$O$267,BG40) -> 21 | Z41: =COUNTIF(年計!$J$2:$O$267,BH40) -> 22 | AA41: =COUNTIF(年計!$J$2:$O$267,BI40) -> 21 | AB41: =COUNTIF(年計!$J$2:$O$267,BJ40) -> 22 | AC41: =COUNTIF(年計!$J$2:$O$267,BK40) -> 22 | AD41: =COUNTIF(年計!$P$2:$U$267,BL40) -> 21 | AE41: =COUNTIF(年計!$P$2:$U$267,BM40) -> 21 | AF41: =COUNTIF(年計!$P$2:$U$267,BN40) -> 21 | AG41: =COUNTIF(年計!$P$2:$U$267,BO40) -> 20 | AH41: =COUNTIF(年計!$P$2:$U$267,BP40) -> 20 | AM41: 月５ | AN41: 火５ | AO41: 水５ | AP41: 木５ | AQ41: 金５ | AR41: 月５ | AS41: 火５ | AT41: 水５ | AU41: 木５ | AV41: 金５ | AW41: 月５ | AX41: 火５ | AY41: 水５ | AZ41: 木５ | BA41: 金５ | BB41: 月５ | BC41: 火５ | BD41: 水５ | BE41: 木５ | BF41: 金５ | BG41: 月５ | BH41: 火５ | BI41: 水５ | BJ41: 木５ | BK41: 金５ | BL41: 月５ | BM41: 火５ | BN41: 水５ | BO41: 木５ | BP41: 金５
...

Sheet 年計から貼り付け
B1: ３ 月 | F1: 1行目 | G1: 会議 | H1: 貼り付け用データ
A2: 1 | B2: 3送会準備・リハ② | E2: {=INDEX($A:$A,ROW(A1)*2)} -> 1 | F2: {=INDEX($B:$B,ROW(A1)*2)&INDEX($B:$B,ROW(A1)*2+1)} -> 3送会準備・リハ② | G2: {=INDEX($C:$C,ROW(B1)*2)&INDEX($C:$C,ROW(B1)*2+1)} | H2: =IF(OR(F2="",G2="",TRIM(H1)=""),F2&G2,F2&"・"&G2) -> 3送会準備・リハ②
A3: 月 | E3: {=INDEX($A:$A,ROW(A1)*2+2)} -> 2 | F3: {=INDEX($B:$B,ROW(A2)*2)&" "&INDEX($B:$B,ROW(A2)*2+1)} -> 3年生を送る会 | G3: {=INDEX($C:$C,ROW(B2)*2)&INDEX($C:$C,ROW(B2)*2+1)} | H3: =IF(OR(F3="",G3="",TRIM(H2)=""),F3&G3,F3&"・"&G3) -> 3年生を送る会
A4: 2 | B4: 3年生を送る会 | E4: {=INDEX($A:$A,ROW(A2)*2+2)} -> 3 | F4: {=INDEX($B:$B,ROW(A3)*2)&" "&INDEX($B:$B,ROW(A3)*2+1)} | G4: {=INDEX($C:$C,ROW(B3)*2)&INDEX($C:$C,ROW(B3)*2+1)} | H4: =IF(OR(F4="",G4="",TRIM(H3)=""),F4&G4,F4&"・"&G4)
A5: 火 | E5: {=INDEX($A:$A,ROW(A3)*2+2)} -> 4 | F5: {=INDEX($B:$B,ROW(A4)*2)&" "&INDEX($B:$B,ROW(A4)*2+1)} -> 卒業式準備 | G5: {=INDEX($C:$C,ROW(B4)*2)&INDEX($C:$C,ROW(B4)*2+1)} | H5: =IF(OR(F5="",G5="",TRIM(H4)=""),F5&G5,F5&"・"&G5) -> 卒業式準備
A6: 3 | E6: {=INDEX($A:$A,ROW(A4)*2+2)} -> 5 | F6: {=INDEX($B:$B,ROW(A5)*2)&" "&INDEX($B:$B,ROW(A5)*2+1)} -> 卒業式 | G6: {=INDEX($C:$C,ROW(B5)*2)&INDEX($C:$C,ROW(B5)*2+1)} -> 定1･2年成績一覧表提出 | H6: =IF(OR(F6="",G6="",TRIM(H5)=""),F6&G6,F6&"・"&G6) -> 卒業式 ・定1･2年成績一覧表提出
A7: 水 | E7: {=INDEX($A:$A,ROW(A5)*2+2)} -> 6 | F7: {=INDEX($B:$B,ROW(A6)*2)&" "&INDEX($B:$B,ROW(A6)*2+1)} | G7: {=INDEX($C:$C,ROW(B6)*2)&INDEX($C:$C,ROW(B6)*2+1)} | H7: =IF(OR(F7="",G7="",TRIM(H6)=""),F7&G7,F7&"・"&G7)
A8: 4 | B8: 卒業式準備 | E8: {=INDEX($A:$A,ROW(A6)*2+2)} -> 7 | F8: {=INDEX($B:$B,ROW(A7)*2)&" "&INDEX($B:$B,ROW(A7)*2+1)} | G8: {=INDEX($C:$C,ROW(B7)*2)&INDEX($C:$C,ROW(B7)*2+1)} | H8: =IF(OR(F8="",G8="",TRIM(H7)=""),F8&G8,F8&"・"&G8)
A9: 木 | E9: {=INDEX($A:$A,ROW(A7)*2+2)} -> 8 | F9: {=INDEX($B:$B,ROW(A8)*2)&" "&INDEX($B:$B,ROW(A8)*2+1)} -> 【公立一般合格発表】 | G9: {=INDEX($C:$C,ROW(B8)*2)&INDEX($C:$C,ROW(B8)*2+1)} -> 進認職11 | H9: =IF(OR(F9="",G9="",TRIM(H8)=""),F9&G9,F9&"・"&G9) -> 【公立一般合格発表】進認職11
A10: 5 | B10: 卒業式 | C10: 定 | E10: {=INDEX($A:$A,ROW(A8)*2+2)} -> 9 | F10: {=INDEX($B:$B,ROW(A9)*2)&" "&INDEX($B:$B,ROW(A9)*2+1)} -> 選挙管理委員会 ▼小中連絡会(汐路) 1･2年通知表（本）提出 | G10: {=INDEX($C:$C,ROW(B9)*2)&INDEX($C:$C,ROW(B9)*2+1)} | H10: =IF(OR(F10="",G10="",TRIM(H9)=""),F10&G10,F10&"・"&G10) -> 選挙管理委員会 ▼小中連絡会(汐路) 1･2年通知表（本）提出
A11: 金 | C11: 1･2年成績一覧表提出 | E11: {=INDEX($A:$A,ROW(A9)*2+2)} -> 10 | F11: {=INDEX($B:$B,ROW(A10)*2)&" "&INDEX($B:$B,ROW(A10)*2+1)} | G11: {=INDEX($C:$C,ROW(B10)*2)&INDEX($C:$C,ROW(B10)*2+1)} -> ▼小中連絡会(陽明) | H11: =IF(OR(F11="",G11="",TRIM(H10)=""),F11&G11,F11&"・"&G11) -> ・▼小中連絡会(陽明)
A12: 6 | E12: {=INDEX($A:$A,ROW(A10)*2+2)} -> 11 | F12: {=INDEX($B:$B,ROW(A11)*2)&" "&INDEX($B:$B,ROW(A11)*2+1)} -> 学年保護者会(2年) 立候補者連絡会 | G12: {=INDEX($C:$C,ROW(B11)*2)&INDEX($C:$C,ROW(B11)*2+1)} -> 委 | H12: =IF(OR(F12="",G12="",TRIM(H11)=""),F12&G12,F12&"・"&G12) -> 学年保護者会(2年) 立候補者連絡会・委
A13: 土 | E13: {=INDEX($A:$A,ROW(A11)*2+2)} -> 12 | F13: {=INDEX($B:$B,ROW(A12)*2)&" "&INDEX($B:$B,ROW(A12)*2+1)} | G13: {=INDEX($C:$C,ROW(B12)*2)&INDEX($C:$C,ROW(B12)*2+1)} -> 編1 | H13: =IF(OR(F13="",G13="",TRIM(H12)=""),F13&G13,F13&"・"&G13) -> ・編1
A14: 7 | E14: {=INDEX($A:$A,ROW(A12)*2+2)} -> 13 | F14: {=INDEX($B:$B,ROW(A13)*2)&" "&INDEX($B:$B,ROW(A13)*2+1)} | G14: {=INDEX($C:$C,ROW(B13)*2)&INDEX($C:$C,ROW(B13)*2+1)} | H14: =IF(OR(F14="",G14="",TRIM(H13)=""),F14&G14,F14&"・"&G14)
A15: 日 | E15: {=INDEX($A:$A,ROW(A13)*2+2)} -> 14 | F15: {=INDEX($B:$B,ROW(A14)*2)&" "&INDEX($B:$B,ROW(A14)*2+1)} -> ノー部活デー | G15: {=INDEX($C:$C,ROW(B14)*2)&INDEX($C:$C,ROW(B14)*2+1)} | H15: =IF(OR(F15="",G15="",TRIM(H14)=""),F15&G15,F15&"・"&G15) -> ノー部活デー
A16: 8 | C16: 進認 | E16: {=INDEX($A:$A,ROW(A14)*2+2)} -> 15 | F16: {=INDEX($B:$B,ROW(A15)*2)&" "&INDEX($B:$B,ROW(A15)*2+1)} -> 立会演説会・選管 | G16: {=INDEX($C:$C,ROW(B15)*2)&INDEX($C:$C,ROW(B15)*2+1)} -> 1･2年通知表（本）提出 | H16: =IF(OR(F16="",G16="",TRIM(H15)=""),F16&G16,F16&"・"&G16) -> 立会演説会・選管 ・1･2年通知表（本）提出
A17: 月 | B17: 【公立一般合格発表】 | C17: 職11 | E17: {=INDEX($A:$A,ROW(A15)*2+2)} -> 16 | F17: {=INDEX($B:$B,ROW(A16)*2)&" "&INDEX($B:$B,ROW(A16)*2+1)} -> R7生徒会オリ(リハ) 【全日制･定時制２次選抜】 | G17: {=INDEX($C:$C,ROW(B16)*2)&INDEX($C:$C,ROW(B16)*2+1)} | H17: =IF(OR(F17="",G17="",TRIM(H16)=""),F17&G17,F17&"・"&G17) -> R7生徒会オリ(リハ) 【全日制･定時制２次選抜】
A18: 9 | B18: 選挙管理委員会 ▼小中連絡会(汐路) | E18: {=INDEX($A:$A,ROW(A16)*2+2)} -> 17 | F18: {=INDEX($B:$B,ROW(A17)*2)&" "&INDEX($B:$B,ROW(A17)*2+1)} -> 【全日制･定時制２次合格発表】 | G18: {=INDEX($C:$C,ROW(B17)*2)&INDEX($C:$C,ROW(B17)*2+1)} | H18: =IF(OR(F18="",G18="",TRIM(H17)=""),F18&G18,F18&"・"&G18) -> 【全日制･定時制２次合格発表】
A19: 火 | B19: 1･2年通知表（本）提出 | E19: {=INDEX($A:$A,ROW(A17)*2+2)} -> 18 | F19: {=INDEX($B:$B,ROW(A18)*2)&" "&INDEX($B:$B,ROW(A18)*2+1)} -> (小学校卒業式) | G19: {=INDEX($C:$C,ROW(B18)*2)&INDEX($C:$C,ROW(B18)*2+1)} -> 編2 | H19: =IF(OR(F19="",G19="",TRIM(H18)=""),F19&G19,F19&"・"&G19) -> (小学校卒業式)・編2
A20: 10 | E20: {=INDEX($A:$A,ROW(A18)*2+2)} -> 19 | F20: {=INDEX($B:$B,ROW(A19)*2)&" "&INDEX($B:$B,ROW(A19)*2+1)} | G20: {=INDEX($C:$C,ROW(B19)*2)&INDEX($C:$C,ROW(B19)*2+1)} -> 採 | H20: =IF(OR(F20="",G20="",TRIM(H19)=""),F20&G20,F20&"・"&G20) -> ・採
A21: 水 | C21: ▼小中連絡会(陽明) | E21: {=INDEX($A:$A,ROW(A19)*2+2)} -> 20 | F21: {=INDEX($B:$B,ROW(A20)*2)&" "&INDEX($B:$B,ROW(A20)*2+1)} | G21: {=INDEX($C:$C,ROW(B20)*2)&INDEX($C:$C,ROW(B20)*2+1)} | H21: =IF(OR(F21="",G21="",TRIM(H20)=""),F21&G21,F21&"・"&G21)
A22: 11 | B22: 学年保護者会(2年) | E22: {=INDEX($A:$A,ROW(A20)*2+2)} -> 21 | F22: {=INDEX($B:$B,ROW(A21)*2)&" "&INDEX($B:$B,ROW(A21)*2+1)} -> 春分の日 | G22: {=INDEX($C:$C,ROW(B21)*2)&INDEX($C:$C,ROW(B21)*2+1)} | H22: =IF(OR(F22="",G22="",TRIM(H21)=""),F22&G22,F22&"・"&G22) -> 春分の日
A23: 木 | B23: 立候補者連絡会 | C23: 委 | E23: {=INDEX($A:$A,ROW(A21)*2+2)} -> 22 | F23: {=INDEX($B:$B,ROW(A22)*2)&" "&INDEX($B:$B,ROW(A22)*2+1)} -> 日曜日祝日による休業日 | G23: {=INDEX($C:$C,ROW(B22)*2)&INDEX($C:$C,ROW(B22)*2+1)} | H23: =IF(OR(F23="",G23="",TRIM(H22)=""),F23&G23,F23&"・"&G23) -> 日曜日祝日による休業日
A24: 12 | C24: 編1 | E24: {=INDEX($A:$A,ROW(A22)*2+2)} -> 23 | F24: {=INDEX($B:$B,ROW(A23)*2)&" "&INDEX($B:$B,ROW(A23)*2+1)} -> 大掃除 【通信制後期入試】 | G24: {=INDEX($C:$C,ROW(B23)*2)&INDEX($C:$C,ROW(B23)*2+1)} | H24: =IF(OR(F24="",G24="",TRIM(H23)=""),F24&G24,F24&"・"&G24) -> 大掃除 【通信制後期入試】
A25: 金 | E25: {=INDEX($A:$A,ROW(A23)*2+2)} -> 24 | F25: {=INDEX($B:$B,ROW(A24)*2)&" "&INDEX($B:$B,ROW(A24)*2+1)} -> 修了式・離任式 【通信制後期合格発表】 | G25: {=INDEX($C:$C,ROW(B24)*2)&INDEX($C:$C,ROW(B24)*2+1)} | H25: =IF(OR(F25="",G25="",TRIM(H24)=""),F25&G25,F25&"・"&G25) -> 修了式・離任式 【通信制後期合格発表】
A26: 13 | E26: {=INDEX($A:$A,ROW(A24)*2+2)} -> 25 | F26: {=INDEX($B:$B,ROW(A25)*2)&" "&INDEX($B:$B,ROW(A25)*2+1)} -> 学年末休業開始 | G26: {=INDEX($C:$C,ROW(B25)*2)&INDEX($C:$C,ROW(B25)*2+1)} | H26: =IF(OR(F26="",G26="",TRIM(H25)=""),F26&G26,F26&"・"&G26) -> 学年末休業開始
A27: 土 | E27: {=INDEX($A:$A,ROW(A25)*2+2)} -> 26 | F27: {=INDEX($B:$B,ROW(A26)*2)&" "&INDEX($B:$B,ROW(A26)*2+1)} | G27: {=INDEX($C:$C,ROW(B26)*2)&INDEX($C:$C,ROW(B26)*2+1)} -> 旧運 | H27: =IF(OR(F27="",G27="",TRIM(H26)=""),F27&G27,F27&"・"&G27) -> ・旧運
A28: 14 | B28: ノー部活デー | E28: {=INDEX($A:$A,ROW(A26)*2+2)} -> 27 | F28: {=INDEX($B:$B,ROW(A27)*2)&" "&INDEX($B:$B,ROW(A27)*2+1)} | G28: {=INDEX($C:$C,ROW(B27)*2)&INDEX($C:$C,ROW(B27)*2+1)} | H28: =IF(OR(F28="",G28="",TRIM(H27)=""),F28&G28,F28&"・"&G28)
A29: 日 | E29: {=INDEX($A:$A,ROW(A27)*2+2)} -> 28 | F29: {=INDEX($B:$B,ROW(A28)*2)&" "&INDEX($B:$B,ROW(A28)*2+1)} | G29: {=INDEX($C:$C,ROW(B28)*2)&INDEX($C:$C,ROW(B28)*2+1)} | H29: =IF(OR(F29="",G29="",TRIM(H28)=""),F29&G29,F29&"・"&G29)
A30: 15 | B30: 立会演説会・選管 | E30: {=INDEX($A:$A,ROW(A28)*2+2)} -> 29 | F30: {=INDEX($B:$B,ROW(A29)*2)&" "&INDEX($B:$B,ROW(A29)*2+1)} | G30: {=INDEX($C:$C,ROW(B29)*2)&INDEX($C:$C,ROW(B29)*2+1)} | H30: =IF(OR(F30="",G30="",TRIM(H29)=""),F30&G30,F30&"・"&G30)
A31: 月 | C31: 1･2年通知表（本）提出 | E31: {=INDEX($A:$A,ROW(A29)*2+2)} -> 30 | F31: {=INDEX($B:$B,ROW(A30)*2)&" "&INDEX($B:$B,ROW(A30)*2+1)} | G31: {=INDEX($C:$C,ROW(B30)*2)&INDEX($C:$C,ROW(B30)*2+1)} | H31: =IF(OR(F31="",G31="",TRIM(H30)=""),F31&G31,F31&"・"&G31)
A32: 16 | B32: R7生徒会オリ(リハ) | E32: {=INDEX($A:$A,ROW(A30)*2+2)} -> 31 | F32: {=INDEX($B:$B,ROW(A31)*2)&" "&INDEX($B:$B,ROW(A31)*2+1)} | G32: {=INDEX($C:$C,ROW(B31)*2)&INDEX($C:$C,ROW(B31)*2+1)} | H32: =IF(OR(F32="",G32="",TRIM(H31)=""),F32&G32,F32&"・"&G32)
A33: 火 | B33: 【全日制･定時制２次選抜】 | G33: {=INDEX($C:$C,ROW(B32)*2)&INDEX($C:$C,ROW(B32)*2+1)} | H33: =IF(OR(F33="",G33="",TRIM(H32)=""),F33&G33,F33&"・"&G33)
A34: 17
A35: 水 | B35: 【全日制･定時制２次合格発表】
A36: 18 | C36: 編2
A37: 木 | B37: (小学校卒業式)
A38: 19 | C38: 採
A39: 金
A40: 20
...
