Workbook

Sheet 教科担任別一覧
A2: 1 | B2: 2 | C2: 3 | D2: 4 | E2: 5 | F2: 6 | G2: 7 | H2: 8 | I2: 9 | J2: 10 | K2: 11 | L2: 12 | M2: 13 | N2: 14 | O2: 15 | P2: 16 | Q2: 17 | R2: 18 | S2: 19 | T2: 20 | U2: 21 | V2: 22 | W2: 23 | X2: 24 | Y2: 25 | Z2: 26 | AA2: 27 | AB2: 28 | AC2: 29 | AD2: 30 | AE2: 31 | AF2: 32 | AG2: 33 | AH2: 34 | AI2: 35 | AJ2: 36 | AK2: 37
B3: 令和８年度 | E3: 教科担任別時間割（本時間割） | AD3: =TODAY() -> 46253 | AG3: ver
B5: 組 | D5: 月 | K5: 火 | R5: 水 | Y5: 木 | AF5: 金
D6: 1 | E6: 2 | F6: 3 | G6: 4 | H6: 5 | I6: 6 | K6: 1 | L6: 2 | M6: 3 | N6: 4 | O6: 5 | P6: 6 | R6: 1 | S6: 2 | T6: 3 | U6: 4 | V6: 5 | W6: 6 | Y6: 1 | Z6: 2 | AA6: 3 | AB6: 4 | AC6: 5 | AD6: 6 | AF6: 1 | AG6: 2 | AH6: 3 | AI6: 4 | AJ6: 5 | AK6: 6 | AL6: 担任名
A7: 1 | B7: 1A | C7: 柿家 | E7: 3A | F7: 主 | H7: 1A | I7: 道 | M7: 待機 | N7: 1B | O7: 3A | R7: 1A | T7: 1C | U7: 1B | W7: 学 | Y7: 3A | AA7: 生 | AB7: 1C | AC7: 1B | AF7: 1A | AI7: 3A | AJ7: 1C | AK7: 総 | AL7: =IF(C7="","",C7) -> 柿家 | CE7: =ASC(AR7)
A8: 2 | B8: 1B | C8: 石垣 | F8: 3E | G8: 3D | H8: 3A | I8: 道 | L8: 1FE | O8: 1C | P8: 1D | R8: 1DC | S8: 1BA | U8: 3B | V8: 3C | W8: 学 | Y8: 1A | AA8: 1B | AB8: 1E | AF8: 待機 | AG8: 待機 | AH8: 待機 | AJ8: 1F | AK8: 総 | AL8: =IF(C8="","",C8) -> 石垣
A9: 3 | B9: 1C | C9: 石飛 | D9: 1C | E9: 1F | F9: 主 | H9: 1B | I9: 道 | K9: 1F | M9: 1CT | O9: 1Dt | T9: 1BT | V9: 1C | W9: 学 | Y9: 1C | Z9: 1B | AA9: 1F | AF9: 1B | AG9: 1FT | AI9: 1At | AJ9: 1Et | AK9: 総 | AL9: =IF(C9="","",C9) -> 石飛
A10: 4 | B10: 1C | C10: 髙橋咲 | D10: 1A | F10: 1C | G10: 1E | I10: 道 | L10: IJ | M10: 1E | P10: 1C | R10: 1E | S10: 1C | T10: 1A | W10: 学 | Y10: IJ | Z10: 1C | AC10: 1A | AF10: 1E | AG10: 1A | AH10: 初 | AI10: 初 | AK10: 総 | AL10: =IF(C10="","",C10) -> 髙橋咲
A11: 5 | B11: 1D | C11: 馬場 | D11: 1E | F11: 1D | G11: 1F | I11: 道 | K11: 1D | N11: 1A | O11: 1F | P11: 1E | R11: 1F | S11: 1D | U11: 1A | V11: IJ | W11: 学 | Y11: 1D | Z11: 1A | AB11: 1F | AC11: 1E | AH11: 1E | AJ11: 1A | AK11: 総 | AL11: =IF(C11="","",C11) -> 馬場
A12: 6 | B12: 1E | C12: 谷口 | D12: IJ | E12: IJ | G12: 2E | H12: 2B | I12: 道 | K12: 1B | L12: 1A | N12: 3AB | O12: 3DE | R12: 待機 | T12: 1E | U12: 1F | W12: 学 | Y12: 2D | Z12: 2A | AA12: 2C | AC12: 3C | AF12: 1C | AG12: 1D | AI12: T2 | AK12: 総 | AL12: =IF(C12="","",C12) -> 谷口
A13: 7 | B13: 1F | C13: 西脇 | E13: 1CD | F13: 1EF | G13: 1AB | I13: 道 | K13: 3DE | L13: 3A | N13: 1CD | O13: 1AB | T13: 3A | U13: 3DE | V13: 1EF | W13: 学 | Y13: 待機 | Z13: 3DE | AA13: 生 | AC13: 1CD | AF13: 3A | AH13: 1AB | AI13: 1EF | AK13: 総 | AL13: =IF(C13="","",C13) -> 西脇
A14: 8 | C14: 安井 | E14: 1E | F14: 1A | H14: 1F | I14: 道 | L14: 1D | M14: 1A | N14: 1F | O14: 1E | P14: 1B | S14: 1F | T14: 1D | V14: 1B | AA14: 1E | AB14: 1A | AI14: 1B | AJ14: 1D | AK14: 総 | AL14: =IF(C14="","",C14) -> 安井
A15: 9 | C15: 浅田 | D15: 1B | E15: 1A | G15: 1D | H15: 1C | L15: 1EF | N15: 3C | O15: 3B | R15: 1CD | S15: 1AB | U15: 2E | V15: 2D | Y15: 1E | Z15: 1F | AB15: 3A | AC15: 2C | AG15: 2B | AH15: 2A | AI15: 3E | AJ15: 3D | AK15: 総 | AL15: =IF(C15="","",C15) -> 浅田
A16: 10 | C16: 渡邉 | D16: 1F | E16: 1B | F16: 主 | H16: 1D | K16: 3B | M16: 1D | P16: 1F | R16: 1B | T16: 3B | V16: 1D | Y16: 1B | Z16: 1D | AA16: 3B | AC16: 1F | AF16: 3B | AG16: 初 | AH16: 1F | AI16: 初 | AJ16: 1B | AK16: 総 | AL16: =IF(C16="","",C16) -> 渡邉
A17: 11 | C17: 高橋美 | E17: さくら | F17: さくら | G17: さくら | M17: 1Ct | N17: 1E | O17: 1DT | P17: 1A | S17: 1E | T17: 1Bt | U17: 1D | V17: 1A | Z17: 1E | AA17: 1A | AB17: 1D | AC17: IJ | AG17: 1Ft | AH17: 1D | AI17: 1AT | AJ17: 1ET | AL17: =IF(C17="","",C17) -> 高橋美
C18: 丹羽 | E18: 2B | F18: 1B | G18: 1C | H18: 2C | L18: 1C | M18: 1B | N18: 2D | O18: 2A | AA18: 1C | AB18: 1B | AG18: 1B | AI18: 1C | AJ18: 2E | AL18: =IF(C18="","",C18) -> 丹羽
A19: 12 | C19: 佐野 | D19: T2 | E19: T2 | F19: 主 | H19: 待機 | K19: 1C | M19: T2 | R19: T2 | U19: 1C | AA19: 生 | AB19: 待機 | AC19: 待機 | AF19: T2 | AH19: 1C | AL19: =IF(C19="","",C19) -> 佐野
AL20: =IF(C20="","",C20)
A21: 13 | B21: 2A | C21: 大島 | F21: 2E | G21: 2D | H21: 2A | I21: 道 | K21: 2C | N21: 2E | O21: 2B | P21: 総 | R21: 2D | S21: 2B | U21: 2C | V21: 2E | W21: 学 | Z21: 2D | AA21: 2A | AB21: IJ | AF21: 2C | AG21: 2A | AJ21: 2B | AK21: 総 | AL21: =IF(C21="","",C21) -> 大島
A22: 14 | B22: 2B | C22: 名倉 | D22: 1D | F22: 2A | G22: 2B | H22: 1E | I22: 道 | K22: 1E | M22: 1F | N22: 2B | P22: 総 | S22: 2A | T22: 2B | W22: 学 | Y22: 1F | Z22: 待機 | AA22: 1D | AF22: 1F | AG22: 1E | AI22: 1D | AJ22: 2A | AK22: 総 | AL22: =IF(C22="","",C22) -> 名倉
A23: 15 | B23: 2C | C23: 浅野 | D23: IJ | E23: IJ | G23: 2C | H23: 2D | I23: 道 | K23: 1A | L23: 1B | N23: 3AB | O23: 3DE | P23: 総 | T23: 1F | U23: 1E | V23: 2A | W23: 学 | Y23: 2E | Z23: 2B | AC23: 3C | AF23: 1D | AG23: 1C | AI23: 待機 | AK23: 総 | AL23: =IF(C23="","",C23) -> 浅野
A24: 16 | B24: 2C | C24: 酒井 | E24: 2D | F24: 2C | G24: IJ | I24: 道 | K24: 2E | L24: 2D | M24: 初 | N24: 初 | P24: 総 | R24: 2C | S24: 待機 | W24: 学 | Z24: 2C | AA24: IJ | AB24: 2E | AF24: 2D | AH24: 2E | AK24: 総 | AL24: =IF(C24="","",C24) -> 酒井
A25: 17 | B25: 2D | C25: 樽見 | D25: 2C | E25: 2E | F25: 2D | I25: 道 | K25: 2B | N25: 2C | O25: 2E | P25: 総 | R25: 2E | T25: 2D | U25: 2B | V25: 2C | W25: 学 | Z25: 2E | AA25: 2B | AC25: 2D | AG25: 2C | AH25: 2D | AI25: 2B | AK25: 総 | AL25: =IF(C25="","",C25) -> 樽見
A26: 18 | B26: 2E | C26: 髙田 | D26: 2E | E26: 2A | F26: 2B | H26: T2 | I26: 道 | K26: 2D | L26: 2E | N26: 2A | O26: 2C | P26: 総 | S26: 2C | T26: 2A | U26: 2D | W26: 学 | Y26: 2C | AC26: 2B | AF26: 2B | AG26: 2E | AI26: 2D | AK26: 総 | AL26: =IF(C26="","",C26) -> 髙田
A27: 19 | C27: 鈴木 | D27: 2AB | E27: 待機 | F27: 主 | H27: 3BC | I27: 道 | L27: 2C | M27: 2DE | P27: 総 | R27: 2AB | S27: 2DE | T27: 2C | Y27: 3BC | AA27: 2DE | AB27: 2AB | AG27: 3BC | AJ27: 2C | AK27: 総 | AL27: =IF(C27="","",C27) -> 鈴木
A28: 20 | C28: 藤井 | D28: 2D | E28: 2C | F28: 主 | H28: 2E | I28: 道 | K28: 2A | L28: 2B | M28: 2C | O28: 2D | P28: 総 | T28: 2E | U28: 2A | V28: 2B | Y28: 2B | AA28: 生 | AB28: 2D | AC28: 2A | AF28: 2E | AI28: 2C | AK28: 総 | AL28: =IF(C28="","",C28) -> 藤井
A29: 21 | C29: 長谷川麻 | E29: 1CD | F29: 1EF | G29: 1AB | L29: 2C | M29: 2DE | N29: 1CD | O29: 1AB | S29: 2DE | T29: 2C | U29: T2 | V29: 1EF | Z29: IJ | AA29: 2DE | AC29: 1CD | AG29: T2 | AH29: 1AB | AI29: 1EF | AJ29: 2C | AL29: =IF(C29="","",C29) -> 長谷川麻
A30: 22 | C30: 篠田 | L30: 2A | M30: 2B | N30: さくら | T30: さくら | AA30: さくら | AG30: 2D | AH30: 2C | AI30: 2E | AJ30: さくら | AL30: =IF(C30="","",C30) -> 篠田
A31: 23 | AL31: =IF(C31="","",C31)
A32: 24 | AL32: =IF(C32="","",C32)
AL33: =IF(C33="","",C33)
A34: 25 | B34: 3A | C34: 城 | E34: 3D | F34: 3C | G34: 3E | I34: 道 | L34: 3C | M34: 3A | N34: 3E | P34: 総 | R34: 3D | T34: 3C | V34: 3A | W34: 学 | AA34: 3A | AB34: 3E | AC34: 3D | AG34: 3D | AH34: 3A | AI34: 3C | AJ34: 3E | AK34: 総 | AL34: =IF(C34="","",C34) -> 城
A35: 26 | B35: 3B | C35: 幸島 | D35: 3C | E35: 3E | F35: 3B | H35: 3D | I35: 道 | K35: 3C | L35: 3E | M35: 3B | P35: 総 | R35: 3B | S35: 3D | V35: 3E | W35: 学 | AA35: 3C | AB35: 3D | AC35: 3B | AF35: 3E | AH35: 3C | AI35: 3D | AK35: 総 | AL35: =IF(C35="","",C35) -> 幸島
A36: 27 | B36: 3C | C36: 菅田 | D36: 3A | F36: 3D | G36: 3B | I36: 道 | L36: 3B | M36: 3C | N36: 3D | P36: 総 | R36: 3E | S36: 3A | U36: 3C | V36: 3D | W36: 学 | AA36: 生 | AB36: 3C | AC36: 3E | AG36: 3A | AH36: 3E | AJ36: 3B | AK36: 総 | AL36: =IF(C36="","",C36) -> 菅田
A37: 28 | B37: 3D | C37: 仲野 | D37: 3D | E37: 3B | F37: 3A | I37: 道 | K37: 待機 | M37: 3D | O37: 待機 | P37: 総 | R37: 3A | S37: 3B | T37: 待機 | W37: 学 | Z37: 3B | AA37: 3D | AC37: 3A | AG37: IJ | AH37: 3D | AI37: 3B | AJ37: 3A | AK37: 総 | AL37: =IF(C37="","",C37) -> 仲野
A38: 29 | B38: 3E | C38: 朝日 | D38: 3B | E38: 3C | G38: 2A | H38: 3E | I38: 道 | M38: 2A | O38: 3C | P38: 総 | R38: 3C | S38: 3E | V38: 3B | W38: 学 | Y38: 2A | AA38: 3E | AB38: 3B | AF38: 2A | AG38: 3E | AH38: 3B | AJ38: 3C | AK38: 総 | AL38: =IF(C38="","",C38) -> 朝日
A39: 30 | C39: 松田 | D39: 待機 | F39: 主 | G39: 3A | I39: 道 | K39: 3A | L39: 3D | N39: IJ | P39: 総 | T39: 3D | U39: 3A | Y39: 3D | Z39: 3A | AA39: 待機 | AF39: 3D | AH39: IJ | AJ39: 待機 | AK39: 総 | AL39: =IF(C39="","",C39) -> 松田
A40: 31 | C40: 長谷川俊 | D40: 3E | F40: 待機 | G40: 3C | I40: 道 | L40: 待機 | M40: 3E | N40: 待機 | P40: 総 | S40: 3C | T40: 3E | U40: 待機 | Y40: 3E | Z40: 3C | AB40: 2C | AC40: 2E | AF40: 3C | AH40: 2B | AI40: 2A | AJ40: 2D | AK40: 総 | AL40: =IF(C40="","",C40) -> 長谷川俊
A41: 32 | C41: 山田 | D41: 2AB | F41: IJ | G41: 待機 | H41: 3BC | I41: 道 | K41: 3DE | L41: 3A | O41: T2 | P41: 総 | R41: 2AB | T41: 3A | U41: 3DE | V41: 待機 | Y41: 3BC | Z41: 3DE | AB41: 2AB | AF41: 3A | AG41: 3BC | AJ41: IJ | AK41: 総 | AL41: =IF(C41="","",C41) -> 山田
A42: 33 | AL42: =IF(C42="","",C42)
...

Sheet クラス別一覧（入力）
A2: 1 | B2: 2 | C2: 3 | D2: 4 | E2: 5 | F2: 6 | G2: 7 | H2: 8 | I2: 9 | J2: 10 | K2: 11 | L2: 12 | M2: 13 | N2: 14 | O2: 15 | P2: 16 | Q2: 17 | R2: 18 | S2: 19 | T2: 20 | U2: 21 | V2: 22 | W2: 23 | X2: 24 | Y2: 25 | Z2: 26 | AA2: 27 | AB2: 28 | AC2: 29 | AD2: 30 | AE2: 31 | AF2: 32 | AG2: 33 | AH2: 34 | AI2: 35 | AJ2: 36
G3: クラス別時間割（本時間割） | AF3: =TODAY() -> 46253
B7: クラス | C7: 月 | J7: 火 | Q7: 水 | X7: 木 | AE7: 金 | AK7: クラス
C8: 1 | D8: 2 | E8: 3 | F8: 4 | G8: 5 | H8: 6 | J8: 1 | K8: 2 | L8: 3 | M8: 4 | N8: 5 | O8: 6 | Q8: 1 | R8: 2 | S8: 3 | T8: 4 | U8: 5 | V8: 6 | X8: 1 | Y8: 2 | Z8: 3 | AA8: 4 | AB8: 5 | AC8: 6 | AE8: 1 | AF8: 2 | AG8: 3 | AH8: 4 | AI8: 5 | AJ8: 6
A9: 1 | B9: 1A | C9: 数 | D9: 音 | E9: 理 | F9: 保体 | G9: 社 | H9: 道 | J9: 技 | K9: 家 | L9: 理 | M9: 国 | N9: 保体 | O9: 英 | Q9: 社 | R9: 音美 | S9: 数 | T9: 国 | U9: 英 | V9: 学 | X9: 美 | Y9: 国 | Z9: 英 | AA9: 理 | AB9: 数 | AE9: 社 | AF9: 数 | AG9: 保体 | AH9: 英 | AI9: 国 | AJ9: 総 | AK9: 1A
A10: 2 | B10: 1B | C10: 音 | D10: 数 | E10: 国 | F10: 保体 | G10: 英 | H10: 道 | J10: 家 | K10: 技 | L10: 国 | M10: 社 | N10: 保体 | O10: 理 | Q10: 数 | R10: 美音 | S10: 英 | T10: 社 | U10: 理 | V10: 学 | X10: 数 | Y10: 英 | Z10: 美 | AA10: 国 | AB10: 社 | AE10: 英 | AF10: 国 | AG10: 保体 | AH10: 理 | AI10: 数 | AJ10: 総 | AK10: 1B
A11: 3 | B11: 1C | C11: 英 | D11: 保体 | E11: 数 | F11: 国 | G11: 音 | H11: 道 | J11: 理 | K11: 国 | L11: 英 | M11: 保体 | N11: 美 | O11: 数 | Q11: 音美 | R11: 数 | S11: 社 | T11: 理 | U11: 英 | V11: 学 | X11: 英 | Y11: 数 | Z11: 国 | AA11: 社 | AB11: 保体 | AE11: 家 | AF11: 技 | AG11: 理 | AH11: 国 | AI11: 社 | AJ11: 総 | AK11: 1C
A12: 4 | B12: 1D | C12: 社 | D12: 保体 | E12: 国 | F12: 音 | G12: 数 | H12: 道 | J12: 国 | K12: 理 | L12: 数 | M12: 保体 | N12: 英 | O12: 美 | Q12: 美音 | R12: 国 | S12: 理 | T12: 英 | U12: 数 | V12: 学 | X12: 国 | Y12: 数 | Z12: 社 | AA12: 英 | AB12: 保体 | AE12: 技 | AF12: 家 | AG12: 英 | AH12: 社 | AI12: 理 | AJ12: 総 | AK12: 1D
A13: 5 | B13: 1E | C13: 国 | D13: 理 | E13: 保体 | F13: 数 | G13: 社 | H13: 道 | J13: 社 | K13: 音美 | L13: 数 | M13: 英 | N13: 理 | O13: 国 | Q13: 数 | R13: 英 | S13: 家 | T13: 技 | U13: 保体 | V13: 学 | X13: 音 | Y13: 英 | Z13: 理 | AA13: 美 | AB13: 国 | AE13: 数 | AF13: 社 | AG13: 国 | AH13: 保体 | AI13: 英 | AJ13: 総 | AK13: 1E
A14: 6 | B14: 1F | C14: 数 | D14: 英 | E14: 保体 | F14: 国 | G14: 理 | H14: 道 | J14: 英 | K14: 美音 | L14: 社 | M14: 理 | N14: 国 | O14: 数 | Q14: 国 | R14: 理 | S14: 技 | T14: 家 | U14: 保体 | V14: 学 | X14: 社 | Y14: 音 | Z14: 英 | AA14: 国 | AB14: 数 | AE14: 社 | AF14: 英 | AG14: 数 | AH14: 保体 | AI14: 美 | AJ14: 総 | AK14: 1F
A16: 7 | B16: 2A | C16: 保体 | D16: 数 | E16: 社 | F16: 理 | G16: 国Ⅰ | H16: 道 | J16: 英 | K16: 美 | L16: 理 | M16: 数 | N16: 国Ⅱ | O16: 総 | Q16: 保体 | R16: 社 | S16: 数 | T16: 英 | U16: 技 | V16: 学 | X16: 理 | Y16: 家 | Z16: 国Ⅰ | AA16: 保体 | AB16: 英 | AE16: 理 | AF16: 国Ⅰ | AG16: 音 | AH16: 英 | AI16: 社 | AJ16: 総 | AK16: 2A
A17: 8 | B17: 2B | C17: 保体 | D17: 国Ⅱ | E17: 数 | F17: 社 | G17: 家 | H17: 道 | J17: 理 | K17: 英 | L17: 美 | M17: 社 | N17: 国Ⅰ | O17: 総 | Q17: 保体 | R17: 国Ⅰ | S17: 社 | T17: 理 | U17: 英 | V17: 学 | X17: 英 | Y17: 技 | Z17: 理 | AA17: 保体 | AB17: 数 | AE17: 数 | AF17: 音 | AG17: 英 | AH17: 理 | AI17: 国Ⅰ | AJ17: 総 | AK17: 2B
A18: 9 | B18: 2C | C18: 理 | D18: 英 | E18: 社 | F18: 技 | G18: 国Ⅱ | H18: 道 | J18: 国Ⅰ | K18: 保体 | L18: 英 | M18: 理 | N18: 数 | O18: 総 | Q18: 社 | R18: 数 | S18: 保体 | T18: 国Ⅰ | U18: 理 | V18: 学 | X18: 数 | Y18: 社 | Z18: 家 | AA18: 英 | AB18: 音 | AE18: 国Ⅰ | AF18: 理 | AG18: 美 | AH18: 英 | AI18: 保体 | AJ18: 総 | AK18: 2C
A19: 10 | B19: 2D | C19: 英 | D19: 社 | E19: 理 | F19: 国Ⅰ | G19: 技 | H19: 道 | J19: 数 | K19: 社 | L19: 保体 | M19: 国Ⅱ | N19: 英 | O19: 総 | Q19: 国Ⅰ | R19: 保体 | S19: 理 | T19: 数 | U19: 音 | V19: 学 | X19: 家 | Y19: 国Ⅰ | Z19: 保体 | AA19: 英 | AB19: 理 | AE19: 社 | AF19: 美 | AG19: 理 | AH19: 数 | AI19: 英 | AJ19: 総 | AK19: 2D
A20: 11 | B20: 2E | C20: 数 | D20: 理 | E20: 国Ⅰ | F20: 家 | G20: 英 | H20: 道 | J20: 社 | K20: 数 | L20: 保体 | M20: 国Ⅰ | N20: 理 | O20: 総 | Q20: 理 | R20: 保体 | S20: 英 | T20: 音 | U20: 国Ⅰ | V20: 学 | X20: 技 | Y20: 理 | Z20: 保体 | AA20: 社 | AB20: 英 | AE20: 英 | AF20: 数 | AG20: 社 | AH20: 美 | AI20: 国Ⅱ | AJ20: 総 | AK20: 2E
B21: 2F | H21: 道 | V21: 学 | AK21: 2F
A23: 12 | B23: ３Ａ | C23: 国 | D23: 社 | E23: 英 | F23: 理 | G23: 美 | H23: 道 | J23: 理 | K23: 保体 | L23: 数 | M23: 技家 | N23: 社 | O23: 総 | Q23: 英 | R23: 国 | S23: 保体 | T23: 理 | U23: 数 | V23: 学 | X23: 社 | Y23: 理 | Z23: 数 | AA23: 音 | AB23: 英 | AE23: 保体 | AF23: 国 | AG23: 数 | AH23: 社 | AI23: 英 | AJ23: 総 | AK23: ３Ａ
A24: 13 | B24: ３Ｂ | C24: 理 | D24: 英 | E24: 社 | F24: 国 | G24: 保体 | H24: 道 | J24: 数 | K24: 国 | L24: 社 | M24: 技家 | N24: 音 | O24: 総 | Q24: 社 | R24: 英 | S24: 数 | T24: 美 | U24: 理 | V24: 学 | X24: 保体 | Y24: 英 | Z24: 数 | AA24: 理 | AB24: 社 | AE24: 数 | AF24: 保体 | AG24: 理 | AH24: 英 | AI24: 国 | AJ24: 総 | AK24: ３Ｂ
A25: 14 | B25: ３Ｃ | C25: 社 | D25: 理 | E25: 数 | F25: 英 | G25: 保体 | H25: 道 | J25: 社 | K25: 数 | L25: 国 | M25: 音 | N25: 理 | O25: 総 | Q25: 理 | R25: 英 | S25: 数 | T25: 国 | U25: 美 | V25: 学 | X25: 保体 | Y25: 英 | Z25: 社 | AA25: 国 | AB25: 技家 | AE25: 英 | AF25: 保体 | AG25: 社 | AH25: 数 | AI25: 理 | AJ25: 総 | AK25: ３Ｃ
A26: 15 | B26: ３D | C26: 英 | D26: 数 | E26: 国 | F26: 美 | G26: 社 | H26: 道 | J26: 保体 | K26: 理 | L26: 英 | M26: 国 | N26: 技家 | O26: 総 | Q26: 数 | R26: 社 | S26: 理 | T26: 保体 | U26: 国 | V26: 学 | X26: 理 | Y26: 保体 | Z26: 英 | AA26: 社 | AB26: 数 | AE26: 理 | AF26: 数 | AG26: 英 | AH26: 社 | AI26: 音 | AJ26: 総 | AK26: ３D
A27: 16 | B27: ３E | C27: 英 | D27: 社 | E27: 美 | F27: 数 | G27: 理 | H27: 道 | J27: 保体 | K27: 社 | L27: 英 | M27: 数 | N27: 技家 | O27: 総 | Q27: 国 | R27: 理 | S27: 英 | T27: 保体 | U27: 社 | V27: 学 | X27: 英 | Y27: 保体 | Z27: 理 | AA27: 数 | AB27: 国 | AE27: 社 | AF27: 理 | AG27: 国 | AH27: 音 | AI27: 数 | AJ27: 総 | AK27: ３E
A29: 17 | B29: Ｉ・Ｊ | C29: 技 | D29: 家 | E29: 保体 | F29: 社 | G29: 作 | H29: 道 | J29: 自 | K29: 数 | L29: 音 | M29: 理 | N29: 作 | O29: 総 | Q29: 自 | R29: 美 | S29: 美 | T29: 作 | U29: 国 | V29: 学 | X29: 数 | Y29: 保体 | Z29: 社 | AA29: 国 | AB29: 英 | AE29: 音 | AF29: 英 | AG29: 理 | AH29: 作 | AI29: 保体 | AJ29: 総 | AK29: Ｉ・Ｊ

Sheet 一覧
C2: =#REF! -> #REF! | G2: 時間割表 （本時間割） | S2: 名古屋市立汐路中学校 | AC2: 45413
E4: 月 | K4: 火 | Q4: 水 | W4: 木 | AB4: 金
E5: 1 | F5: 2 | G5: 3 | H5: 4 | I5: 5 | J5: 6 | K5: 1 | L5: 2 | M5: 3 | N5: 4 | O5: 5 | P5: 6 | Q5: 1 | R5: 2 | S5: 3 | T5: 4 | U5: 5 | V5: 6 | W5: 1 | X5: 2 | Y5: 3 | Z5: 4 | AA5: 5 | AB5: 1 | AC5: 2 | AD5: 3 | AE5: 4 | AF5: 5 | AG5: 6
C6: ='クラス別一覧（入力）'!B9 -> 1A | E6: ='クラス別一覧（入力）'!C9 -> 数 | F6: ='クラス別一覧（入力）'!D9 -> 音 | G6: ='クラス別一覧（入力）'!E9 -> 理 | H6: ='クラス別一覧（入力）'!F9 -> 保体 | I6: ='クラス別一覧（入力）'!G9 -> 社 | J6: ='クラス別一覧（入力）'!H9 -> 道 | K6: ='クラス別一覧（入力）'!J9 -> 技 | L6: ='クラス別一覧（入力）'!K9 -> 家 | M6: ='クラス別一覧（入力）'!L9 -> 理 | N6: ='クラス別一覧（入力）'!M9 -> 国 | O6: ='クラス別一覧（入力）'!N9 -> 保体 | P6: ='クラス別一覧（入力）'!O9 -> 英 | Q6: ='クラス別一覧（入力）'!Q9 -> 社 | R6: ='クラス別一覧（入力）'!R9 -> 音美 | S6: ='クラス別一覧（入力）'!S9 -> 数 | T6: ='クラス別一覧（入力）'!T9 -> 国 | U6: ='クラス別一覧（入力）'!U9 -> 英 | V6: ='クラス別一覧（入力）'!V9 -> 学 | W6: ='クラス別一覧（入力）'!X9 -> 美 | X6: ='クラス別一覧（入力）'!Y9 -> 国 | Y6: ='クラス別一覧（入力）'!Z9 -> 英 | Z6: ='クラス別一覧（入力）'!AA9 -> 理 | AA6: ='クラス別一覧（入力）'!AB9 -> 数 | AB6: ='クラス別一覧（入力）'!AE9 -> 社 | AC6: ='クラス別一覧（入力）'!AF9 -> 数 | AD6: ='クラス別一覧（入力）'!AG9 -> 保体 | AE6: ='クラス別一覧（入力）'!AH9 -> 英 | AF6: ='クラス別一覧（入力）'!AI9 -> 国 | AG6: ='クラス別一覧（入力）'!AJ9 -> 総
C7: ='クラス別一覧（入力）'!B10 -> 1B | E7: ='クラス別一覧（入力）'!C10 -> 音 | F7: ='クラス別一覧（入力）'!D10 -> 数 | G7: ='クラス別一覧（入力）'!E10 -> 国 | H7: ='クラス別一覧（入力）'!F10 -> 保体 | I7: ='クラス別一覧（入力）'!G10 -> 英 | J7: ='クラス別一覧（入力）'!H10 -> 道 | K7: ='クラス別一覧（入力）'!J10 -> 家 | L7: ='クラス別一覧（入力）'!K10 -> 技 | M7: ='クラス別一覧（入力）'!L10 -> 国 | N7: ='クラス別一覧（入力）'!M10 -> 社 | O7: ='クラス別一覧（入力）'!N10 -> 保体 | P7: ='クラス別一覧（入力）'!O10 -> 理 | Q7: ='クラス別一覧（入力）'!Q10 -> 数 | R7: ='クラス別一覧（入力）'!R10 -> 美音 | S7: ='クラス別一覧（入力）'!S10 -> 英 | T7: ='クラス別一覧（入力）'!T10 -> 社 | U7: ='クラス別一覧（入力）'!U10 -> 理 | V7: ='クラス別一覧（入力）'!V10 -> 学 | W7: ='クラス別一覧（入力）'!X10 -> 数 | X7: ='クラス別一覧（入力）'!Y10 -> 英 | Y7: ='クラス別一覧（入力）'!Z10 -> 美 | Z7: ='クラス別一覧（入力）'!AA10 -> 国 | AA7: ='クラス別一覧（入力）'!AB10 -> 社 | AB7: ='クラス別一覧（入力）'!AE10 -> 英 | AC7: ='クラス別一覧（入力）'!AF10 -> 国 | AD7: ='クラス別一覧（入力）'!AG10 -> 保体 | AE7: ='クラス別一覧（入力）'!AH10 -> 理 | AF7: ='クラス別一覧（入力）'!AI10 -> 数 | AG7: ='クラス別一覧（入力）'!AJ10 -> 総
C8: ='クラス別一覧（入力）'!B11 -> 1C | E8: ='クラス別一覧（入力）'!C11 -> 英 | F8: ='クラス別一覧（入力）'!D11 -> 保体 | G8: ='クラス別一覧（入力）'!E11 -> 数 | H8: ='クラス別一覧（入力）'!F11 -> 国 | I8: ='クラス別一覧（入力）'!G11 -> 音 | J8: ='クラス別一覧（入力）'!H11 -> 道 | K8: ='クラス別一覧（入力）'!J11 -> 理 | L8: ='クラス別一覧（入力）'!K11 -> 国 | M8: ='クラス別一覧（入力）'!L11 -> 英 | N8: ='クラス別一覧（入力）'!M11 -> 保体 | O8: ='クラス別一覧（入力）'!N11 -> 美 | P8: ='クラス別一覧（入力）'!O11 -> 数 | Q8: ='クラス別一覧（入力）'!Q11 -> 音美 | R8: ='クラス別一覧（入力）'!R11 -> 数 | S8: ='クラス別一覧（入力）'!S11 -> 社 | T8: ='クラス別一覧（入力）'!T11 -> 理 | U8: ='クラス別一覧（入力）'!U11 -> 英 | V8: ='クラス別一覧（入力）'!V11 -> 学 | W8: ='クラス別一覧（入力）'!X11 -> 英 | X8: ='クラス別一覧（入力）'!Y11 -> 数 | Y8: ='クラス別一覧（入力）'!Z11 -> 国 | Z8: ='クラス別一覧（入力）'!AA11 -> 社 | AA8: ='クラス別一覧（入力）'!AB11 -> 保体 | AB8: ='クラス別一覧（入力）'!AE11 -> 家 | AC8: ='クラス別一覧（入力）'!AF11 -> 技 | AD8: ='クラス別一覧（入力）'!AG11 -> 理 | AE8: ='クラス別一覧（入力）'!AH11 -> 国 | AF8: ='クラス別一覧（入力）'!AI11 -> 社 | AG8: ='クラス別一覧（入力）'!AJ11 -> 総
C9: ='クラス別一覧（入力）'!B12 -> 1D | E9: ='クラス別一覧（入力）'!C12 -> 社 | F9: ='クラス別一覧（入力）'!D12 -> 保体 | G9: ='クラス別一覧（入力）'!E12 -> 国 | H9: ='クラス別一覧（入力）'!F12 -> 音 | I9: ='クラス別一覧（入力）'!G12 -> 数 | J9: ='クラス別一覧（入力）'!H12 -> 道 | K9: ='クラス別一覧（入力）'!J12 -> 国 | L9: ='クラス別一覧（入力）'!K12 -> 理 | M9: ='クラス別一覧（入力）'!L12 -> 数 | N9: ='クラス別一覧（入力）'!M12 -> 保体 | O9: ='クラス別一覧（入力）'!N12 -> 英 | P9: ='クラス別一覧（入力）'!O12 -> 美 | Q9: ='クラス別一覧（入力）'!Q12 -> 美音 | R9: ='クラス別一覧（入力）'!R12 -> 国 | S9: ='クラス別一覧（入力）'!S12 -> 理 | T9: ='クラス別一覧（入力）'!T12 -> 英 | U9: ='クラス別一覧（入力）'!U12 -> 数 | V9: ='クラス別一覧（入力）'!V12 -> 学 | W9: ='クラス別一覧（入力）'!X12 -> 国 | X9: ='クラス別一覧（入力）'!Y12 -> 数 | Y9: ='クラス別一覧（入力）'!Z12 -> 社 | Z9: ='クラス別一覧（入力）'!AA12 -> 英 | AA9: ='クラス別一覧（入力）'!AB12 -> 保体 | AB9: ='クラス別一覧（入力）'!AE12 -> 技 | AC9: ='クラス別一覧（入力）'!AF12 -> 家 | AD9: ='クラス別一覧（入力）'!AG12 -> 英 | AE9: ='クラス別一覧（入力）'!AH12 -> 社 | AF9: ='クラス別一覧（入力）'!AI12 -> 理 | AG9: ='クラス別一覧（入力）'!AJ12 -> 総
C10: ='クラス別一覧（入力）'!B13 -> 1E | E10: ='クラス別一覧（入力）'!C13 -> 国 | F10: ='クラス別一覧（入力）'!D13 -> 理 | G10: ='クラス別一覧（入力）'!E13 -> 保体 | H10: ='クラス別一覧（入力）'!F13 -> 数 | I10: ='クラス別一覧（入力）'!G13 -> 社 | J10: ='クラス別一覧（入力）'!H13 -> 道 | K10: ='クラス別一覧（入力）'!J13 -> 社 | L10: ='クラス別一覧（入力）'!K13 -> 音美 | M10: ='クラス別一覧（入力）'!L13 -> 数 | N10: ='クラス別一覧（入力）'!M13 -> 英 | O10: ='クラス別一覧（入力）'!N13 -> 理 | P10: ='クラス別一覧（入力）'!O13 -> 国 | Q10: ='クラス別一覧（入力）'!Q13 -> 数 | R10: ='クラス別一覧（入力）'!R13 -> 英 | S10: ='クラス別一覧（入力）'!S13 -> 家 | T10: ='クラス別一覧（入力）'!T13 -> 技 | U10: ='クラス別一覧（入力）'!U13 -> 保体 | V10: ='クラス別一覧（入力）'!V13 -> 学 | W10: ='クラス別一覧（入力）'!X13 -> 音 | X10: ='クラス別一覧（入力）'!Y13 -> 英 | Y10: ='クラス別一覧（入力）'!Z13 -> 理 | Z10: ='クラス別一覧（入力）'!AA13 -> 美 | AA10: ='クラス別一覧（入力）'!AB13 -> 国 | AB10: ='クラス別一覧（入力）'!AE13 -> 数 | AC10: ='クラス別一覧（入力）'!AF13 -> 社 | AD10: ='クラス別一覧（入力）'!AG13 -> 国 | AE10: ='クラス別一覧（入力）'!AH13 -> 保体 | AF10: ='クラス別一覧（入力）'!AI13 -> 英 | AG10: ='クラス別一覧（入力）'!AJ13 -> 総
C11: ='クラス別一覧（入力）'!B14 -> 1F | E11: ='クラス別一覧（入力）'!C14 -> 数 | F11: ='クラス別一覧（入力）'!D14 -> 英 | G11: ='クラス別一覧（入力）'!E14 -> 保体 | H11: ='クラス別一覧（入力）'!F14 -> 国 | I11: ='クラス別一覧（入力）'!G14 -> 理 | J11: ='クラス別一覧（入力）'!H14 -> 道 | K11: ='クラス別一覧（入力）'!J14 -> 英 | L11: ='クラス別一覧（入力）'!K14 -> 美音 | M11: ='クラス別一覧（入力）'!L14 -> 社 | N11: ='クラス別一覧（入力）'!M14 -> 理 | O11: ='クラス別一覧（入力）'!N14 -> 国 | P11: ='クラス別一覧（入力）'!O14 -> 数 | Q11: ='クラス別一覧（入力）'!Q14 -> 国 | R11: ='クラス別一覧（入力）'!R14 -> 理 | S11: ='クラス別一覧（入力）'!S14 -> 技 | T11: ='クラス別一覧（入力）'!T14 -> 家 | U11: ='クラス別一覧（入力）'!U14 -> 保体 | V11: ='クラス別一覧（入力）'!V14 -> 学 | W11: ='クラス別一覧（入力）'!X14 -> 社 | X11: ='クラス別一覧（入力）'!Y14 -> 音 | Y11: ='クラス別一覧（入力）'!Z14 -> 英 | Z11: ='クラス別一覧（入力）'!AA14 -> 国 | AA11: ='クラス別一覧（入力）'!AB14 -> 数 | AB11: ='クラス別一覧（入力）'!AE14 -> 社 | AC11: ='クラス別一覧（入力）'!AF14 -> 英 | AD11: ='クラス別一覧（入力）'!AG14 -> 数 | AE11: ='クラス別一覧（入力）'!AH14 -> 保体 | AF11: ='クラス別一覧（入力）'!AI14 -> 美 | AG11: ='クラス別一覧（入力）'!AJ14 -> 総
C12: ='クラス別一覧（入力）'!B16 -> 2A | E12: ='クラス別一覧（入力）'!C16 -> 保体 | F12: ='クラス別一覧（入力）'!D16 -> 数 | G12: ='クラス別一覧（入力）'!E16 -> 社 | H12: ='クラス別一覧（入力）'!F16 -> 理 | I12: ='クラス別一覧（入力）'!G16 -> 国Ⅰ | J12: ='クラス別一覧（入力）'!H16 -> 道 | K12: ='クラス別一覧（入力）'!J16 -> 英 | L12: ='クラス別一覧（入力）'!K16 -> 美 | M12: ='クラス別一覧（入力）'!L16 -> 理 | N12: ='クラス別一覧（入力）'!M16 -> 数 | O12: ='クラス別一覧（入力）'!N16 -> 国Ⅱ | P12: ='クラス別一覧（入力）'!O16 -> 総 | Q12: ='クラス別一覧（入力）'!Q16 -> 保体 | R12: ='クラス別一覧（入力）'!R16 -> 社 | S12: ='クラス別一覧（入力）'!S16 -> 数 | T12: ='クラス別一覧（入力）'!T16 -> 英 | U12: ='クラス別一覧（入力）'!U16 -> 技 | V12: ='クラス別一覧（入力）'!V16 -> 学 | W12: ='クラス別一覧（入力）'!X16 -> 理 | X12: ='クラス別一覧（入力）'!Y16 -> 家 | Y12: ='クラス別一覧（入力）'!Z16 -> 国Ⅰ | Z12: ='クラス別一覧（入力）'!AA16 -> 保体 | AA12: ='クラス別一覧（入力）'!AB16 -> 英 | AB12: ='クラス別一覧（入力）'!AE16 -> 理 | AC12: ='クラス別一覧（入力）'!AF16 -> 国Ⅰ | AD12: ='クラス別一覧（入力）'!AG16 -> 音 | AE12: ='クラス別一覧（入力）'!AH16 -> 英 | AF12: ='クラス別一覧（入力）'!AI16 -> 社 | AG12: ='クラス別一覧（入力）'!AJ16 -> 総
C13: ='クラス別一覧（入力）'!B17 -> 2B | E13: ='クラス別一覧（入力）'!C17 -> 保体 | F13: ='クラス別一覧（入力）'!D17 -> 国Ⅱ | G13: ='クラス別一覧（入力）'!E17 -> 数 | H13: ='クラス別一覧（入力）'!F17 -> 社 | I13: ='クラス別一覧（入力）'!G17 -> 家 | J13: ='クラス別一覧（入力）'!H17 -> 道 | K13: ='クラス別一覧（入力）'!J17 -> 理 | L13: ='クラス別一覧（入力）'!K17 -> 英 | M13: ='クラス別一覧（入力）'!L17 -> 美 | N13: ='クラス別一覧（入力）'!M17 -> 社 | O13: ='クラス別一覧（入力）'!N17 -> 国Ⅰ | P13: ='クラス別一覧（入力）'!O17 -> 総 | Q13: ='クラス別一覧（入力）'!Q17 -> 保体 | R13: ='クラス別一覧（入力）'!R17 -> 国Ⅰ | S13: ='クラス別一覧（入力）'!S17 -> 社 | T13: ='クラス別一覧（入力）'!T17 -> 理 | U13: ='クラス別一覧（入力）'!U17 -> 英 | V13: ='クラス別一覧（入力）'!V17 -> 学 | W13: ='クラス別一覧（入力）'!X17 -> 英 | X13: ='クラス別一覧（入力）'!Y17 -> 技 | Y13: ='クラス別一覧（入力）'!Z17 -> 理 | Z13: ='クラス別一覧（入力）'!AA17 -> 保体 | AA13: ='クラス別一覧（入力）'!AB17 -> 数 | AB13: ='クラス別一覧（入力）'!AE17 -> 数 | AC13: ='クラス別一覧（入力）'!AF17 -> 音 | AD13: ='クラス別一覧（入力）'!AG17 -> 英 | AE13: ='クラス別一覧（入力）'!AH17 -> 理 | AF13: ='クラス別一覧（入力）'!AI17 -> 国Ⅰ | AG13: ='クラス別一覧（入力）'!AJ17 -> 総
C14: ='クラス別一覧（入力）'!B18 -> 2C | E14: ='クラス別一覧（入力）'!C18 -> 理 | F14: ='クラス別一覧（入力）'!D18 -> 英 | G14: ='クラス別一覧（入力）'!E18 -> 社 | H14: ='クラス別一覧（入力）'!F18 -> 技 | I14: ='クラス別一覧（入力）'!G18 -> 国Ⅱ | J14: ='クラス別一覧（入力）'!H18 -> 道 | K14: ='クラス別一覧（入力）'!J18 -> 国Ⅰ | L14: ='クラス別一覧（入力）'!K18 -> 保体 | M14: ='クラス別一覧（入力）'!L18 -> 英 | N14: ='クラス別一覧（入力）'!M18 -> 理 | O14: ='クラス別一覧（入力）'!N18 -> 数 | P14: ='クラス別一覧（入力）'!O18 -> 総 | Q14: ='クラス別一覧（入力）'!Q18 -> 社 | R14: ='クラス別一覧（入力）'!R18 -> 数 | S14: ='クラス別一覧（入力）'!S18 -> 保体 | T14: ='クラス別一覧（入力）'!T18 -> 国Ⅰ | U14: ='クラス別一覧（入力）'!U18 -> 理 | V14: ='クラス別一覧（入力）'!V18 -> 学 | W14: ='クラス別一覧（入力）'!X18 -> 数 | X14: ='クラス別一覧（入力）'!Y18 -> 社 | Y14: ='クラス別一覧（入力）'!Z18 -> 家 | Z14: ='クラス別一覧（入力）'!AA18 -> 英 | AA14: ='クラス別一覧（入力）'!AB18 -> 音 | AB14: ='クラス別一覧（入力）'!AE18 -> 国Ⅰ | AC14: ='クラス別一覧（入力）'!AF18 -> 理 | AD14: ='クラス別一覧（入力）'!AG18 -> 美 | AE14: ='クラス別一覧（入力）'!AH18 -> 英 | AF14: ='クラス別一覧（入力）'!AI18 -> 保体 | AG14: ='クラス別一覧（入力）'!AJ18 -> 総
C15: ='クラス別一覧（入力）'!B19 -> 2D | E15: ='クラス別一覧（入力）'!C19 -> 英 | F15: ='クラス別一覧（入力）'!D19 -> 社 | G15: ='クラス別一覧（入力）'!E19 -> 理 | H15: ='クラス別一覧（入力）'!F19 -> 国Ⅰ | I15: ='クラス別一覧（入力）'!G19 -> 技 | J15: ='クラス別一覧（入力）'!H19 -> 道 | K15: ='クラス別一覧（入力）'!J19 -> 数 | L15: ='クラス別一覧（入力）'!K19 -> 社 | M15: ='クラス別一覧（入力）'!L19 -> 保体 | N15: ='クラス別一覧（入力）'!M19 -> 国Ⅱ | O15: ='クラス別一覧（入力）'!N19 -> 英 | P15: ='クラス別一覧（入力）'!O19 -> 総 | Q15: ='クラス別一覧（入力）'!Q19 -> 国Ⅰ | R15: ='クラス別一覧（入力）'!R19 -> 保体 | S15: ='クラス別一覧（入力）'!S19 -> 理 | T15: ='クラス別一覧（入力）'!T19 -> 数 | U15: ='クラス別一覧（入力）'!U19 -> 音 | V15: ='クラス別一覧（入力）'!V19 -> 学 | W15: ='クラス別一覧（入力）'!X19 -> 家 | X15: ='クラス別一覧（入力）'!Y19 -> 国Ⅰ | Y15: ='クラス別一覧（入力）'!Z19 -> 保体 | Z15: ='クラス別一覧（入力）'!AA19 -> 英 | AA15: ='クラス別一覧（入力）'!AB19 -> 理 | AB15: ='クラス別一覧（入力）'!AE19 -> 社 | AC15: ='クラス別一覧（入力）'!AF19 -> 美 | AD15: ='クラス別一覧（入力）'!AG19 -> 理 | AE15: ='クラス別一覧（入力）'!AH19 -> 数 | AF15: ='クラス別一覧（入力）'!AI19 -> 英 | AG15: ='クラス別一覧（入力）'!AJ19 -> 総
C16: ='クラス別一覧（入力）'!B20 -> 2E | E16: ='クラス別一覧（入力）'!C20 -> 数 | F16: ='クラス別一覧（入力）'!D20 -> 理 | G16: ='クラス別一覧（入力）'!E20 -> 国Ⅰ | H16: ='クラス別一覧（入力）'!F20 -> 家 | I16: ='クラス別一覧（入力）'!G20 -> 英 | J16: ='クラス別一覧（入力）'!H20 -> 道 | K16: ='クラス別一覧（入力）'!J20 -> 社 | L16: ='クラス別一覧（入力）'!K20 -> 数 | M16: ='クラス別一覧（入力）'!L20 -> 保体 | N16: ='クラス別一覧（入力）'!M20 -> 国Ⅰ | O16: ='クラス別一覧（入力）'!N20 -> 理 | P16: ='クラス別一覧（入力）'!O20 -> 総 | Q16: ='クラス別一覧（入力）'!Q20 -> 理 | R16: ='クラス別一覧（入力）'!R20 -> 保体 | S16: ='クラス別一覧（入力）'!S20 -> 英 | T16: ='クラス別一覧（入力）'!T20 -> 音 | U16: ='クラス別一覧（入力）'!U20 -> 国Ⅰ | V16: ='クラス別一覧（入力）'!V20 -> 学 | W16: ='クラス別一覧（入力）'!X20 -> 技 | X16: ='クラス別一覧（入力）'!Y20 -> 理 | Y16: ='クラス別一覧（入力）'!Z20 -> 保体 | Z16: ='クラス別一覧（入力）'!AA20 -> 社 | AA16: ='クラス別一覧（入力）'!AB20 -> 英 | AB16: ='クラス別一覧（入力）'!AE20 -> 英 | AC16: ='クラス別一覧（入力）'!AF20 -> 数 | AD16: ='クラス別一覧（入力）'!AG20 -> 社 | AE16: ='クラス別一覧（入力）'!AH20 -> 美 | AF16: ='クラス別一覧（入力）'!AI20 -> 国Ⅱ | AG16: ='クラス別一覧（入力）'!AJ20 -> 総
C17: ='クラス別一覧（入力）'!B21 -> 2F | E17: ='クラス別一覧（入力）'!C21 -> 0 | F17: ='クラス別一覧（入力）'!D21 -> 0 | G17: ='クラス別一覧（入力）'!E21 -> 0 | H17: ='クラス別一覧（入力）'!F21 -> 0 | I17: ='クラス別一覧（入力）'!G21 -> 0 | J17: ='クラス別一覧（入力）'!H21 -> 道 | K17: ='クラス別一覧（入力）'!J21 -> 0 | L17: ='クラス別一覧（入力）'!K21 -> 0 | M17: ='クラス別一覧（入力）'!L21 -> 0 | N17: ='クラス別一覧（入力）'!M21 -> 0 | O17: ='クラス別一覧（入力）'!N21 -> 0 | P17: ='クラス別一覧（入力）'!O21 -> 0 | Q17: ='クラス別一覧（入力）'!Q21 -> 0 | R17: ='クラス別一覧（入力）'!R21 -> 0 | S17: ='クラス別一覧（入力）'!S21 -> 0 | T17: ='クラス別一覧（入力）'!T21 -> 0 | U17: ='クラス別一覧（入力）'!U21 -> 0 | V17: ='クラス別一覧（入力）'!V21 -> 学 | W17: ='クラス別一覧（入力）'!X21 -> 0 | X17: ='クラス別一覧（入力）'!Y21 -> 0 | Y17: ='クラス別一覧（入力）'!Z21 -> 0 | Z17: ='クラス別一覧（入力）'!AA21 -> 0 | AA17: ='クラス別一覧（入力）'!AB21 -> 0 | AB17: ='クラス別一覧（入力）'!AE21 -> 0 | AC17: ='クラス別一覧（入力）'!AF21 -> 0 | AD17: ='クラス別一覧（入力）'!AG21 -> 0 | AE17: ='クラス別一覧（入力）'!AH21 -> 0 | AF17: ='クラス別一覧（入力）'!AI21 -> 0 | AG17: ='クラス別一覧（入力）'!AJ21 -> 0
C18: ='クラス別一覧（入力）'!B23 -> ３Ａ | E18: ='クラス別一覧（入力）'!C23 -> 国 | F18: ='クラス別一覧（入力）'!D23 -> 社 | G18: ='クラス別一覧（入力）'!E23 -> 英 | H18: ='クラス別一覧（入力）'!F23 -> 理 | I18: ='クラス別一覧（入力）'!G23 -> 美 | J18: ='クラス別一覧（入力）'!H23 -> 道 | K18: ='クラス別一覧（入力）'!J23 -> 理 | L18: ='クラス別一覧（入力）'!K23 -> 保体 | M18: ='クラス別一覧（入力）'!L23 -> 数 | N18: ='クラス別一覧（入力）'!M23 -> 技家 | O18: ='クラス別一覧（入力）'!N23 -> 社 | P18: ='クラス別一覧（入力）'!O23 -> 総 | Q18: ='クラス別一覧（入力）'!Q23 -> 英 | R18: ='クラス別一覧（入力）'!R23 -> 国 | S18: ='クラス別一覧（入力）'!S23 -> 保体 | T18: ='クラス別一覧（入力）'!T23 -> 理 | U18: ='クラス別一覧（入力）'!U23 -> 数 | V18: ='クラス別一覧（入力）'!V23 -> 学 | W18: ='クラス別一覧（入力）'!X23 -> 社 | X18: ='クラス別一覧（入力）'!Y23 -> 理 | Y18: ='クラス別一覧（入力）'!Z23 -> 数 | Z18: ='クラス別一覧（入力）'!AA23 -> 音 | AA18: ='クラス別一覧（入力）'!AB23 -> 英 | AB18: ='クラス別一覧（入力）'!AE23 -> 保体 | AC18: ='クラス別一覧（入力）'!AF23 -> 国 | AD18: ='クラス別一覧（入力）'!AG23 -> 数 | AE18: ='クラス別一覧（入力）'!AH23 -> 社 | AF18: ='クラス別一覧（入力）'!AI23 -> 英 | AG18: ='クラス別一覧（入力）'!AJ23 -> 総
C19: ='クラス別一覧（入力）'!B24 -> ３Ｂ | E19: ='クラス別一覧（入力）'!C24 -> 理 | F19: ='クラス別一覧（入力）'!D24 -> 英 | G19: ='クラス別一覧（入力）'!E24 -> 社 | H19: ='クラス別一覧（入力）'!F24 -> 国 | I19: ='クラス別一覧（入力）'!G24 -> 保体 | J19: ='クラス別一覧（入力）'!H24 -> 道 | K19: ='クラス別一覧（入力）'!J24 -> 数 | L19: ='クラス別一覧（入力）'!K24 -> 国 | M19: ='クラス別一覧（入力）'!L24 -> 社 | N19: ='クラス別一覧（入力）'!M24 -> 技家 | O19: ='クラス別一覧（入力）'!N24 -> 音 | P19: ='クラス別一覧（入力）'!O24 -> 総 | Q19: ='クラス別一覧（入力）'!Q24 -> 社 | R19: ='クラス別一覧（入力）'!R24 -> 英 | S19: ='クラス別一覧（入力）'!S24 -> 数 | T19: ='クラス別一覧（入力）'!T24 -> 美 | U19: ='クラス別一覧（入力）'!U24 -> 理 | V19: ='クラス別一覧（入力）'!V24 -> 学 | W19: ='クラス別一覧（入力）'!X24 -> 保体 | X19: ='クラス別一覧（入力）'!Y24 -> 英 | Y19: ='クラス別一覧（入力）'!Z24 -> 数 | Z19: ='クラス別一覧（入力）'!AA24 -> 理 | AA19: ='クラス別一覧（入力）'!AB24 -> 社 | AB19: ='クラス別一覧（入力）'!AE24 -> 数 | AC19: ='クラス別一覧（入力）'!AF24 -> 保体 | AD19: ='クラス別一覧（入力）'!AG24 -> 理 | AE19: ='クラス別一覧（入力）'!AH24 -> 英 | AF19: ='クラス別一覧（入力）'!AI24 -> 国 | AG19: ='クラス別一覧（入力）'!AJ24 -> 総
C20: ='クラス別一覧（入力）'!B25 -> ３Ｃ | E20: ='クラス別一覧（入力）'!C25 -> 社 | F20: ='クラス別一覧（入力）'!D25 -> 理 | G20: ='クラス別一覧（入力）'!E25 -> 数 | H20: ='クラス別一覧（入力）'!F25 -> 英 | I20: ='クラス別一覧（入力）'!G25 -> 保体 | J20: ='クラス別一覧（入力）'!H25 -> 道 | K20: ='クラス別一覧（入力）'!J25 -> 社 | L20: ='クラス別一覧（入力）'!K25 -> 数 | M20: ='クラス別一覧（入力）'!L25 -> 国 | N20: ='クラス別一覧（入力）'!M25 -> 音 | O20: ='クラス別一覧（入力）'!N25 -> 理 | P20: ='クラス別一覧（入力）'!O25 -> 総 | Q20: ='クラス別一覧（入力）'!Q25 -> 理 | R20: ='クラス別一覧（入力）'!R25 -> 英 | S20: ='クラス別一覧（入力）'!S25 -> 数 | T20: ='クラス別一覧（入力）'!T25 -> 国 | U20: ='クラス別一覧（入力）'!U25 -> 美 | V20: ='クラス別一覧（入力）'!V25 -> 学 | W20: ='クラス別一覧（入力）'!X25 -> 保体 | X20: ='クラス別一覧（入力）'!Y25 -> 英 | Y20: ='クラス別一覧（入力）'!Z25 -> 社 | Z20: ='クラス別一覧（入力）'!AA25 -> 国 | AA20: ='クラス別一覧（入力）'!AB25 -> 技家 | AB20: ='クラス別一覧（入力）'!AE25 -> 英 | AC20: ='クラス別一覧（入力）'!AF25 -> 保体 | AD20: ='クラス別一覧（入力）'!AG25 -> 社 | AE20: ='クラス別一覧（入力）'!AH25 -> 数 | AF20: ='クラス別一覧（入力）'!AI25 -> 理 | AG20: ='クラス別一覧（入力）'!AJ25 -> 総
C21: ='クラス別一覧（入力）'!B26 -> ３D | E21: ='クラス別一覧（入力）'!C26 -> 英 | F21: ='クラス別一覧（入力）'!D26 -> 数 | G21: ='クラス別一覧（入力）'!E26 -> 国 | H21: ='クラス別一覧（入力）'!F26 -> 美 | I21: ='クラス別一覧（入力）'!G26 -> 社 | J21: ='クラス別一覧（入力）'!H26 -> 道 | K21: ='クラス別一覧（入力）'!J26 -> 保体 | L21: ='クラス別一覧（入力）'!K26 -> 理 | M21: ='クラス別一覧（入力）'!L26 -> 英 | N21: ='クラス別一覧（入力）'!M26 -> 国 | O21: ='クラス別一覧（入力）'!N26 -> 技家 | P21: ='クラス別一覧（入力）'!O26 -> 総 | Q21: ='クラス別一覧（入力）'!Q26 -> 数 | R21: ='クラス別一覧（入力）'!R26 -> 社 | S21: ='クラス別一覧（入力）'!S26 -> 理 | T21: ='クラス別一覧（入力）'!T26 -> 保体 | U21: ='クラス別一覧（入力）'!U26 -> 国 | V21: ='クラス別一覧（入力）'!V26 -> 学 | W21: ='クラス別一覧（入力）'!X26 -> 理 | X21: ='クラス別一覧（入力）'!Y26 -> 保体 | Y21: ='クラス別一覧（入力）'!Z26 -> 英 | Z21: ='クラス別一覧（入力）'!AA26 -> 社 | AA21: ='クラス別一覧（入力）'!AB26 -> 数 | AB21: ='クラス別一覧（入力）'!AE26 -> 理 | AC21: ='クラス別一覧（入力）'!AF26 -> 数 | AD21: ='クラス別一覧（入力）'!AG26 -> 英 | AE21: ='クラス別一覧（入力）'!AH26 -> 社 | AF21: ='クラス別一覧（入力）'!AI26 -> 音 | AG21: ='クラス別一覧（入力）'!AJ26 -> 総
C22: ='クラス別一覧（入力）'!B27 -> ３E | E22: ='クラス別一覧（入力）'!C27 -> 英 | F22: ='クラス別一覧（入力）'!D27 -> 社 | G22: ='クラス別一覧（入力）'!E27 -> 美 | H22: ='クラス別一覧（入力）'!F27 -> 数 | I22: ='クラス別一覧（入力）'!G27 -> 理 | J22: ='クラス別一覧（入力）'!H27 -> 道 | K22: ='クラス別一覧（入力）'!J27 -> 保体 | L22: ='クラス別一覧（入力）'!K27 -> 社 | M22: ='クラス別一覧（入力）'!L27 -> 英 | N22: ='クラス別一覧（入力）'!M27 -> 数 | O22: ='クラス別一覧（入力）'!N27 -> 技家 | P22: ='クラス別一覧（入力）'!O27 -> 総 | Q22: ='クラス別一覧（入力）'!Q27 -> 国 | R22: ='クラス別一覧（入力）'!R27 -> 理 | S22: ='クラス別一覧（入力）'!S27 -> 英 | T22: ='クラス別一覧（入力）'!T27 -> 保体 | U22: ='クラス別一覧（入力）'!U27 -> 社 | V22: ='クラス別一覧（入力）'!V27 -> 学 | W22: ='クラス別一覧（入力）'!X27 -> 英 | X22: ='クラス別一覧（入力）'!Y27 -> 保体 | Y22: ='クラス別一覧（入力）'!Z27 -> 理 | Z22: ='クラス別一覧（入力）'!AA27 -> 数 | AA22: ='クラス別一覧（入力）'!AB27 -> 国 | AB22: ='クラス別一覧（入力）'!AE27 -> 社 | AC22: ='クラス別一覧（入力）'!AF27 -> 理 | AD22: ='クラス別一覧（入力）'!AG27 -> 国 | AE22: ='クラス別一覧（入力）'!AH27 -> 音 | AF22: ='クラス別一覧（入力）'!AI27 -> 数 | AG22: ='クラス別一覧（入力）'!AJ27 -> 総
C23: ='クラス別一覧（入力）'!B29 -> Ｉ・Ｊ | E23: ='クラス別一覧（入力）'!C29 -> 技 | F23: ='クラス別一覧（入力）'!D29 -> 家 | G23: ='クラス別一覧（入力）'!E29 -> 保体 | H23: ='クラス別一覧（入力）'!F29 -> 社 | I23: ='クラス別一覧（入力）'!G29 -> 作 | J23: ='クラス別一覧（入力）'!H29 -> 道 | K23: ='クラス別一覧（入力）'!J29 -> 自 | L23: ='クラス別一覧（入力）'!K29 -> 数 | M23: ='クラス別一覧（入力）'!L29 -> 音 | N23: ='クラス別一覧（入力）'!M29 -> 理 | O23: ='クラス別一覧（入力）'!N29 -> 作 | P23: ='クラス別一覧（入力）'!O29 -> 総 | Q23: ='クラス別一覧（入力）'!Q29 -> 自 | R23: ='クラス別一覧（入力）'!R29 -> 美 | S23: ='クラス別一覧（入力）'!S29 -> 美 | T23: ='クラス別一覧（入力）'!T29 -> 作 | U23: ='クラス別一覧（入力）'!U29 -> 国 | V23: ='クラス別一覧（入力）'!V29 -> 学 | W23: ='クラス別一覧（入力）'!X29 -> 数 | X23: ='クラス別一覧（入力）'!Y29 -> 保体 | Y23: ='クラス別一覧（入力）'!Z29 -> 社 | Z23: ='クラス別一覧（入力）'!AA29 -> 国 | AA23: ='クラス別一覧（入力）'!AB29 -> 英 | AB23: ='クラス別一覧（入力）'!AE29 -> 音 | AC23: ='クラス別一覧（入力）'!AF29 -> 英 | AD23: ='クラス別一覧（入力）'!AG29 -> 理 | AE23: ='クラス別一覧（入力）'!AH29 -> 作 | AF23: ='クラス別一覧（入力）'!AI29 -> 保体 | AG23: ='クラス別一覧（入力）'!AJ29 -> 総
E25: 月 | K25: 火 | Q25: 水 | W25: 木 | AB25: 金
E26: 1 | F26: 2 | G26: 3 | H26: 4 | I26: 5 | J26: 6 | K26: 1 | L26: 2 | M26: 3 | N26: 4 | O26: 5 | P26: 6 | Q26: 1 | R26: 2 | S26: 3 | T26: 4 | U26: 5 | V26: 6 | W26: 1 | X26: 2 | Y26: 3 | Z26: 4 | AA26: 5 | AB26: 1 | AC26: 2 | AD26: 3 | AE26: 4 | AF26: 5 | AG26: 6
C27: =Sheet1!B7 -> 1A | D27: =Sheet1!C7 -> 柿家 | E27: =Sheet1!D7 -> 0 | F27: =Sheet1!E7 -> 3A | G27: =Sheet1!F7 -> 主 | H27: =Sheet1!G7 -> 0 | I27: =Sheet1!H7 -> 1A | J27: =Sheet1!I7 -> 道 | K27: =Sheet1!K7 -> 0 | L27: =Sheet1!L7 -> 待機 | M27: =Sheet1!M7 -> 3A | N27: =Sheet1!N7 -> 0 | O27: =Sheet1!O7 -> 0 | P27: =Sheet1!P7 -> 1B | Q27: =Sheet1!R7 -> 1A | R27: =Sheet1!S7 -> 0 | S27: =Sheet1!T7 -> 1C | T27: =Sheet1!U7 -> 0 | U27: =Sheet1!V7 -> 1B | V27: =Sheet1!W7 -> 学 | W27: =Sheet1!Y7 -> 1B | X27: =Sheet1!Z7 -> 0 | Y27: =Sheet1!AA7 -> 生 | Z27: =Sheet1!AB7 -> 1C | AA27: =Sheet1!AC7 -> 3A | AB27: =Sheet1!AF7 -> 1A | AC27: =Sheet1!AG7 -> 0 | AD27: =Sheet1!AH7 -> 0 | AE27: =Sheet1!AI7 -> 3A | AF27: =Sheet1!AJ7 -> 1C | AG27: =Sheet1!AK7 -> 総
C28: =Sheet1!B8 -> 1B | D28: =Sheet1!C8 -> 石垣 | E28: =Sheet1!D8 -> 0 | F28: =Sheet1!E8 -> 0 | G28: =Sheet1!F8 -> 3E | H28: =Sheet1!G8 -> 3D | I28: =Sheet1!H8 -> 3A | J28: =Sheet1!I8 -> 道 | K28: =Sheet1!K8 -> 0 | L28: =Sheet1!L8 -> 1FE | M28: =Sheet1!M8 -> 0 | N28: =Sheet1!N8 -> 0 | O28: =Sheet1!O8 -> 1C | P28: =Sheet1!P8 -> 1D | Q28: =Sheet1!R8 -> 1DC | R28: =Sheet1!S8 -> 1BA | S28: =Sheet1!T8 -> 0 | T28: =Sheet1!U8 -> 3B | U28: =Sheet1!V8 -> 3C | V28: =Sheet1!W8 -> 学 | W28: =Sheet1!Y8 -> 0 | X28: =Sheet1!Z8 -> 1A | Y28: =Sheet1!AA8 -> 1B | Z28: =Sheet1!AB8 -> 1E | AA28: =Sheet1!AC8 -> 0 | AB28: =Sheet1!AF8 -> 待機 | AC28: =Sheet1!AG8 -> 待機 | AD28: =Sheet1!AH8 -> 待機 | AE28: =Sheet1!AI8 -> 0 | AF28: =Sheet1!AJ8 -> 1F | AG28: =Sheet1!AK8 -> 総
C29: =Sheet1!B9 -> 1C | D29: =Sheet1!C9 -> 石飛 | E29: =Sheet1!D9 -> 1C | F29: =Sheet1!E9 -> 1F | G29: =Sheet1!F9 -> 主 | H29: =Sheet1!G9 -> 0 | I29: =Sheet1!H9 -> 1B | J29: =Sheet1!I9 -> 道 | K29: =Sheet1!K9 -> 1F | L29: =Sheet1!L9 -> 0 | M29: =Sheet1!M9 -> 1CT | N29: =Sheet1!N9 -> 0 | O29: =Sheet1!O9 -> 1Dt | P29: =Sheet1!P9 -> 0 | Q29: =Sheet1!R9 -> 0 | R29: =Sheet1!S9 -> 0 | S29: =Sheet1!T9 -> 1BT | T29: =Sheet1!U9 -> 1C | U29: =Sheet1!V9 -> 0 | V29: =Sheet1!W9 -> 学 | W29: =Sheet1!Y9 -> 1C | X29: =Sheet1!Z9 -> 1B | Y29: =Sheet1!AA9 -> 1F | Z29: =Sheet1!AB9 -> 0 | AA29: =Sheet1!AC9 -> 0 | AB29: =Sheet1!AF9 -> 1B | AC29: =Sheet1!AG9 -> 1FT | AD29: =Sheet1!AH9 -> 0 | AE29: =Sheet1!AI9 -> 1At | AF29: =Sheet1!AJ9 -> 1Et | AG29: =Sheet1!AK9 -> 総
C30: =Sheet1!B10 -> 1C | D30: =Sheet1!C10 -> 高橋咲 | E30: =Sheet1!D10 -> 1A | F30: =Sheet1!E10 -> 0 | G30: =Sheet1!F10 -> 1C | H30: =Sheet1!G10 -> 0 | I30: =Sheet1!H10 -> 1E | J30: =Sheet1!I10 -> 道 | K30: =Sheet1!K10 -> 0 | L30: =Sheet1!L10 -> IJ | M30: =Sheet1!M10 -> 1E | N30: =Sheet1!N10 -> 0 | O30: =Sheet1!O10 -> 0 | P30: =Sheet1!P10 -> 1C | Q30: =Sheet1!R10 -> 1E | R30: =Sheet1!S10 -> 1C | S30: =Sheet1!T10 -> 1A | T30: =Sheet1!U10 -> 0 | U30: =Sheet1!V10 -> 0 | V30: =Sheet1!W10 -> 学 | W30: =Sheet1!Y10 -> IJ | X30: =Sheet1!Z10 -> 1C | Y30: =Sheet1!AA10 -> 0 | Z30: =Sheet1!AB10 -> 0 | AA30: =Sheet1!AC10 -> 1A | AB30: =Sheet1!AF10 -> 1E | AC30: =Sheet1!AG10 -> 1A | AD30: =Sheet1!AH10 -> 初 | AE30: =Sheet1!AI10 -> 初 | AF30: =Sheet1!AJ10 -> 0 | AG30: =Sheet1!AK10 -> 総
C31: =Sheet1!B11 -> 1D | D31: =Sheet1!C11 -> 馬場 | E31: =Sheet1!D11 -> 1F | F31: =Sheet1!E11 -> 0 | G31: =Sheet1!F11 -> 1D | H31: =Sheet1!G11 -> 1E | I31: =Sheet1!H11 -> 0 | J31: =Sheet1!I11 -> 道 | K31: =Sheet1!K11 -> 1D | L31: =Sheet1!L11 -> 0 | M31: =Sheet1!M11 -> 1F | N31: =Sheet1!N11 -> 1A | O31: =Sheet1!O11 -> 0 | P31: =Sheet1!P11 -> 1E | Q31: =Sheet1!R11 -> 1F | R31: =Sheet1!S11 -> 1D | S31: =Sheet1!T11 -> 0 | T31: =Sheet1!U11 -> 1A | U31: =Sheet1!V11 -> IJ | V31: =Sheet1!W11 -> 学 | W31: =Sheet1!Y11 -> 1A | X31: =Sheet1!Z11 -> 0 | Y31: =Sheet1!AA11 -> 1D | Z31: =Sheet1!AB11 -> 1F | AA31: =Sheet1!AC11 -> 1E | AB31: =Sheet1!AF11 -> 0 | AC31: =Sheet1!AG11 -> 0 | AD31: =Sheet1!AH11 -> 1E | AE31: =Sheet1!AI11 -> 0 | AF31: =Sheet1!AJ11 -> 1A | AG31: =Sheet1!AK11 -> 総
C32: =Sheet1!B12 -> 1E | D32: =Sheet1!C12 -> 谷口 | E32: =Sheet1!D12 -> IJ | F32: =Sheet1!E12 -> IJ | G32: =Sheet1!F12 -> 0 | H32: =Sheet1!G12 -> 2E | I32: =Sheet1!H12 -> 2B | J32: =Sheet1!I12 -> 道 | K32: =Sheet1!K12 -> 1B | L32: =Sheet1!L12 -> 1A | M32: =Sheet1!M12 -> 0 | N32: =Sheet1!N12 -> 3AB | O32: =Sheet1!O12 -> 3DE | P32: =Sheet1!P12 -> 0 | Q32: =Sheet1!R12 -> 待機 | R32: =Sheet1!S12 -> 0 | S32: =Sheet1!T12 -> 1E | T32: =Sheet1!U12 -> 1F | U32: =Sheet1!V12 -> 0 | V32: =Sheet1!W12 -> 学 | W32: =Sheet1!Y12 -> 2D | X32: =Sheet1!Z12 -> 2A | Y32: =Sheet1!AA12 -> 2C | Z32: =Sheet1!AB12 -> 0 | AA32: =Sheet1!AC12 -> 3C | AB32: =Sheet1!AF12 -> 1C | AC32: =Sheet1!AG12 -> 1D | AD32: =Sheet1!AH12 -> 0 | AE32: =Sheet1!AI12 -> T2 | AF32: =Sheet1!AJ12 -> 0 | AG32: =Sheet1!AK12 -> 総
C33: =Sheet1!B13 -> 1F | D33: =Sheet1!C13 -> 西脇 | E33: =Sheet1!D13 -> 0 | F33: =Sheet1!E13 -> 1CD | G33: =Sheet1!F13 -> 1EF | H33: =Sheet1!G13 -> 1AB | I33: =Sheet1!H13 -> 0 | J33: =Sheet1!I13 -> 道 | K33: =Sheet1!K13 -> 3DE | L33: =Sheet1!L13 -> 3A | M33: =Sheet1!M13 -> 0 | N33: =Sheet1!N13 -> 1CD | O33: =Sheet1!O13 -> 1AB | P33: =Sheet1!P13 -> 0 | Q33: =Sheet1!R13 -> 0 | R33: =Sheet1!S13 -> 0 | S33: =Sheet1!T13 -> 3A | T33: =Sheet1!U13 -> 3DE | U33: =Sheet1!V13 -> 1EF | V33: =Sheet1!W13 -> 学 | W33: =Sheet1!Y13 -> 待機 | X33: =Sheet1!Z13 -> 3DE | Y33: =Sheet1!AA13 -> 生 | Z33: =Sheet1!AB13 -> 0 | AA33: =Sheet1!AC13 -> 1CD | AB33: =Sheet1!AF13 -> 3A | AC33: =Sheet1!AG13 -> 0 | AD33: =Sheet1!AH13 -> 1AB | AE33: =Sheet1!AI13 -> 1EF | AF33: =Sheet1!AJ13 -> 0 | AG33: =Sheet1!AK13 -> 総
C34: =Sheet1!B14 -> 0 | D34: =Sheet1!C14 -> 安井 | E34: =Sheet1!D14 -> 0 | F34: =Sheet1!E14 -> 1E | G34: =Sheet1!F14 -> 1A | H34: =Sheet1!G14 -> 0 | I34: =Sheet1!H14 -> 1F | J34: =Sheet1!I14 -> 道 | K34: =Sheet1!K14 -> 0 | L34: =Sheet1!L14 -> 1D | M34: =Sheet1!M14 -> 1A | N34: =Sheet1!N14 -> 1B | O34: =Sheet1!O14 -> 1E | P34: =Sheet1!P14 -> 1F | Q34: =Sheet1!R14 -> 0 | R34: =Sheet1!S14 -> 1F | S34: =Sheet1!T14 -> 1D | T34: =Sheet1!U14 -> 1B | U34: =Sheet1!V14 -> 0 | V34: =Sheet1!W14 -> 0 | W34: =Sheet1!Y14 -> 0 | X34: =Sheet1!Z14 -> 0 | Y34: =Sheet1!AA14 -> 1E | Z34: =Sheet1!AB14 -> 1A | AA34: =Sheet1!AC14 -> 0 | AB34: =Sheet1!AF14 -> 0 | AC34: =Sheet1!AG14 -> 0 | AD34: =Sheet1!AH14 -> 0 | AE34: =Sheet1!AI14 -> 1B | AF34: =Sheet1!AJ14 -> 1D | AG34: =Sheet1!AK14 -> 総
C35: =Sheet1!B15 -> 0 | D35: =Sheet1!C15 -> 浅田 | E35: =Sheet1!D15 -> 1B | F35: =Sheet1!E15 -> 1A | G35: =Sheet1!F15 -> 0 | H35: =Sheet1!G15 -> 1D | I35: =Sheet1!H15 -> 1C | J35: =Sheet1!I15 -> 0 | K35: =Sheet1!K15 -> 0 | L35: =Sheet1!L15 -> 1EF | M35: =Sheet1!M15 -> 0 | N35: =Sheet1!N15 -> 3C | O35: =Sheet1!O15 -> 3B | P35: =Sheet1!P15 -> 0 | Q35: =Sheet1!R15 -> 1CD | R35: =Sheet1!S15 -> 1AB | S35: =Sheet1!T15 -> 0 | T35: =Sheet1!U15 -> 2E | U35: =Sheet1!V15 -> 2D | V35: =Sheet1!W15 -> 0 | W35: =Sheet1!Y15 -> 1E | X35: =Sheet1!Z15 -> 1F | Y35: =Sheet1!AA15 -> 0 | Z35: =Sheet1!AB15 -> 3A | AA35: =Sheet1!AC15 -> 2C | AB35: =Sheet1!AF15 -> 0 | AC35: =Sheet1!AG15 -> 2B | AD35: =Sheet1!AH15 -> 2A | AE35: =Sheet1!AI15 -> 3E | AF35: =Sheet1!AJ15 -> 3D | AG35: =Sheet1!AK15 -> 0
C36: =Sheet1!B16 -> 0 | D36: =Sheet1!C16 -> 渡邉 | E36: =Sheet1!D16 -> 1D | F36: =Sheet1!E16 -> 1B | G36: =Sheet1!F16 -> 主 | H36: =Sheet1!G16 -> 1F | I36: =Sheet1!H16 -> 0 | J36: =Sheet1!I16 -> 0 | K36: =Sheet1!K16 -> 3B | L36: =Sheet1!L16 -> 0 | M36: =Sheet1!M16 -> 1D | N36: =Sheet1!N16 -> 1F | O36: =Sheet1!O16 -> 0 | P36: =Sheet1!P16 -> 0 | Q36: =Sheet1!R16 -> 1B | R36: =Sheet1!S16 -> 0 | S36: =Sheet1!T16 -> 3B | T36: =Sheet1!U16 -> 0 | U36: =Sheet1!V16 -> 1D | V36: =Sheet1!W16 -> 0 | W36: =Sheet1!Y16 -> 1F | X36: =Sheet1!Z16 -> 1D | Y36: =Sheet1!AA16 -> 3B | Z36: =Sheet1!AB16 -> 0 | AA36: =Sheet1!AC16 -> 1B | AB36: =Sheet1!AF16 -> 3B | AC36: =Sheet1!AG16 -> 初 | AD36: =Sheet1!AH16 -> 1F | AE36: =Sheet1!AI16 -> 初 | AF36: =Sheet1!AJ16 -> 1B | AG36: =Sheet1!AK16 -> 0
C37: =Sheet1!B21 -> 2A | D37: =Sheet1!C21 -> 大島 | E37: =Sheet1!D21 -> 0 | F37: =Sheet1!E21 -> 0 | G37: =Sheet1!F21 -> 2E | H37: =Sheet1!G21 -> 2D | I37: =Sheet1!H21 -> 2A | J37: =Sheet1!I21 -> 道 | K37: =Sheet1!K21 -> 2C | L37: =Sheet1!L21 -> 0 | M37: =Sheet1!M21 -> 0 | N37: =Sheet1!N21 -> 2E | O37: =Sheet1!O21 -> 2B | P37: =Sheet1!P21 -> 総 | Q37: =Sheet1!R21 -> 2D | R37: =Sheet1!S21 -> 2B | S37: =Sheet1!T21 -> 0 | T37: =Sheet1!U21 -> 2C | U37: =Sheet1!V21 -> 2E | V37: =Sheet1!W21 -> 学 | W37: =Sheet1!Y21 -> 0 | X37: =Sheet1!Z21 -> 2D | Y37: =Sheet1!AA21 -> 2A | Z37: =Sheet1!AB21 -> IJ | AA37: =Sheet1!AC21 -> 0 | AB37: =Sheet1!AF21 -> 2C | AC37: =Sheet1!AG21 -> 2A | AD37: =Sheet1!AH21 -> 0 | AE37: =Sheet1!AI21 -> 0 | AF37: =Sheet1!AJ21 -> 2B | AG37: =Sheet1!AK21 -> 総
C38: =Sheet1!B22 -> 2B | D38: =Sheet1!C22 -> 名倉 | E38: =Sheet1!D22 -> 1E | F38: =Sheet1!E22 -> 0 | G38: =Sheet1!F22 -> 2A | H38: =Sheet1!G22 -> 2B | I38: =Sheet1!H22 -> 1D | J38: =Sheet1!I22 -> 道 | K38: =Sheet1!K22 -> 1E | L38: =Sheet1!L22 -> 0 | M38: =Sheet1!M22 -> 0 | N38: =Sheet1!N22 -> 2B | O38: =Sheet1!O22 -> 1F | P38: =Sheet1!P22 -> 総 | Q38: =Sheet1!R22 -> 0 | R38: =Sheet1!S22 -> 2A | S38: =Sheet1!T22 -> 2B | T38: =Sheet1!U22 -> 0 | U38: =Sheet1!V22 -> 0 | V38: =Sheet1!W22 -> 学 | W38: =Sheet1!Y22 -> 1D | X38: =Sheet1!Z22 -> 待機 | Y38: =Sheet1!AA22 -> 0 | Z38: =Sheet1!AB22 -> 0 | AA38: =Sheet1!AC22 -> 1F | AB38: =Sheet1!AF22 -> 1F | AC38: =Sheet1!AG22 -> 1E | AD38: =Sheet1!AH22 -> 0 | AE38: =Sheet1!AI22 -> 1D | AF38: =Sheet1!AJ22 -> 2A | AG38: =Sheet1!AK22 -> 総
C39: =Sheet1!B23 -> 2C | D39: =Sheet1!C23 -> 浅野 | E39: =Sheet1!D23 -> IJ | F39: =Sheet1!E23 -> IJ | G39: =Sheet1!F23 -> 0 | H39: =Sheet1!G23 -> 2C | I39: =Sheet1!H23 -> 2D | J39: =Sheet1!I23 -> 道 | K39: =Sheet1!K23 -> 1A | L39: =Sheet1!L23 -> 1B | M39: =Sheet1!M23 -> 0 | N39: =Sheet1!N23 -> 3AB | O39: =Sheet1!O23 -> 3DE | P39: =Sheet1!P23 -> 総 | Q39: =Sheet1!R23 -> 0 | R39: =Sheet1!S23 -> 0 | S39: =Sheet1!T23 -> 1F | T39: =Sheet1!U23 -> 1E | U39: =Sheet1!V23 -> 2A | V39: =Sheet1!W23 -> 学 | W39: =Sheet1!Y23 -> 2E | X39: =Sheet1!Z23 -> 2B | Y39: =Sheet1!AA23 -> 0 | Z39: =Sheet1!AB23 -> 0 | AA39: =Sheet1!AC23 -> 3C | AB39: =Sheet1!AF23 -> 1D | AC39: =Sheet1!AG23 -> 1C | AD39: =Sheet1!AH23 -> 0 | AE39: =Sheet1!AI23 -> 待機 | AF39: =Sheet1!AJ23 -> 0 | AG39: =Sheet1!AK23 -> 総
C40: =Sheet1!B24 -> 2C | D40: =Sheet1!C24 -> 酒井 | E40: =Sheet1!D24 -> 0 | F40: =Sheet1!E24 -> 2D | G40: =Sheet1!F24 -> 2C | H40: =Sheet1!G24 -> IJ | I40: =Sheet1!H24 -> 0 | J40: =Sheet1!I24 -> 道 | K40: =Sheet1!K24 -> 2E | L40: =Sheet1!L24 -> 2D | M40: =Sheet1!M24 -> 初 | N40: =Sheet1!N24 -> 初 | O40: =Sheet1!O24 -> 0 | P40: =Sheet1!P24 -> 総 | Q40: =Sheet1!R24 -> 2C | R40: =Sheet1!S24 -> 待機 | S40: =Sheet1!T24 -> 0 | T40: =Sheet1!U24 -> 0 | U40: =Sheet1!V24 -> 0 | V40: =Sheet1!W24 -> 学 | W40: =Sheet1!Y24 -> 0 | X40: =Sheet1!Z24 -> 2C | Y40: =Sheet1!AA24 -> IJ | Z40: =Sheet1!AB24 -> 2E | AA40: =Sheet1!AC24 -> 0 | AB40: =Sheet1!AF24 -> 2D | AC40: =Sheet1!AG24 -> 0 | AD40: =Sheet1!AH24 -> 2E | AE40: =Sheet1!AI24 -> 0 | AF40: =Sheet1!AJ24 -> 0 | AG40: =Sheet1!AK24 -> 総
C41: =Sheet1!B25 -> 2D | D41: =Sheet1!C25 -> 樽見 | E41: =Sheet1!D25 -> 2C | F41: =Sheet1!E25 -> 2E | G41: =Sheet1!F25 -> 2D | H41: =Sheet1!G25 -> 0 | I41: =Sheet1!H25 -> 0 | J41: =Sheet1!I25 -> 道 | K41: =Sheet1!K25 -> 2B | L41: =Sheet1!L25 -> 0 | M41: =Sheet1!M25 -> 0 | N41: =Sheet1!N25 -> 2C | O41: =Sheet1!O25 -> 2E | P41: =Sheet1!P25 -> 総 | Q41: =Sheet1!R25 -> 2E | R41: =Sheet1!S25 -> 0 | S41: =Sheet1!T25 -> 2D | T41: =Sheet1!U25 -> 2B | U41: =Sheet1!V25 -> 2C | V41: =Sheet1!W25 -> 学 | W41: =Sheet1!Y25 -> 0 | X41: =Sheet1!Z25 -> 2E | Y41: =Sheet1!AA25 -> 2B | Z41: =Sheet1!AB25 -> 0 | AA41: =Sheet1!AC25 -> 2D | AB41: =Sheet1!AF25 -> 0 | AC41: =Sheet1!AG25 -> 2C | AD41: =Sheet1!AH25 -> 2D | AE41: =Sheet1!AI25 -> 2B | AF41: =Sheet1!AJ25 -> 0 | AG41: =Sheet1!AK25 -> 総
C42: =Sheet1!B26 -> 2E | D42: =Sheet1!C26 -> 高田 | E42: =Sheet1!D26 -> 2E | F42: =Sheet1!E26 -> 2A | G42: =Sheet1!F26 -> 2B | H42: =Sheet1!G26 -> 0 | I42: =Sheet1!H26 -> T2 | J42: =Sheet1!I26 -> 道 | K42: =Sheet1!K26 -> 2D | L42: =Sheet1!L26 -> 2E | M42: =Sheet1!M26 -> 0 | N42: =Sheet1!N26 -> 2A | O42: =Sheet1!O26 -> 2C | P42: =Sheet1!P26 -> 総 | Q42: =Sheet1!R26 -> 0 | R42: =Sheet1!S26 -> 2C | S42: =Sheet1!T26 -> 2A | T42: =Sheet1!U26 -> 2D | U42: =Sheet1!V26 -> 0 | V42: =Sheet1!W26 -> 学 | W42: =Sheet1!Y26 -> 2C | X42: =Sheet1!Z26 -> 0 | Y42: =Sheet1!AA26 -> 0 | Z42: =Sheet1!AB26 -> 0 | AA42: =Sheet1!AC26 -> 2B | AB42: =Sheet1!AF26 -> 2B | AC42: =Sheet1!AG26 -> 2E | AD42: =Sheet1!AH26 -> 0 | AE42: =Sheet1!AI26 -> 2D | AF42: =Sheet1!AJ26 -> 0 | AG42: =Sheet1!AK26 -> 総
C43: =Sheet1!B27 -> 0 | D43: =Sheet1!C27 -> 鈴木 | E43: =Sheet1!D27 -> 2AB | F43: =Sheet1!E27 -> 待機 | G43: =Sheet1!F27 -> 主 | H43: =Sheet1!G27 -> 0 | I43: =Sheet1!H27 -> 3BC | J43: =Sheet1!I27 -> 道 | K43: =Sheet1!K27 -> 0 | L43: =Sheet1!L27 -> 2C | M43: =Sheet1!M27 -> 2DE | N43: =Sheet1!N27 -> 0 | O43: =Sheet1!O27 -> 0 | P43: =Sheet1!P27 -> 総 | Q43: =Sheet1!R27 -> 2AB | R43: =Sheet1!S27 -> 2DE | S43: =Sheet1!T27 -> 2C | T43: =Sheet1!U27 -> 0 | U43: =Sheet1!V27 -> 0 | V43: =Sheet1!W27 -> 0 | W43: =Sheet1!Y27 -> 3BC | X43: =Sheet1!Z27 -> 0 | Y43: =Sheet1!AA27 -> 2DE | Z43: =Sheet1!AB27 -> 2AB | AA43: =Sheet1!AC27 -> 0 | AB43: =Sheet1!AF27 -> 0 | AC43: =Sheet1!AG27 -> 3BC | AD43: =Sheet1!AH27 -> 0 | AE43: =Sheet1!AI27 -> 0 | AF43: =Sheet1!AJ27 -> 2C | AG43: =Sheet1!AK27 -> 総
...

Sheet 担任別
A1: =IF(#REF!="","",#REF!) -> #REF! | D1: 先生 | H1: =IF(#REF!="","",#REF!) -> #REF! | K1: 先生 | O1: =IF(#REF!="","",#REF!) -> #REF! | R1: 先生 | V1: =IF(#REF!="","",#REF!) -> #REF! | Y1: 先生
A2: 1 | H2: 2 | O2: 3 | V2: 4
B3: 月 | C3: 火 | D3: 水 | E3: 木 | F3: 金 | I3: 月 | J3: 火 | K3: 水 | L3: 木 | M3: 金 | P3: 月 | Q3: 火 | R3: 水 | S3: 木 | T3: 金 | W3: 月 | X3: 火 | Y3: 水 | Z3: 木 | AA3: 金
A4: 1 | B4: =IF(VLOOKUP(A2,#REF!,4)="","",VLOOKUP(A2,#REF!,4)) -> #REF! | C4: =IF(VLOOKUP(A2,#REF!,11)="","",VLOOKUP(A2,#REF!,11)) -> #REF! | D4: =IF(VLOOKUP(A2,#REF!,18)="","",VLOOKUP(A2,#REF!,18)) -> #REF! | E4: =IF(VLOOKUP(A2,#REF!,25)="","",VLOOKUP(A2,#REF!,25)) -> #REF! | F4: =IF(VLOOKUP(A2,#REF!,32)="","",VLOOKUP(A2,#REF!,32)) -> #REF! | H4: 1 | I4: =IF(VLOOKUP(H2,#REF!,4)="","",VLOOKUP(H2,#REF!,4)) -> #REF! | J4: =IF(VLOOKUP(H2,#REF!,11)="","",VLOOKUP(H2,#REF!,11)) -> #REF! | K4: =IF(VLOOKUP(H2,#REF!,18)="","",VLOOKUP(H2,#REF!,18)) -> #REF! | L4: =IF(VLOOKUP(H2,#REF!,25)="","",VLOOKUP(H2,#REF!,25)) -> #REF! | M4: =IF(VLOOKUP(H2,#REF!,32)="","",VLOOKUP(H2,#REF!,32)) -> #REF! | O4: 1 | P4: =IF(VLOOKUP(O2,#REF!,4)="","",VLOOKUP(O2,#REF!,4)) -> #REF! | Q4: =IF(VLOOKUP(O2,#REF!,11)="","",VLOOKUP(O2,#REF!,11)) -> #REF! | R4: =IF(VLOOKUP(O2,#REF!,18)="","",VLOOKUP(O2,#REF!,18)) -> #REF! | S4: =IF(VLOOKUP(O2,#REF!,25)="","",VLOOKUP(O2,#REF!,25)) -> #REF! | T4: =IF(VLOOKUP(O2,#REF!,32)="","",VLOOKUP(O2,#REF!,32)) -> #REF! | V4: 1 | W4: =IF(VLOOKUP(V2,#REF!,4)="","",VLOOKUP(V2,#REF!,4)) -> #REF! | X4: =IF(VLOOKUP(V2,#REF!,11)="","",VLOOKUP(V2,#REF!,11)) -> #REF! | Y4: =IF(VLOOKUP(V2,#REF!,18)="","",VLOOKUP(V2,#REF!,18)) -> #REF! | Z4: =IF(VLOOKUP(V2,#REF!,25)="","",VLOOKUP(V2,#REF!,25)) -> #REF! | AA4: =IF(VLOOKUP(V2,#REF!,32)="","",VLOOKUP(V2,#REF!,32)) -> #REF!
A5: 2 | B5: =IF(VLOOKUP(A2,#REF!,5)="","",VLOOKUP(A2,#REF!,5)) -> #REF! | C5: =IF(VLOOKUP(A2,#REF!,12)="","",VLOOKUP(A2,#REF!,12)) -> #REF! | D5: =IF(VLOOKUP(A2,#REF!,19)="","",VLOOKUP(A2,#REF!,19)) -> #REF! | E5: =IF(VLOOKUP(A2,#REF!,26)="","",VLOOKUP(A2,#REF!,26)) -> #REF! | F5: =IF(VLOOKUP(A2,#REF!,33)="","",VLOOKUP(A2,#REF!,33)) -> #REF! | H5: 2 | I5: =IF(VLOOKUP(H2,#REF!,5)="","",VLOOKUP(H2,#REF!,5)) -> #REF! | J5: =IF(VLOOKUP(H2,#REF!,12)="","",VLOOKUP(H2,#REF!,12)) -> #REF! | K5: =IF(VLOOKUP(H2,#REF!,19)="","",VLOOKUP(H2,#REF!,19)) -> #REF! | L5: =IF(VLOOKUP(H2,#REF!,26)="","",VLOOKUP(H2,#REF!,26)) -> #REF! | M5: =IF(VLOOKUP(H2,#REF!,33)="","",VLOOKUP(H2,#REF!,33)) -> #REF! | O5: 2 | P5: =IF(VLOOKUP(O2,#REF!,5)="","",VLOOKUP(O2,#REF!,5)) -> #REF! | Q5: =IF(VLOOKUP(O2,#REF!,12)="","",VLOOKUP(O2,#REF!,12)) -> #REF! | R5: =IF(VLOOKUP(O2,#REF!,19)="","",VLOOKUP(O2,#REF!,19)) -> #REF! | S5: =IF(VLOOKUP(O2,#REF!,26)="","",VLOOKUP(O2,#REF!,26)) -> #REF! | T5: =IF(VLOOKUP(O2,#REF!,33)="","",VLOOKUP(O2,#REF!,33)) -> #REF! | V5: 2 | W5: =IF(VLOOKUP(V2,#REF!,5)="","",VLOOKUP(V2,#REF!,5)) -> #REF! | X5: =IF(VLOOKUP(V2,#REF!,12)="","",VLOOKUP(V2,#REF!,12)) -> #REF! | Y5: =IF(VLOOKUP(V2,#REF!,19)="","",VLOOKUP(V2,#REF!,19)) -> #REF! | Z5: =IF(VLOOKUP(V2,#REF!,26)="","",VLOOKUP(V2,#REF!,26)) -> #REF! | AA5: =IF(VLOOKUP(V2,#REF!,33)="","",VLOOKUP(V2,#REF!,33)) -> #REF!
A6: 3 | B6: =IF(VLOOKUP(A2,#REF!,6)="","",VLOOKUP(A2,#REF!,6)) -> #REF! | C6: =IF(VLOOKUP(A2,#REF!,13)="","",VLOOKUP(A2,#REF!,13)) -> #REF! | D6: =IF(VLOOKUP(A2,#REF!,20)="","",VLOOKUP(A2,#REF!,20)) -> #REF! | E6: =IF(VLOOKUP(A2,#REF!,27)="","",VLOOKUP(A2,#REF!,27)) -> #REF! | F6: =IF(VLOOKUP(A2,#REF!,34)="","",VLOOKUP(A2,#REF!,34)) -> #REF! | H6: 3 | I6: =IF(VLOOKUP(H2,#REF!,6)="","",VLOOKUP(H2,#REF!,6)) -> #REF! | J6: =IF(VLOOKUP(H2,#REF!,13)="","",VLOOKUP(H2,#REF!,13)) -> #REF! | K6: =IF(VLOOKUP(H2,#REF!,20)="","",VLOOKUP(H2,#REF!,20)) -> #REF! | L6: =IF(VLOOKUP(H2,#REF!,27)="","",VLOOKUP(H2,#REF!,27)) -> #REF! | M6: =IF(VLOOKUP(H2,#REF!,34)="","",VLOOKUP(H2,#REF!,34)) -> #REF! | O6: 3 | P6: =IF(VLOOKUP(O2,#REF!,6)="","",VLOOKUP(O2,#REF!,6)) -> #REF! | Q6: =IF(VLOOKUP(O2,#REF!,13)="","",VLOOKUP(O2,#REF!,13)) -> #REF! | R6: =IF(VLOOKUP(O2,#REF!,20)="","",VLOOKUP(O2,#REF!,20)) -> #REF! | S6: =IF(VLOOKUP(O2,#REF!,27)="","",VLOOKUP(O2,#REF!,27)) -> #REF! | T6: =IF(VLOOKUP(O2,#REF!,34)="","",VLOOKUP(O2,#REF!,34)) -> #REF! | V6: 3 | W6: =IF(VLOOKUP(V2,#REF!,6)="","",VLOOKUP(V2,#REF!,6)) -> #REF! | X6: =IF(VLOOKUP(V2,#REF!,13)="","",VLOOKUP(V2,#REF!,13)) -> #REF! | Y6: =IF(VLOOKUP(V2,#REF!,20)="","",VLOOKUP(V2,#REF!,20)) -> #REF! | Z6: =IF(VLOOKUP(V2,#REF!,27)="","",VLOOKUP(V2,#REF!,27)) -> #REF! | AA6: =IF(VLOOKUP(V2,#REF!,34)="","",VLOOKUP(V2,#REF!,34)) -> #REF!
A7: 4 | B7: =IF(VLOOKUP(A2,#REF!,7)="","",VLOOKUP(A2,#REF!,7)) -> #REF! | C7: =IF(VLOOKUP(A2,#REF!,14)="","",VLOOKUP(A2,#REF!,14)) -> #REF! | D7: =IF(VLOOKUP(A2,#REF!,21)="","",VLOOKUP(A2,#REF!,21)) -> #REF! | E7: =IF(VLOOKUP(A2,#REF!,28)="","",VLOOKUP(A2,#REF!,28)) -> #REF! | F7: =IF(VLOOKUP(A2,#REF!,35)="","",VLOOKUP(A2,#REF!,35)) -> #REF! | H7: 4 | I7: =IF(VLOOKUP(H2,#REF!,7)="","",VLOOKUP(H2,#REF!,7)) -> #REF! | J7: =IF(VLOOKUP(H2,#REF!,14)="","",VLOOKUP(H2,#REF!,14)) -> #REF! | K7: =IF(VLOOKUP(H2,#REF!,21)="","",VLOOKUP(H2,#REF!,21)) -> #REF! | L7: =IF(VLOOKUP(H2,#REF!,28)="","",VLOOKUP(H2,#REF!,28)) -> #REF! | M7: =IF(VLOOKUP(H2,#REF!,35)="","",VLOOKUP(H2,#REF!,35)) -> #REF! | O7: 4 | P7: =IF(VLOOKUP(O2,#REF!,7)="","",VLOOKUP(O2,#REF!,7)) -> #REF! | Q7: =IF(VLOOKUP(O2,#REF!,14)="","",VLOOKUP(O2,#REF!,14)) -> #REF! | R7: =IF(VLOOKUP(O2,#REF!,21)="","",VLOOKUP(O2,#REF!,21)) -> #REF! | S7: =IF(VLOOKUP(O2,#REF!,28)="","",VLOOKUP(O2,#REF!,28)) -> #REF! | T7: =IF(VLOOKUP(O2,#REF!,35)="","",VLOOKUP(O2,#REF!,35)) -> #REF! | V7: 4 | W7: =IF(VLOOKUP(V2,#REF!,7)="","",VLOOKUP(V2,#REF!,7)) -> #REF! | X7: =IF(VLOOKUP(V2,#REF!,14)="","",VLOOKUP(V2,#REF!,14)) -> #REF! | Y7: =IF(VLOOKUP(V2,#REF!,21)="","",VLOOKUP(V2,#REF!,21)) -> #REF! | Z7: =IF(VLOOKUP(V2,#REF!,28)="","",VLOOKUP(V2,#REF!,28)) -> #REF! | AA7: =IF(VLOOKUP(V2,#REF!,35)="","",VLOOKUP(V2,#REF!,35)) -> #REF!
A8: 5 | B8: =IF(VLOOKUP(A2,#REF!,8)="","",VLOOKUP(A2,#REF!,8)) -> #REF! | C8: =IF(VLOOKUP(A2,#REF!,15)="","",VLOOKUP(A2,#REF!,15)) -> #REF! | D8: =IF(VLOOKUP(A2,#REF!,22)="","",VLOOKUP(A2,#REF!,22)) -> #REF! | E8: =IF(VLOOKUP(A2,#REF!,29)="","",VLOOKUP(A2,#REF!,29)) -> #REF! | F8: =IF(VLOOKUP(A2,#REF!,36)="","",VLOOKUP(A2,#REF!,36)) -> #REF! | H8: 5 | I8: =IF(VLOOKUP(H2,#REF!,8)="","",VLOOKUP(H2,#REF!,8)) -> #REF! | J8: =IF(VLOOKUP(H2,#REF!,15)="","",VLOOKUP(H2,#REF!,15)) -> #REF! | K8: =IF(VLOOKUP(H2,#REF!,22)="","",VLOOKUP(H2,#REF!,22)) -> #REF! | L8: =IF(VLOOKUP(H2,#REF!,29)="","",VLOOKUP(H2,#REF!,29)) -> #REF! | M8: =IF(VLOOKUP(H2,#REF!,36)="","",VLOOKUP(H2,#REF!,36)) -> #REF! | O8: 5 | P8: =IF(VLOOKUP(O2,#REF!,8)="","",VLOOKUP(O2,#REF!,8)) -> #REF! | Q8: =IF(VLOOKUP(O2,#REF!,15)="","",VLOOKUP(O2,#REF!,15)) -> #REF! | R8: =IF(VLOOKUP(O2,#REF!,22)="","",VLOOKUP(O2,#REF!,22)) -> #REF! | S8: =IF(VLOOKUP(O2,#REF!,29)="","",VLOOKUP(O2,#REF!,29)) -> #REF! | T8: =IF(VLOOKUP(O2,#REF!,36)="","",VLOOKUP(O2,#REF!,36)) -> #REF! | V8: 5 | W8: =IF(VLOOKUP(V2,#REF!,8)="","",VLOOKUP(V2,#REF!,8)) -> #REF! | X8: =IF(VLOOKUP(V2,#REF!,15)="","",VLOOKUP(V2,#REF!,15)) -> #REF! | Y8: =IF(VLOOKUP(V2,#REF!,22)="","",VLOOKUP(V2,#REF!,22)) -> #REF! | Z8: =IF(VLOOKUP(V2,#REF!,29)="","",VLOOKUP(V2,#REF!,29)) -> #REF! | AA8: =IF(VLOOKUP(V2,#REF!,36)="","",VLOOKUP(V2,#REF!,36)) -> #REF!
A9: 6 | B9: =IF(VLOOKUP(A2,#REF!,9)="","",VLOOKUP(A2,#REF!,9)) -> #REF! | C9: =IF(VLOOKUP(A2,#REF!,16)="","",VLOOKUP(A2,#REF!,16)) -> #REF! | D9: =IF(VLOOKUP(A2,#REF!,23)="","",VLOOKUP(A2,#REF!,23)) -> #REF! | E9: =IF(VLOOKUP(A2,#REF!,30)="","",VLOOKUP(A2,#REF!,30)) -> #REF! | F9: =IF(VLOOKUP(A2,#REF!,37)="","",VLOOKUP(A2,#REF!,37)) -> #REF! | H9: 6 | I9: =IF(VLOOKUP(H2,#REF!,9)="","",VLOOKUP(H2,#REF!,9)) -> #REF! | J9: =IF(VLOOKUP(H2,#REF!,16)="","",VLOOKUP(H2,#REF!,16)) -> #REF! | K9: =IF(VLOOKUP(H2,#REF!,23)="","",VLOOKUP(H2,#REF!,23)) -> #REF! | L9: =IF(VLOOKUP(H2,#REF!,30)="","",VLOOKUP(H2,#REF!,30)) -> #REF! | M9: =IF(VLOOKUP(H2,#REF!,37)="","",VLOOKUP(H2,#REF!,37)) -> #REF! | O9: 6 | P9: =IF(VLOOKUP(O2,#REF!,9)="","",VLOOKUP(O2,#REF!,9)) -> #REF! | Q9: =IF(VLOOKUP(O2,#REF!,16)="","",VLOOKUP(O2,#REF!,16)) -> #REF! | R9: =IF(VLOOKUP(O2,#REF!,23)="","",VLOOKUP(O2,#REF!,23)) -> #REF! | S9: =IF(VLOOKUP(O2,#REF!,30)="","",VLOOKUP(O2,#REF!,30)) -> #REF! | T9: =IF(VLOOKUP(O2,#REF!,37)="","",VLOOKUP(O2,#REF!,37)) -> #REF! | V9: 6 | W9: =IF(VLOOKUP(V2,#REF!,9)="","",VLOOKUP(V2,#REF!,9)) -> #REF! | X9: =IF(VLOOKUP(V2,#REF!,16)="","",VLOOKUP(V2,#REF!,16)) -> #REF! | Y9: =IF(VLOOKUP(V2,#REF!,23)="","",VLOOKUP(V2,#REF!,23)) -> #REF! | Z9: =IF(VLOOKUP(V2,#REF!,30)="","",VLOOKUP(V2,#REF!,30)) -> #REF! | AA9: =IF(VLOOKUP(V2,#REF!,37)="","",VLOOKUP(V2,#REF!,37)) -> #REF!
A11: =IF(#REF!="","",#REF!) -> #REF! | D11: 先生 | H11: =IF(#REF!="","",#REF!) -> #REF! | K11: 先生 | O11: =IF(#REF!="","",#REF!) -> #REF! | R11: 先生 | V11: =IF(#REF!="","",#REF!) -> #REF! | Y11: 先生
A12: 5 | H12: 6 | O12: 7 | V12: 8
B13: 月 | C13: 火 | D13: 水 | E13: 木 | F13: 金 | I13: 月 | J13: 火 | K13: 水 | L13: 木 | M13: 金 | P13: 月 | Q13: 火 | R13: 水 | S13: 木 | T13: 金 | W13: 月 | X13: 火 | Y13: 水 | Z13: 木 | AA13: 金
A14: 1 | B14: =IF(VLOOKUP(A12,#REF!,4)="","",VLOOKUP(A12,#REF!,4)) -> #REF! | C14: =IF(VLOOKUP(A12,#REF!,11)="","",VLOOKUP(A12,#REF!,11)) -> #REF! | D14: =IF(VLOOKUP(A12,#REF!,18)="","",VLOOKUP(A12,#REF!,18)) -> #REF! | E14: =IF(VLOOKUP(A12,#REF!,25)="","",VLOOKUP(A12,#REF!,25)) -> #REF! | F14: =IF(VLOOKUP(A12,#REF!,32)="","",VLOOKUP(A12,#REF!,32)) -> #REF! | H14: 1 | I14: =IF(VLOOKUP(H12,#REF!,4)="","",VLOOKUP(H12,#REF!,4)) -> #REF! | J14: =IF(VLOOKUP(H12,#REF!,11)="","",VLOOKUP(H12,#REF!,11)) -> #REF! | K14: =IF(VLOOKUP(H12,#REF!,18)="","",VLOOKUP(H12,#REF!,18)) -> #REF! | L14: =IF(VLOOKUP(H12,#REF!,25)="","",VLOOKUP(H12,#REF!,25)) -> #REF! | M14: =IF(VLOOKUP(H12,#REF!,32)="","",VLOOKUP(H12,#REF!,32)) -> #REF! | O14: 1 | P14: =IF(VLOOKUP(O12,#REF!,4)="","",VLOOKUP(O12,#REF!,4)) -> #REF! | Q14: =IF(VLOOKUP(O12,#REF!,11)="","",VLOOKUP(O12,#REF!,11)) -> #REF! | R14: =IF(VLOOKUP(O12,#REF!,18)="","",VLOOKUP(O12,#REF!,18)) -> #REF! | S14: =IF(VLOOKUP(O12,#REF!,25)="","",VLOOKUP(O12,#REF!,25)) -> #REF! | T14: =IF(VLOOKUP(O12,#REF!,32)="","",VLOOKUP(O12,#REF!,32)) -> #REF! | V14: 1 | W14: =IF(VLOOKUP(V12,#REF!,4)="","",VLOOKUP(V12,#REF!,4)) -> #REF! | X14: =IF(VLOOKUP(V12,#REF!,11)="","",VLOOKUP(V12,#REF!,11)) -> #REF! | Y14: =IF(VLOOKUP(V12,#REF!,18)="","",VLOOKUP(V12,#REF!,18)) -> #REF! | Z14: =IF(VLOOKUP(V12,#REF!,25)="","",VLOOKUP(V12,#REF!,25)) -> #REF! | AA14: =IF(VLOOKUP(V12,#REF!,32)="","",VLOOKUP(V12,#REF!,32)) -> #REF!
A15: 2 | B15: =IF(VLOOKUP(A12,#REF!,5)="","",VLOOKUP(A12,#REF!,5)) -> #REF! | C15: =IF(VLOOKUP(A12,#REF!,12)="","",VLOOKUP(A12,#REF!,12)) -> #REF! | D15: =IF(VLOOKUP(A12,#REF!,19)="","",VLOOKUP(A12,#REF!,19)) -> #REF! | E15: =IF(VLOOKUP(A12,#REF!,26)="","",VLOOKUP(A12,#REF!,26)) -> #REF! | F15: =IF(VLOOKUP(A12,#REF!,33)="","",VLOOKUP(A12,#REF!,33)) -> #REF! | H15: 2 | I15: =IF(VLOOKUP(H12,#REF!,5)="","",VLOOKUP(H12,#REF!,5)) -> #REF! | J15: =IF(VLOOKUP(H12,#REF!,12)="","",VLOOKUP(H12,#REF!,12)) -> #REF! | K15: =IF(VLOOKUP(H12,#REF!,19)="","",VLOOKUP(H12,#REF!,19)) -> #REF! | L15: =IF(VLOOKUP(H12,#REF!,26)="","",VLOOKUP(H12,#REF!,26)) -> #REF! | M15: =IF(VLOOKUP(H12,#REF!,33)="","",VLOOKUP(H12,#REF!,33)) -> #REF! | O15: 2 | P15: =IF(VLOOKUP(O12,#REF!,5)="","",VLOOKUP(O12,#REF!,5)) -> #REF! | Q15: =IF(VLOOKUP(O12,#REF!,12)="","",VLOOKUP(O12,#REF!,12)) -> #REF! | R15: =IF(VLOOKUP(O12,#REF!,19)="","",VLOOKUP(O12,#REF!,19)) -> #REF! | S15: =IF(VLOOKUP(O12,#REF!,26)="","",VLOOKUP(O12,#REF!,26)) -> #REF! | T15: =IF(VLOOKUP(O12,#REF!,33)="","",VLOOKUP(O12,#REF!,33)) -> #REF! | V15: 2 | W15: =IF(VLOOKUP(V12,#REF!,5)="","",VLOOKUP(V12,#REF!,5)) -> #REF! | X15: =IF(VLOOKUP(V12,#REF!,12)="","",VLOOKUP(V12,#REF!,12)) -> #REF! | Y15: =IF(VLOOKUP(V12,#REF!,19)="","",VLOOKUP(V12,#REF!,19)) -> #REF! | Z15: =IF(VLOOKUP(V12,#REF!,26)="","",VLOOKUP(V12,#REF!,26)) -> #REF! | AA15: =IF(VLOOKUP(V12,#REF!,33)="","",VLOOKUP(V12,#REF!,33)) -> #REF!
A16: 3 | B16: =IF(VLOOKUP(A12,#REF!,6)="","",VLOOKUP(A12,#REF!,6)) -> #REF! | C16: =IF(VLOOKUP(A12,#REF!,13)="","",VLOOKUP(A12,#REF!,13)) -> #REF! | D16: =IF(VLOOKUP(A12,#REF!,20)="","",VLOOKUP(A12,#REF!,20)) -> #REF! | E16: =IF(VLOOKUP(A12,#REF!,27)="","",VLOOKUP(A12,#REF!,27)) -> #REF! | F16: =IF(VLOOKUP(A12,#REF!,34)="","",VLOOKUP(A12,#REF!,34)) -> #REF! | H16: 3 | I16: =IF(VLOOKUP(H12,#REF!,6)="","",VLOOKUP(H12,#REF!,6)) -> #REF! | J16: =IF(VLOOKUP(H12,#REF!,13)="","",VLOOKUP(H12,#REF!,13)) -> #REF! | K16: =IF(VLOOKUP(H12,#REF!,20)="","",VLOOKUP(H12,#REF!,20)) -> #REF! | L16: =IF(VLOOKUP(H12,#REF!,27)="","",VLOOKUP(H12,#REF!,27)) -> #REF! | M16: =IF(VLOOKUP(H12,#REF!,34)="","",VLOOKUP(H12,#REF!,34)) -> #REF! | O16: 3 | P16: =IF(VLOOKUP(O12,#REF!,6)="","",VLOOKUP(O12,#REF!,6)) -> #REF! | Q16: =IF(VLOOKUP(O12,#REF!,13)="","",VLOOKUP(O12,#REF!,13)) -> #REF! | R16: =IF(VLOOKUP(O12,#REF!,20)="","",VLOOKUP(O12,#REF!,20)) -> #REF! | S16: =IF(VLOOKUP(O12,#REF!,27)="","",VLOOKUP(O12,#REF!,27)) -> #REF! | T16: =IF(VLOOKUP(O12,#REF!,34)="","",VLOOKUP(O12,#REF!,34)) -> #REF! | V16: 3 | W16: =IF(VLOOKUP(V12,#REF!,6)="","",VLOOKUP(V12,#REF!,6)) -> #REF! | X16: =IF(VLOOKUP(V12,#REF!,13)="","",VLOOKUP(V12,#REF!,13)) -> #REF! | Y16: =IF(VLOOKUP(V12,#REF!,20)="","",VLOOKUP(V12,#REF!,20)) -> #REF! | Z16: =IF(VLOOKUP(V12,#REF!,27)="","",VLOOKUP(V12,#REF!,27)) -> #REF! | AA16: =IF(VLOOKUP(V12,#REF!,34)="","",VLOOKUP(V12,#REF!,34)) -> #REF!
A17: 4 | B17: =IF(VLOOKUP(A12,#REF!,7)="","",VLOOKUP(A12,#REF!,7)) -> #REF! | C17: =IF(VLOOKUP(A12,#REF!,14)="","",VLOOKUP(A12,#REF!,14)) -> #REF! | D17: =IF(VLOOKUP(A12,#REF!,21)="","",VLOOKUP(A12,#REF!,21)) -> #REF! | E17: =IF(VLOOKUP(A12,#REF!,28)="","",VLOOKUP(A12,#REF!,28)) -> #REF! | F17: =IF(VLOOKUP(A12,#REF!,35)="","",VLOOKUP(A12,#REF!,35)) -> #REF! | H17: 4 | I17: =IF(VLOOKUP(H12,#REF!,7)="","",VLOOKUP(H12,#REF!,7)) -> #REF! | J17: =IF(VLOOKUP(H12,#REF!,14)="","",VLOOKUP(H12,#REF!,14)) -> #REF! | K17: =IF(VLOOKUP(H12,#REF!,21)="","",VLOOKUP(H12,#REF!,21)) -> #REF! | L17: =IF(VLOOKUP(H12,#REF!,28)="","",VLOOKUP(H12,#REF!,28)) -> #REF! | M17: =IF(VLOOKUP(H12,#REF!,35)="","",VLOOKUP(H12,#REF!,35)) -> #REF! | O17: 4 | P17: =IF(VLOOKUP(O12,#REF!,7)="","",VLOOKUP(O12,#REF!,7)) -> #REF! | Q17: =IF(VLOOKUP(O12,#REF!,14)="","",VLOOKUP(O12,#REF!,14)) -> #REF! | R17: =IF(VLOOKUP(O12,#REF!,21)="","",VLOOKUP(O12,#REF!,21)) -> #REF! | S17: =IF(VLOOKUP(O12,#REF!,28)="","",VLOOKUP(O12,#REF!,28)) -> #REF! | T17: =IF(VLOOKUP(O12,#REF!,35)="","",VLOOKUP(O12,#REF!,35)) -> #REF! | V17: 4 | W17: =IF(VLOOKUP(V12,#REF!,7)="","",VLOOKUP(V12,#REF!,7)) -> #REF! | X17: =IF(VLOOKUP(V12,#REF!,14)="","",VLOOKUP(V12,#REF!,14)) -> #REF! | Y17: =IF(VLOOKUP(V12,#REF!,21)="","",VLOOKUP(V12,#REF!,21)) -> #REF! | Z17: =IF(VLOOKUP(V12,#REF!,28)="","",VLOOKUP(V12,#REF!,28)) -> #REF! | AA17: =IF(VLOOKUP(V12,#REF!,35)="","",VLOOKUP(V12,#REF!,35)) -> #REF!
